{
  "version": 8,
  "blockIdVersion": 11,
  "anchorX": 0,
  "anchorY": 7,
  "anchorZ": 0,
  "blocks": [
    {
      "x": -8,
      "y": 17,
      "z": -1,
      "name": "Plant_Crop_Mushroom_Block_Blue"
    },
    {
      "x": -8,
      "y": 18,
      "z": -1,
      "name": "Plant_Crop_Mushroom_Glowing_Blue"
    },
    {
      "x": -8,
      "y": 16,
      "z": 0,
      "name": "Plant_Crop_Mushroom_Block_Blue"
    },
    {
      "x": -8,
      "y": 17,
      "z": 0,
      "name": "Plant_Crop_Mushroom_Block_Blue"
    },
    {
      "x": -8,
      "y": 18,
      "z": 0,
      "name": "Plant_Crop_Mushroom_Block_Blue"
    },
    {
      "x": -8,
      "y": 17,
      "z": 1,
      "name": "Plant_Crop_Mushroom_Block_Blue"
    },
    {
      "x": -7,
      "y": 17,
      "z": -3,
      "name": "Plant_Crop_Mushroom_Block_Blue"
    },
    {
      "x": -7,
      "y": 18,
      "z": -3,
      "name": "Plant_Crop_Mushroom_Glowing_Blue"
    },
    {
      "x": -7,
      "y": 14,
      "z": -2,
      "name": "Plant_Crop_Mushroom_Block_Blue"
    },
    {
      "x": -7,
      "y": 15,
      "z": -2,
      "name": "Plant_Crop_Mushroom_Block_Blue"
    },
    {
      "x": -7,
      "y": 16,
      "z": -2,
      "name": "Plant_Crop_Mushroom_Block_Blue"
    },
    {
      "x": -7,
      "y": 17,
      "z": -2,
      "name": "Plant_Crop_Mushroom_Block_Blue"
    },
    {
      "x": -7,
      "y": 18,
      "z": -2,
      "name": "Plant_Crop_Mushroom_Block_Blue"
    },
    {
      "x": -7,
      "y": 19,
      "z": -2,
      "name": "Plant_Crop_Mushroom_Glowing_Blue"
    },
    {
      "x": -7,
      "y": 16,
      "z": -1,
      "name": "Plant_Crop_Mushroom_Block_Blue"
    },
    {
      "x": -7,
      "y": 17,
      "z": -1,
      "name": "Plant_Crop_Mushroom_Block_Blue"
    },
    {
      "x": -7,
      "y": 18,
      "z": -1,
      "name": "Plant_Crop_Mushroom_Block_Blue"
    },
    {
      "x": -7,
      "y": 19,
      "z": -1,
      "name": "Plant_Crop_Mushroom_Block_Blue"
    },
    {
      "x": -7,
      "y": 16,
      "z": 0,
      "name": "Plant_Crop_Mushroom_Block_Blue"
    },
    {
      "x": -7,
      "y": 17,
      "z": 0,
      "name": "Plant_Crop_Mushroom_Block_Blue"
    },
    {
      "x": -7,
      "y": 18,
      "z": 0,
      "name": "Plant_Crop_Mushroom_Block_Blue"
    },
    {
      "x": -7,
      "y": 19,
      "z": 0,
      "name": "Plant_Crop_Mushroom_Block_Blue"
    },
    {
      "x": -7,
      "y": 20,
      "z": 0,
      "name": "Plant_Crop_Mushroom_Glowing_Blue"
    },
    {
      "x": -7,
      "y": 16,
      "z": 1,
      "name": "Plant_Crop_Mushroom_Block_Blue"
    },
    {
      "x": -7,
      "y": 17,
      "z": 1,
      "name": "Plant_Crop_Mushroom_Block_Blue"
    },
    {
      "x": -7,
      "y": 18,
      "z": 1,
      "name": "Plant_Crop_Mushroom_Block_Blue"
    },
    {
      "x": -7,
      "y": 19,
      "z": 1,
      "name": "Plant_Crop_Mushroom_Block_Blue"
    },
    {
      "x": -7,
      "y": 15,
      "z": 2,
      "name": "Plant_Crop_Mushroom_Block_Blue"
    },
    {
      "x": -7,
      "y": 16,
      "z": 2,
      "name": "Plant_Crop_Mushroom_Block_Blue"
    },
    {
      "x": -7,
      "y": 17,
      "z": 2,
      "name": "Plant_Crop_Mushroom_Block_Blue"
    },
    {
      "x": -7,
      "y": 18,
      "z": 2,
      "name": "Plant_Crop_Mushroom_Block_Blue"
    },
    {
      "x": -7,
      "y": 19,
      "z": 2,
      "name": "Plant_Crop_Mushroom_Glowing_Blue"
    },
    {
      "x": -7,
      "y": 17,
      "z": 3,
      "name": "Plant_Crop_Mushroom_Block_Blue"
    },
    {
      "x": -7,
      "y": 18,
      "z": 3,
      "name": "Plant_Crop_Mushroom_Glowing_Blue"
    },
    {
      "x": -6,
      "y": 17,
      "z": -5,
      "name": "Plant_Crop_Mushroom_Block_Blue"
    },
    {
      "x": -6,
      "y": 18,
      "z": -5,
      "name": "Plant_Crop_Mushroom_Glowing_Blue"
    },
    {
      "x": -6,
      "y": 15,
      "z": -4,
      "name": "Plant_Crop_Mushroom_Block_Blue"
    },
    {
      "x": -6,
      "y": 16,
      "z": -4,
      "name": "Plant_Crop_Mushroom_Block_Blue"
    },
    {
      "x": -6,
      "y": 17,
      "z": -4,
      "name": "Plant_Crop_Mushroom_Block_Blue"
    },
    {
      "x": -6,
      "y": 18,
      "z": -4,
      "name": "Plant_Crop_Mushroom_Block_Blue"
    },
    {
      "x": -6,
      "y": 16,
      "z": -3,
      "name": "Plant_Crop_Mushroom_Block_Blue"
    },
    {
      "x": -6,
      "y": 17,
      "z": -3,
      "name": "Plant_Crop_Mushroom_Block_Blue"
    },
    {
      "x": -6,
      "y": 18,
      "z": -3,
      "name": "Plant_Crop_Mushroom_Block_Blue"
    },
    {
      "x": -6,
      "y": 19,
      "z": -3,
      "name": "Plant_Crop_Mushroom_Block_Blue"
    },
    {
      "x": -6,
      "y": 17,
      "z": -2,
      "name": "Plant_Crop_Mushroom_Block_Blue_Mycelium"
    },
    {
      "x": -6,
      "y": 18,
      "z": -2,
      "name": "Plant_Crop_Mushroom_Block_Blue"
    },
    {
      "x": -6,
      "y": 19,
      "z": -2,
      "name": "Plant_Crop_Mushroom_Block_Blue"
    },
    {
      "x": -6,
      "y": 17,
      "z": -1,
      "name": "Plant_Crop_Mushroom_Block_Blue_Mycelium"
    },
    {
      "x": -6,
      "y": 18,
      "z": -1,
      "name": "Plant_Crop_Mushroom_Block_Blue"
    },
    {
      "x": -6,
      "y": 19,
      "z": -1,
      "name": "Plant_Crop_Mushroom_Block_Blue"
    },
    {
      "x": -6,
      "y": 20,
      "z": -1,
      "name": "Plant_Crop_Mushroom_Block_Blue"
    },
    {
      "x": -6,
      "y": 17,
      "z": 0,
      "name": "Plant_Crop_Mushroom_Block_Blue_Mycelium"
    },
    {
      "x": -6,
      "y": 18,
      "z": 0,
      "name": "Plant_Crop_Mushroom_Block_Blue"
    },
    {
      "x": -6,
      "y": 19,
      "z": 0,
      "name": "Plant_Crop_Mushroom_Block_Blue"
    },
    {
      "x": -6,
      "y": 20,
      "z": 0,
      "name": "Plant_Crop_Mushroom_Block_Blue"
    },
    {
      "x": -6,
      "y": 17,
      "z": 1,
      "name": "Plant_Crop_Mushroom_Block_Blue_Mycelium"
    },
    {
      "x": -6,
      "y": 18,
      "z": 1,
      "name": "Plant_Crop_Mushroom_Block_Blue"
    },
    {
      "x": -6,
      "y": 19,
      "z": 1,
      "name": "Plant_Crop_Mushroom_Block_Blue"
    },
    {
      "x": -6,
      "y": 20,
      "z": 1,
      "name": "Plant_Crop_Mushroom_Block_Blue"
    },
    {
      "x": -6,
      "y": 17,
      "z": 2,
      "name": "Plant_Crop_Mushroom_Block_Blue_Mycelium"
    },
    {
      "x": -6,
      "y": 18,
      "z": 2,
      "name": "Plant_Crop_Mushroom_Block_Blue"
    },
    {
      "x": -6,
      "y": 19,
      "z": 2,
      "name": "Plant_Crop_Mushroom_Block_Blue"
    },
    {
      "x": -6,
      "y": 20,
      "z": 2,
      "name": "Plant_Crop_Mushroom_Glowing_Blue"
    },
    {
      "x": -6,
      "y": 16,
      "z": 3,
      "name": "Plant_Crop_Mushroom_Block_Blue"
    },
    {
      "x": -6,
      "y": 17,
      "z": 3,
      "name": "Plant_Crop_Mushroom_Block_Blue"
    },
    {
      "x": -6,
      "y": 18,
      "z": 3,
      "name": "Plant_Crop_Mushroom_Block_Blue"
    },
    {
      "x": -6,
      "y": 19,
      "z": 3,
      "name": "Plant_Crop_Mushroom_Block_Blue"
    },
    {
      "x": -6,
      "y": 14,
      "z": 4,
      "name": "Plant_Crop_Mushroom_Block_Blue"
    },
    {
      "x": -6,
      "y": 15,
      "z": 4,
      "name": "Plant_Crop_Mushroom_Block_Blue"
    },
    {
      "x": -6,
      "y": 16,
      "z": 4,
      "name": "Plant_Crop_Mushroom_Block_Blue"
    },
    {
      "x": -6,
      "y": 17,
      "z": 4,
      "name": "Plant_Crop_Mushroom_Block_Blue"
    },
    {
      "x": -6,
      "y": 18,
      "z": 4,
      "name": "Plant_Crop_Mushroom_Block_Blue"
    },
    {
      "x": -6,
      "y": 17,
      "z": 5,
      "name": "Plant_Crop_Mushroom_Block_Blue"
    },
    {
      "x": -5,
      "y": 17,
      "z": -6,
      "name": "Plant_Crop_Mushroom_Block_Blue"
    },
    {
      "x": -5,
      "y": 16,
      "z": -5,
      "name": "Plant_Crop_Mushroom_Block_Blue"
    },
    {
      "x": -5,
      "y": 17,
      "z": -5,
      "name": "Plant_Crop_Mushroom_Block_Blue"
    },
    {
      "x": -5,
      "y": 18,
      "z": -5,
      "name": "Plant_Crop_Mushroom_Block_Blue"
    },
    {
      "x": -5,
      "y": 17,
      "z": -4,
      "name": "Plant_Crop_Mushroom_Block_Blue_Mycelium"
    },
    {
      "x": -5,
      "y": 18,
      "z": -4,
      "name": "Plant_Crop_Mushroom_Block_Blue"
    },
    {
      "x": -5,
      "y": 19,
      "z": -4,
      "name": "Plant_Crop_Mushroom_Block_Blue"
    },
    {
      "x": -5,
      "y": 17,
      "z": -3,
      "name": "Plant_Crop_Mushroom_Block_Blue_Mycelium"
    },
    {
      "x": -5,
      "y": 18,
      "z": -3,
      "name": "Plant_Crop_Mushroom_Block_Blue"
    },
    {
      "x": -5,
      "y": 19,
      "z": -3,
      "name": "Plant_Crop_Mushroom_Block_Blue"
    },
    {
      "x": -5,
      "y": 20,
      "z": -3,
      "name": "Plant_Crop_Mushroom_Block_Blue"
    },
    {
      "x": -5,
      "y": 17,
      "z": -2,
      "name": "Plant_Crop_Mushroom_Block_Blue_Mycelium"
    },
    {
      "x": -5,
      "y": 18,
      "z": -2,
      "name": "Plant_Crop_Mushroom_Block_Blue"
    },
    {
      "x": -5,
      "y": 19,
      "z": -2,
      "name": "Plant_Crop_Mushroom_Block_Blue"
    },
    {
      "x": -5,
      "y": 20,
      "z": -2,
      "name": "Plant_Crop_Mushroom_Block_Blue"
    },
    {
      "x": -5,
      "y": 2,
      "z": -1,
      "name": "Plant_Crop_Mushroom_Block_Blue_Trunk"
    },
    {
      "x": -5,
      "y": 3,
      "z": -1,
      "name": "Plant_Crop_Mushroom_Block_Blue_Trunk"
    },
    {
      "x": -5,
      "y": 17,
      "z": -1,
      "name": "Plant_Crop_Mushroom_Block_Blue_Mycelium"
    },
    {
      "x": -5,
      "y": 18,
      "z": -1,
      "name": "Plant_Crop_Mushroom_Block_Blue"
    },
    {
      "x": -5,
      "y": 19,
      "z": -1,
      "name": "Plant_Crop_Mushroom_Block_Blue"
    },
    {
      "x": -5,
      "y": 20,
      "z": -1,
      "name": "Plant_Crop_Mushroom_Block_Blue"
    },
    {
      "x": -5,
      "y": 21,
      "z": -1,
      "name": "Plant_Crop_Mushroom_Glowing_Blue"
    },
    {
      "x": -5,
      "y": 0,
      "z": 0,
      "name": "Plant_Crop_Mushroom_Block_Blue_Trunk"
    },
    {
      "x": -5,
      "y": 1,
      "z": 0,
      "name": "Plant_Crop_Mushroom_Block_Blue_Trunk"
    },
    {
      "x": -5,
      "y": 2,
      "z": 0,
      "name": "Plant_Crop_Mushroom_Block_Blue_Trunk"
    },
    {
      "x": -5,
      "y": 3,
      "z": 0,
      "name": "Plant_Crop_Mushroom_Block_Blue_Trunk"
    },
    {
      "x": -5,
      "y": 17,
      "z": 0,
      "name": "Plant_Crop_Mushroom_Block_Blue_Mycelium"
    },
    {
      "x": -5,
      "y": 18,
      "z": 0,
      "name": "Plant_Crop_Mushroom_Block_Blue"
    },
    {
      "x": -5,
      "y": 19,
      "z": 0,
      "name": "Plant_Crop_Mushroom_Block_Blue"
    },
    {
      "x": -5,
      "y": 20,
      "z": 0,
      "name": "Plant_Crop_Mushroom_Block_Blue"
    },
    {
      "x": -5,
      "y": 21,
      "z": 0,
      "name": "Plant_Crop_Mushroom_Block_Blue"
    },
    {
      "x": -5,
      "y": 2,
      "z": 1,
      "name": "Plant_Crop_Mushroom_Block_Blue_Trunk"
    },
    {
      "x": -5,
      "y": 3,
      "z": 1,
      "name": "Plant_Crop_Mushroom_Block_Blue_Trunk"
    },
    {
      "x": -5,
      "y": 17,
      "z": 1,
      "name": "Plant_Crop_Mushroom_Block_Blue_Mycelium"
    },
    {
      "x": -5,
      "y": 18,
      "z": 1,
      "name": "Plant_Crop_Mushroom_Block_Blue"
    },
    {
      "x": -5,
      "y": 19,
      "z": 1,
      "name": "Plant_Crop_Mushroom_Block_Blue"
    },
    {
      "x": -5,
      "y": 20,
      "z": 1,
      "name": "Plant_Crop_Mushroom_Block_Blue"
    },
    {
      "x": -5,
      "y": 21,
      "z": 1,
      "name": "Plant_Crop_Mushroom_Glowing_Blue"
    },
    {
      "x": -5,
      "y": 17,
      "z": 2,
      "name": "Plant_Crop_Mushroom_Block_Blue_Mycelium"
    },
    {
      "x": -5,
      "y": 18,
      "z": 2,
      "name": "Plant_Crop_Mushroom_Block_Blue"
    },
    {
      "x": -5,
      "y": 19,
      "z": 2,
      "name": "Plant_Crop_Mushroom_Block_Blue"
    },
    {
      "x": -5,
      "y": 20,
      "z": 2,
      "name": "Plant_Crop_Mushroom_Block_Blue"
    },
    {
      "x": -5,
      "y": 17,
      "z": 3,
      "name": "Plant_Crop_Mushroom_Block_Blue_Mycelium"
    },
    {
      "x": -5,
      "y": 18,
      "z": 3,
      "name": "Plant_Crop_Mushroom_Block_Blue"
    },
    {
      "x": -5,
      "y": 19,
      "z": 3,
      "name": "Plant_Crop_Mushroom_Block_Blue"
    },
    {
      "x": -5,
      "y": 20,
      "z": 3,
      "name": "Plant_Crop_Mushroom_Block_Blue"
    },
    {
      "x": -5,
      "y": 17,
      "z": 4,
      "name": "Plant_Crop_Mushroom_Block_Blue_Mycelium"
    },
    {
      "x": -5,
      "y": 18,
      "z": 4,
      "name": "Plant_Crop_Mushroom_Block_Blue"
    },
    {
      "x": -5,
      "y": 19,
      "z": 4,
      "name": "Plant_Crop_Mushroom_Block_Blue"
    },
    {
      "x": -5,
      "y": 20,
      "z": 4,
      "name": "Plant_Crop_Mushroom_Glowing_Blue"
    },
    {
      "x": -5,
      "y": 15,
      "z": 5,
      "name": "Plant_Crop_Mushroom_Block_Blue"
    },
    {
      "x": -5,
      "y": 16,
      "z": 5,
      "name": "Plant_Crop_Mushroom_Block_Blue"
    },
    {
      "x": -5,
      "y": 17,
      "z": 5,
      "name": "Plant_Crop_Mushroom_Block_Blue"
    },
    {
      "x": -5,
      "y": 18,
      "z": 5,
      "name": "Plant_Crop_Mushroom_Block_Blue"
    },
    {
      "x": -5,
      "y": 19,
      "z": 5,
      "name": "Plant_Crop_Mushroom_Glowing_Blue"
    },
    {
      "x": -5,
      "y": 17,
      "z": 6,
      "name": "Plant_Crop_Mushroom_Block_Blue"
    },
    {
      "x": -4,
      "y": 16,
      "z": -6,
      "name": "Plant_Crop_Mushroom_Block_Blue"
    },
    {
      "x": -4,
      "y": 17,
      "z": -6,
      "name": "Plant_Crop_Mushroom_Block_Blue"
    },
    {
      "x": -4,
      "y": 18,
      "z": -6,
      "name": "Plant_Crop_Mushroom_Block_Blue"
    },
    {
      "x": -4,
      "y": 19,
      "z": -6,
      "name": "Plant_Crop_Mushroom_Glowing_Blue"
    },
    {
      "x": -4,
      "y": 17,
      "z": -5,
      "name": "Plant_Crop_Mushroom_Block_Blue_Mycelium"
    },
    {
      "x": -4,
      "y": 18,
      "z": -5,
      "name": "Plant_Crop_Mushroom_Block_Blue"
    },
    {
      "x": -4,
      "y": 19,
      "z": -5,
      "name": "Plant_Crop_Mushroom_Block_Blue"
    },
    {
      "x": -4,
      "y": 20,
      "z": -5,
      "name": "Plant_Crop_Mushroom_Glowing_Blue"
    },
    {
      "x": -4,
      "y": 17,
      "z": -4,
      "name": "Plant_Crop_Mushroom_Block_Blue_Mycelium"
    },
    {
      "x": -4,
      "y": 18,
      "z": -4,
      "name": "Plant_Crop_Mushroom_Block_Blue"
    },
    {
      "x": -4,
      "y": 19,
      "z": -4,
      "name": "Plant_Crop_Mushroom_Block_Blue"
    },
    {
      "x": -4,
      "y": 20,
      "z": -4,
      "name": "Plant_Crop_Mushroom_Block_Blue"
    },
    {
      "x": -4,
      "y": 17,
      "z": -3,
      "name": "Plant_Crop_Mushroom_Block_Blue_Mycelium"
    },
    {
      "x": -4,
      "y": 18,
      "z": -3,
      "name": "Plant_Crop_Mushroom_Block_Blue"
    },
    {
      "x": -4,
      "y": 19,
      "z": -3,
      "name": "Plant_Crop_Mushroom_Block_Blue"
    },
    {
      "x": -4,
      "y": 20,
      "z": -3,
      "name": "Plant_Crop_Mushroom_Block_Blue"
    },
    {
      "x": -4,
      "y": 21,
      "z": -3,
      "name": "Plant_Crop_Mushroom_Glowing_Blue"
    },
    {
      "x": -4,
      "y": 2,
      "z": -2,
      "name": "Plant_Crop_Mushroom_Block_Blue_Trunk"
    },
    {
      "x": -4,
      "y": 3,
      "z": -2,
      "name": "Plant_Crop_Mushroom_Block_Blue_Trunk"
    },
    {
      "x": -4,
      "y": 17,
      "z": -2,
      "name": "Plant_Crop_Mushroom_Block_Blue_Mycelium"
    },
    {
      "x": -4,
      "y": 18,
      "z": -2,
      "name": "Plant_Crop_Mushroom_Block_Blue"
    },
    {
      "x": -4,
      "y": 19,
      "z": -2,
      "name": "Plant_Crop_Mushroom_Block_Blue"
    },
    {
      "x": -4,
      "y": 20,
      "z": -2,
      "name": "Plant_Crop_Mushroom_Block_Blue"
    },
    {
      "x": -4,
      "y": 21,
      "z": -2,
      "name": "Plant_Crop_Mushroom_Block_Blue"
    },
    {
      "x": -4,
      "y": 0,
      "z": -1,
      "name": "Plant_Crop_Mushroom_Block_Blue_Trunk"
    },
    {
      "x": -4,
      "y": 1,
      "z": -1,
      "name": "Plant_Crop_Mushroom_Block_Blue_Trunk"
    },
    {
      "x": -4,
      "y": 2,
      "z": -1,
      "name": "Plant_Crop_Mushroom_Block_Blue_Trunk"
    },
    {
      "x": -4,
      "y": 3,
      "z": -1,
      "name": "Plant_Crop_Mushroom_Block_Blue_Trunk"
    },
    {
      "x": -4,
      "y": 4,
      "z": -1,
      "name": "Plant_Crop_Mushroom_Block_Blue_Trunk"
    },
    {
      "x": -4,
      "y": 5,
      "z": -1,
      "name": "Plant_Crop_Mushroom_Block_Blue_Trunk"
    },
    {
      "x": -4,
      "y": 17,
      "z": -1,
      "name": "Plant_Crop_Mushroom_Block_Blue_Mycelium"
    },
    {
      "x": -4,
      "y": 18,
      "z": -1,
      "name": "Plant_Crop_Mushroom_Block_Blue"
    },
    {
      "x": -4,
      "y": 19,
      "z": -1,
      "name": "Plant_Crop_Mushroom_Block_Blue"
    },
    {
      "x": -4,
      "y": 20,
      "z": -1,
      "name": "Plant_Crop_Mushroom_Block_Blue"
    },
    {
      "x": -4,
      "y": 21,
      "z": -1,
      "name": "Plant_Crop_Mushroom_Block_Blue"
    },
    {
      "x": -4,
      "y": 2,
      "z": 0,
      "name": "Plant_Crop_Mushroom_Block_Blue_Trunk"
    },
    {
      "x": -4,
      "y": 3,
      "z": 0,
      "name": "Plant_Crop_Mushroom_Block_Blue_Trunk"
    },
    {
      "x": -4,
      "y": 4,
      "z": 0,
      "name": "Plant_Crop_Mushroom_Block_Blue_Trunk"
    },
    {
      "x": -4,
      "y": 5,
      "z": 0,
      "name": "Plant_Crop_Mushroom_Block_Blue_Trunk"
    },
    {
      "x": -4,
      "y": 17,
      "z": 0,
      "name": "Plant_Crop_Mushroom_Block_Blue_Mycelium"
    },
    {
      "x": -4,
      "y": 18,
      "z": 0,
      "name": "Plant_Crop_Mushroom_Block_Blue"
    },
    {
      "x": -4,
      "y": 19,
      "z": 0,
      "name": "Plant_Crop_Mushroom_Block_Blue"
    },
    {
      "x": -4,
      "y": 20,
      "z": 0,
      "name": "Plant_Crop_Mushroom_Block_Blue"
    },
    {
      "x": -4,
      "y": 21,
      "z": 0,
      "name": "Plant_Crop_Mushroom_Block_Blue"
    },
    {
      "x": -4,
      "y": 22,
      "z": 0,
      "name": "Plant_Crop_Mushroom_Glowing_Blue"
    },
    {
      "x": -4,
      "y": 1,
      "z": 1,
      "name": "Plant_Crop_Mushroom_Block_Blue_Trunk"
    },
    {
      "x": -4,
      "y": 2,
      "z": 1,
      "name": "Plant_Crop_Mushroom_Block_Blue_Trunk"
    },
    {
      "x": -4,
      "y": 3,
      "z": 1,
      "name": "Plant_Crop_Mushroom_Block_Blue_Trunk"
    },
    {
      "x": -4,
      "y": 4,
      "z": 1,
      "name": "Plant_Crop_Mushroom_Block_Blue_Trunk"
    },
    {
      "x": -4,
      "y": 5,
      "z": 1,
      "name": "Plant_Crop_Mushroom_Block_Blue_Trunk"
    },
    {
      "x": -4,
      "y": 17,
      "z": 1,
      "name": "Plant_Crop_Mushroom_Block_Blue_Mycelium"
    },
    {
      "x": -4,
      "y": 18,
      "z": 1,
      "name": "Plant_Crop_Mushroom_Block_Blue"
    },
    {
      "x": -4,
      "y": 19,
      "z": 1,
      "name": "Plant_Crop_Mushroom_Block_Blue"
    },
    {
      "x": -4,
      "y": 20,
      "z": 1,
      "name": "Plant_Crop_Mushroom_Block_Blue"
    },
    {
      "x": -4,
      "y": 21,
      "z": 1,
      "name": "Plant_Crop_Mushroom_Block_Blue"
    },
    {
      "x": -4,
      "y": 2,
      "z": 2,
      "name": "Plant_Crop_Mushroom_Block_Blue_Trunk"
    },
    {
      "x": -4,
      "y": 3,
      "z": 2,
      "name": "Plant_Crop_Mushroom_Block_Blue_Trunk"
    },
    {
      "x": -4,
      "y": 17,
      "z": 2,
      "name": "Plant_Crop_Mushroom_Block_Blue_Mycelium"
    },
    {
      "x": -4,
      "y": 18,
      "z": 2,
      "name": "Plant_Crop_Mushroom_Block_Blue"
    },
    {
      "x": -4,
      "y": 19,
      "z": 2,
      "name": "Plant_Crop_Mushroom_Block_Blue"
    },
    {
      "x": -4,
      "y": 20,
      "z": 2,
      "name": "Plant_Crop_Mushroom_Block_Blue"
    },
    {
      "x": -4,
      "y": 21,
      "z": 2,
      "name": "Plant_Crop_Mushroom_Block_Blue"
    },
    {
      "x": -4,
      "y": 17,
      "z": 3,
      "name": "Plant_Crop_Mushroom_Block_Blue_Mycelium"
    },
    {
      "x": -4,
      "y": 18,
      "z": 3,
      "name": "Plant_Crop_Mushroom_Block_Blue"
    },
    {
      "x": -4,
      "y": 19,
      "z": 3,
      "name": "Plant_Crop_Mushroom_Block_Blue"
    },
    {
      "x": -4,
      "y": 20,
      "z": 3,
      "name": "Plant_Crop_Mushroom_Block_Blue"
    },
    {
      "x": -4,
      "y": 17,
      "z": 4,
      "name": "Plant_Crop_Mushroom_Block_Blue_Mycelium"
    },
    {
      "x": -4,
      "y": 18,
      "z": 4,
      "name": "Plant_Crop_Mushroom_Block_Blue"
    },
    {
      "x": -4,
      "y": 19,
      "z": 4,
      "name": "Plant_Crop_Mushroom_Block_Blue"
    },
    {
      "x": -4,
      "y": 20,
      "z": 4,
      "name": "Plant_Crop_Mushroom_Block_Blue"
    },
    {
      "x": -4,
      "y": 17,
      "z": 5,
      "name": "Plant_Crop_Mushroom_Block_Blue_Mycelium"
    },
    {
      "x": -4,
      "y": 18,
      "z": 5,
      "name": "Plant_Crop_Mushroom_Block_Blue"
    },
    {
      "x": -4,
      "y": 19,
      "z": 5,
      "name": "Plant_Crop_Mushroom_Block_Blue"
    },
    {
      "x": -4,
      "y": 20,
      "z": 5,
      "name": "Plant_Crop_Mushroom_Glowing_Blue"
    },
    {
      "x": -4,
      "y": 16,
      "z": 6,
      "name": "Plant_Crop_Mushroom_Block_Blue"
    },
    {
      "x": -4,
      "y": 17,
      "z": 6,
      "name": "Plant_Crop_Mushroom_Block_Blue"
    },
    {
      "x": -4,
      "y": 18,
      "z": 6,
      "name": "Plant_Crop_Mushroom_Block_Blue"
    },
    {
      "x": -3,
      "y": 17,
      "z": -7,
      "name": "Plant_Crop_Mushroom_Block_Blue"
    },
    {
      "x": -3,
      "y": 18,
      "z": -7,
      "name": "Plant_Crop_Mushroom_Glowing_Blue"
    },
    {
      "x": -3,
      "y": 16,
      "z": -6,
      "name": "Plant_Crop_Mushroom_Block_Blue"
    },
    {
      "x": -3,
      "y": 17,
      "z": -6,
      "name": "Plant_Crop_Mushroom_Block_Blue"
    },
    {
      "x": -3,
      "y": 18,
      "z": -6,
      "name": "Plant_Crop_Mushroom_Block_Blue"
    },
    {
      "x": -3,
      "y": 19,
      "z": -6,
      "name": "Plant_Crop_Mushroom_Block_Blue"
    },
    {
      "x": -3,
      "y": 17,
      "z": -5,
      "name": "Plant_Crop_Mushroom_Block_Blue_Mycelium"
    },
    {
      "x": -3,
      "y": 18,
      "z": -5,
      "name": "Plant_Crop_Mushroom_Block_Blue"
    },
    {
      "x": -3,
      "y": 19,
      "z": -5,
      "name": "Plant_Crop_Mushroom_Block_Blue"
    },
    {
      "x": -3,
      "y": 20,
      "z": -5,
      "name": "Plant_Crop_Mushroom_Block_Blue"
    },
    {
      "x": -3,
      "y": 17,
      "z": -4,
      "name": "Plant_Crop_Mushroom_Block_Blue_Mycelium"
    },
    {
      "x": -3,
      "y": 18,
      "z": -4,
      "name": "Plant_Crop_Mushroom_Block_Blue"
    },
    {
      "x": -3,
      "y": 19,
      "z": -4,
      "name": "Plant_Crop_Mushroom_Block_Blue"
    },
    {
      "x": -3,
      "y": 20,
      "z": -4,
      "name": "Plant_Crop_Mushroom_Block_Blue"
    },
    {
      "x": -3,
      "y": 0,
      "z": -3,
      "name": "Plant_Crop_Mushroom_Block_Blue_Trunk"
    },
    {
      "x": -3,
      "y": 1,
      "z": -3,
      "name": "Plant_Crop_Mushroom_Block_Blue_Trunk"
    },
    {
      "x": -3,
      "y": 2,
      "z": -3,
      "name": "Plant_Crop_Mushroom_Block_Blue_Trunk"
    },
    {
      "x": -3,
      "y": 3,
      "z": -3,
      "name": "Plant_Crop_Mushroom_Block_Blue_Trunk"
    },
    {
      "x": -3,
      "y": 17,
      "z": -3,
      "name": "Plant_Crop_Mushroom_Block_Blue_Mycelium"
    },
    {
      "x": -3,
      "y": 18,
      "z": -3,
      "name": "Plant_Crop_Mushroom_Block_Blue"
    },
    {
      "x": -3,
      "y": 19,
      "z": -3,
      "name": "Plant_Crop_Mushroom_Block_Blue"
    },
    {
      "x": -3,
      "y": 20,
      "z": -3,
      "name": "Plant_Crop_Mushroom_Block_Blue"
    },
    {
      "x": -3,
      "y": 21,
      "z": -3,
      "name": "Plant_Crop_Mushroom_Block_Blue"
    },
    {
      "x": -3,
      "y": 22,
      "z": -3,
      "name": "Plant_Crop_Mushroom_Glowing_Blue"
    },
    {
      "x": -3,
      "y": 2,
      "z": -2,
      "name": "Plant_Crop_Mushroom_Block_Blue_Trunk"
    },
    {
      "x": -3,
      "y": 3,
      "z": -2,
      "name": "Plant_Crop_Mushroom_Block_Blue_Trunk"
    },
    {
      "x": -3,
      "y": 4,
      "z": -2,
      "name": "Plant_Crop_Mushroom_Block_Blue_Trunk"
    },
    {
      "x": -3,
      "y": 5,
      "z": -2,
      "name": "Plant_Crop_Mushroom_Block_Blue_Trunk"
    },
    {
      "x": -3,
      "y": 16,
      "z": -2,
      "name": "Plant_Crop_Mushroom_Block_Blue_Mycelium"
    },
    {
      "x": -3,
      "y": 17,
      "z": -2,
      "name": "Plant_Crop_Mushroom_Block_Blue_Trunk"
    },
    {
      "x": -3,
      "y": 18,
      "z": -2,
      "name": "Plant_Crop_Mushroom_Block_Blue"
    },
    {
      "x": -3,
      "y": 19,
      "z": -2,
      "name": "Plant_Crop_Mushroom_Block_Blue"
    },
    {
      "x": -3,
      "y": 20,
      "z": -2,
      "name": "Plant_Crop_Mushroom_Block_Blue"
    },
    {
      "x": -3,
      "y": 21,
      "z": -2,
      "name": "Plant_Crop_Mushroom_Block_Blue"
    },
    {
      "x": -3,
      "y": 22,
      "z": -2,
      "name": "Plant_Crop_Mushroom_Glowing_Blue"
    },
    {
      "x": -3,
      "y": 2,
      "z": -1,
      "name": "Plant_Crop_Mushroom_Block_Blue_Trunk"
    },
    {
      "x": -3,
      "y": 3,
      "z": -1,
      "name": "Plant_Crop_Mushroom_Block_Blue_Trunk"
    },
    {
      "x": -3,
      "y": 4,
      "z": -1,
      "name": "Plant_Crop_Mushroom_Block_Blue_Trunk"
    },
    {
      "x": -3,
      "y": 5,
      "z": -1,
      "name": "Plant_Crop_Mushroom_Block_Blue_Trunk"
    },
    {
      "x": -3,
      "y": 6,
      "z": -1,
      "name": "Plant_Crop_Mushroom_Block_Blue_Trunk"
    },
    {
      "x": -3,
      "y": 7,
      "z": -1,
      "name": "Plant_Crop_Mushroom_Block_Blue_Trunk"
    },
    {
      "x": -3,
      "y": 16,
      "z": -1,
      "name": "Plant_Crop_Mushroom_Block_Blue_Mycelium"
    },
    {
      "x": -3,
      "y": 17,
      "z": -1,
      "name": "Plant_Crop_Mushroom_Block_Blue_Trunk"
    },
    {
      "x": -3,
      "y": 18,
      "z": -1,
      "name": "Plant_Crop_Mushroom_Block_Blue"
    },
    {
      "x": -3,
      "y": 19,
      "z": -1,
      "name": "Plant_Crop_Mushroom_Block_Blue"
    },
    {
      "x": -3,
      "y": 20,
      "z": -1,
      "name": "Plant_Crop_Mushroom_Block_Blue"
    },
    {
      "x": -3,
      "y": 21,
      "z": -1,
      "name": "Plant_Crop_Mushroom_Block_Blue"
    },
    {
      "x": -3,
      "y": 22,
      "z": -1,
      "name": "Plant_Crop_Mushroom_Block_Blue"
    },
    {
      "x": -3,
      "y": 0,
      "z": 0,
      "name": "Plant_Crop_Mushroom_Block_Blue_Trunk"
    },
    {
      "x": -3,
      "y": 1,
      "z": 0,
      "name": "Plant_Crop_Mushroom_Block_Blue_Trunk"
    },
    {
      "x": -3,
      "y": 2,
      "z": 0,
      "name": "Plant_Crop_Mushroom_Block_Blue_Trunk"
    },
    {
      "x": -3,
      "y": 3,
      "z": 0,
      "name": "Plant_Crop_Mushroom_Block_Blue_Trunk"
    },
    {
      "x": -3,
      "y": 4,
      "z": 0,
      "name": "Plant_Crop_Mushroom_Block_Blue_Trunk"
    },
    {
      "x": -3,
      "y": 5,
      "z": 0,
      "name": "Plant_Crop_Mushroom_Block_Blue_Trunk"
    },
    {
      "x": -3,
      "y": 6,
      "z": 0,
      "name": "Plant_Crop_Mushroom_Block_Blue_Trunk"
    },
    {
      "x": -3,
      "y": 7,
      "z": 0,
      "name": "Plant_Crop_Mushroom_Block_Blue_Trunk"
    },
    {
      "x": -3,
      "y": 8,
      "z": 0,
      "name": "Plant_Crop_Mushroom_Glowing_Blue"
    },
    {
      "x": -3,
      "y": 16,
      "z": 0,
      "name": "Plant_Crop_Mushroom_Block_Blue_Mycelium"
    },
    {
      "x": -3,
      "y": 17,
      "z": 0,
      "name": "Plant_Crop_Mushroom_Block_Blue_Trunk"
    },
    {
      "x": -3,
      "y": 18,
      "z": 0,
      "name": "Plant_Crop_Mushroom_Block_Blue"
    },
    {
      "x": -3,
      "y": 19,
      "z": 0,
      "name": "Plant_Crop_Mushroom_Block_Blue"
    },
    {
      "x": -3,
      "y": 20,
      "z": 0,
      "name": "Plant_Crop_Mushroom_Block_Blue"
    },
    {
      "x": -3,
      "y": 21,
      "z": 0,
      "name": "Plant_Crop_Mushroom_Block_Blue"
    },
    {
      "x": -3,
      "y": 22,
      "z": 0,
      "name": "Plant_Crop_Mushroom_Block_Blue"
    },
    {
      "x": -3,
      "y": 2,
      "z": 1,
      "name": "Plant_Crop_Mushroom_Block_Blue_Trunk"
    },
    {
      "x": -3,
      "y": 3,
      "z": 1,
      "name": "Plant_Crop_Mushroom_Block_Blue_Trunk"
    },
    {
      "x": -3,
      "y": 4,
      "z": 1,
      "name": "Plant_Crop_Mushroom_Block_Blue_Trunk"
    },
    {
      "x": -3,
      "y": 5,
      "z": 1,
      "name": "Plant_Crop_Mushroom_Block_Blue_Trunk"
    },
    {
      "x": -3,
      "y": 6,
      "z": 1,
      "name": "Plant_Crop_Mushroom_Block_Blue_Trunk"
    },
    {
      "x": -3,
      "y": 7,
      "z": 1,
      "name": "Plant_Crop_Mushroom_Block_Blue_Trunk"
    },
    {
      "x": -3,
      "y": 16,
      "z": 1,
      "name": "Plant_Crop_Mushroom_Block_Blue_Mycelium"
    },
    {
      "x": -3,
      "y": 17,
      "z": 1,
      "name": "Plant_Crop_Mushroom_Block_Blue_Trunk"
    },
    {
      "x": -3,
      "y": 18,
      "z": 1,
      "name": "Plant_Crop_Mushroom_Block_Blue"
    },
    {
      "x": -3,
      "y": 19,
      "z": 1,
      "name": "Plant_Crop_Mushroom_Block_Blue"
    },
    {
      "x": -3,
      "y": 20,
      "z": 1,
      "name": "Plant_Crop_Mushroom_Block_Blue"
    },
    {
      "x": -3,
      "y": 21,
      "z": 1,
      "name": "Plant_Crop_Mushroom_Block_Blue"
    },
    {
      "x": -3,
      "y": 22,
      "z": 1,
      "name": "Plant_Crop_Mushroom_Block_Blue"
    },
    {
      "x": -3,
      "y": 2,
      "z": 2,
      "name": "Plant_Crop_Mushroom_Block_Blue_Trunk"
    },
    {
      "x": -3,
      "y": 3,
      "z": 2,
      "name": "Plant_Crop_Mushroom_Block_Blue_Trunk"
    },
    {
      "x": -3,
      "y": 4,
      "z": 2,
      "name": "Plant_Crop_Mushroom_Block_Blue_Trunk"
    },
    {
      "x": -3,
      "y": 5,
      "z": 2,
      "name": "Plant_Crop_Mushroom_Block_Blue_Trunk"
    },
    {
      "x": -3,
      "y": 16,
      "z": 2,
      "name": "Plant_Crop_Mushroom_Block_Blue_Mycelium"
    },
    {
      "x": -3,
      "y": 17,
      "z": 2,
      "name": "Plant_Crop_Mushroom_Block_Blue_Trunk"
    },
    {
      "x": -3,
      "y": 18,
      "z": 2,
      "name": "Plant_Crop_Mushroom_Block_Blue"
    },
    {
      "x": -3,
      "y": 19,
      "z": 2,
      "name": "Plant_Crop_Mushroom_Block_Blue"
    },
    {
      "x": -3,
      "y": 20,
      "z": 2,
      "name": "Plant_Crop_Mushroom_Block_Blue"
    },
    {
      "x": -3,
      "y": 21,
      "z": 2,
      "name": "Plant_Crop_Mushroom_Block_Blue"
    },
    {
      "x": -3,
      "y": 0,
      "z": 3,
      "name": "Plant_Crop_Mushroom_Block_Blue_Trunk"
    },
    {
      "x": -3,
      "y": 1,
      "z": 3,
      "name": "Plant_Crop_Mushroom_Block_Blue_Trunk"
    },
    {
      "x": -3,
      "y": 2,
      "z": 3,
      "name": "Plant_Crop_Mushroom_Block_Blue_Trunk"
    },
    {
      "x": -3,
      "y": 3,
      "z": 3,
      "name": "Plant_Crop_Mushroom_Block_Blue_Trunk"
    },
    {
      "x": -3,
      "y": 17,
      "z": 3,
      "name": "Plant_Crop_Mushroom_Block_Blue_Mycelium"
    },
    {
      "x": -3,
      "y": 18,
      "z": 3,
      "name": "Plant_Crop_Mushroom_Block_Blue"
    },
    {
      "x": -3,
      "y": 19,
      "z": 3,
      "name": "Plant_Crop_Mushroom_Block_Blue"
    },
    {
      "x": -3,
      "y": 20,
      "z": 3,
      "name": "Plant_Crop_Mushroom_Block_Blue"
    },
    {
      "x": -3,
      "y": 21,
      "z": 3,
      "name": "Plant_Crop_Mushroom_Block_Blue"
    },
    {
      "x": -3,
      "y": 17,
      "z": 4,
      "name": "Plant_Crop_Mushroom_Block_Blue_Mycelium"
    },
    {
      "x": -3,
      "y": 18,
      "z": 4,
      "name": "Plant_Crop_Mushroom_Block_Blue"
    },
    {
      "x": -3,
      "y": 19,
      "z": 4,
      "name": "Plant_Crop_Mushroom_Block_Blue"
    },
    {
      "x": -3,
      "y": 20,
      "z": 4,
      "name": "Plant_Crop_Mushroom_Block_Blue"
    },
    {
      "x": -3,
      "y": 21,
      "z": 4,
      "name": "Plant_Crop_Mushroom_Glowing_Blue"
    },
    {
      "x": -3,
      "y": 17,
      "z": 5,
      "name": "Plant_Crop_Mushroom_Block_Blue_Mycelium"
    },
    {
      "x": -3,
      "y": 18,
      "z": 5,
      "name": "Plant_Crop_Mushroom_Block_Blue"
    },
    {
      "x": -3,
      "y": 19,
      "z": 5,
      "name": "Plant_Crop_Mushroom_Block_Blue"
    },
    {
      "x": -3,
      "y": 20,
      "z": 5,
      "name": "Plant_Crop_Mushroom_Block_Blue"
    },
    {
      "x": -3,
      "y": 16,
      "z": 6,
      "name": "Plant_Crop_Mushroom_Block_Blue"
    },
    {
      "x": -3,
      "y": 17,
      "z": 6,
      "name": "Plant_Crop_Mushroom_Block_Blue"
    },
    {
      "x": -3,
      "y": 18,
      "z": 6,
      "name": "Plant_Crop_Mushroom_Block_Blue"
    },
    {
      "x": -3,
      "y": 19,
      "z": 6,
      "name": "Plant_Crop_Mushroom_Block_Blue"
    },
    {
      "x": -3,
      "y": 17,
      "z": 7,
      "name": "Plant_Crop_Mushroom_Block_Blue"
    },
    {
      "x": -3,
      "y": 18,
      "z": 7,
      "name": "Plant_Crop_Mushroom_Glowing_Blue"
    },
    {
      "x": -2,
      "y": 15,
      "z": -7,
      "name": "Plant_Crop_Mushroom_Block_Blue"
    },
    {
      "x": -2,
      "y": 16,
      "z": -7,
      "name": "Plant_Crop_Mushroom_Block_Blue"
    },
    {
      "x": -2,
      "y": 17,
      "z": -7,
      "name": "Plant_Crop_Mushroom_Block_Blue"
    },
    {
      "x": -2,
      "y": 18,
      "z": -7,
      "name": "Plant_Crop_Mushroom_Block_Blue"
    },
    {
      "x": -2,
      "y": 19,
      "z": -7,
      "name": "Plant_Crop_Mushroom_Glowing_Blue"
    },
    {
      "x": -2,
      "y": 17,
      "z": -6,
      "name": "Plant_Crop_Mushroom_Block_Blue_Mycelium"
    },
    {
      "x": -2,
      "y": 18,
      "z": -6,
      "name": "Plant_Crop_Mushroom_Block_Blue"
    },
    {
      "x": -2,
      "y": 19,
      "z": -6,
      "name": "Plant_Crop_Mushroom_Block_Blue"
    },
    {
      "x": -2,
      "y": 20,
      "z": -6,
      "name": "Plant_Crop_Mushroom_Glowing_Blue"
    },
    {
      "x": -2,
      "y": 17,
      "z": -5,
      "name": "Plant_Crop_Mushroom_Block_Blue_Mycelium"
    },
    {
      "x": -2,
      "y": 18,
      "z": -5,
      "name": "Plant_Crop_Mushroom_Block_Blue"
    },
    {
      "x": -2,
      "y": 19,
      "z": -5,
      "name": "Plant_Crop_Mushroom_Block_Blue"
    },
    {
      "x": -2,
      "y": 20,
      "z": -5,
      "name": "Plant_Crop_Mushroom_Block_Blue"
    },
    {
      "x": -2,
      "y": 1,
      "z": -4,
      "name": "Plant_Crop_Mushroom_Block_Blue_Trunk"
    },
    {
      "x": -2,
      "y": 2,
      "z": -4,
      "name": "Plant_Crop_Mushroom_Block_Blue_Trunk"
    },
    {
      "x": -2,
      "y": 3,
      "z": -4,
      "name": "Plant_Crop_Mushroom_Block_Blue_Trunk"
    },
    {
      "x": -2,
      "y": 17,
      "z": -4,
      "name": "Plant_Crop_Mushroom_Block_Blue_Mycelium"
    },
    {
      "x": -2,
      "y": 18,
      "z": -4,
      "name": "Plant_Crop_Mushroom_Block_Blue"
    },
    {
      "x": -2,
      "y": 19,
      "z": -4,
      "name": "Plant_Crop_Mushroom_Block_Blue"
    },
    {
      "x": -2,
      "y": 20,
      "z": -4,
      "name": "Plant_Crop_Mushroom_Block_Blue"
    },
    {
      "x": -2,
      "y": 21,
      "z": -4,
      "name": "Plant_Crop_Mushroom_Block_Blue"
    },
    {
      "x": -2,
      "y": 2,
      "z": -3,
      "name": "Plant_Crop_Mushroom_Block_Blue_Trunk"
    },
    {
      "x": -2,
      "y": 3,
      "z": -3,
      "name": "Plant_Crop_Mushroom_Block_Blue_Trunk"
    },
    {
      "x": -2,
      "y": 4,
      "z": -3,
      "name": "Plant_Crop_Mushroom_Block_Blue_Trunk"
    },
    {
      "x": -2,
      "y": 5,
      "z": -3,
      "name": "Plant_Crop_Mushroom_Block_Blue_Trunk"
    },
    {
      "x": -2,
      "y": 16,
      "z": -3,
      "name": "Plant_Crop_Mushroom_Block_Blue_Mycelium"
    },
    {
      "x": -2,
      "y": 17,
      "z": -3,
      "name": "Plant_Crop_Mushroom_Block_Blue_Trunk"
    },
    {
      "x": -2,
      "y": 18,
      "z": -3,
      "name": "Plant_Crop_Mushroom_Block_Blue"
    },
    {
      "x": -2,
      "y": 19,
      "z": -3,
      "name": "Plant_Crop_Mushroom_Block_Blue"
    },
    {
      "x": -2,
      "y": 20,
      "z": -3,
      "name": "Plant_Crop_Mushroom_Block_Blue"
    },
    {
      "x": -2,
      "y": 21,
      "z": -3,
      "name": "Plant_Crop_Mushroom_Block_Blue"
    },
    {
      "x": -2,
      "y": 22,
      "z": -3,
      "name": "Plant_Crop_Mushroom_Glowing_Blue"
    },
    {
      "x": -2,
      "y": 2,
      "z": -2,
      "name": "Plant_Crop_Mushroom_Block_Blue_Trunk"
    },
    {
      "x": -2,
      "y": 3,
      "z": -2,
      "name": "Plant_Crop_Mushroom_Block_Blue_Trunk"
    },
    {
      "x": -2,
      "y": 4,
      "z": -2,
      "name": "Plant_Crop_Mushroom_Block_Blue_Trunk"
    },
    {
      "x": -2,
      "y": 5,
      "z": -2,
      "name": "Plant_Crop_Mushroom_Block_Blue_Trunk"
    },
    {
      "x": -2,
      "y": 6,
      "z": -2,
      "name": "Plant_Crop_Mushroom_Block_Blue_Trunk"
    },
    {
      "x": -2,
      "y": 7,
      "z": -2,
      "name": "Plant_Crop_Mushroom_Block_Blue_Trunk"
    },
    {
      "x": -2,
      "y": 16,
      "z": -2,
      "name": "Plant_Crop_Mushroom_Block_Blue_Mycelium"
    },
    {
      "x": -2,
      "y": 17,
      "z": -2,
      "name": "Plant_Crop_Mushroom_Block_Blue_Trunk"
    },
    {
      "x": -2,
      "y": 18,
      "z": -2,
      "name": "Plant_Crop_Mushroom_Block_Blue"
    },
    {
      "x": -2,
      "y": 19,
      "z": -2,
      "name": "Plant_Crop_Mushroom_Block_Blue"
    },
    {
      "x": -2,
      "y": 20,
      "z": -2,
      "name": "Plant_Crop_Mushroom_Block_Blue"
    },
    {
      "x": -2,
      "y": 21,
      "z": -2,
      "name": "Plant_Crop_Mushroom_Block_Blue"
    },
    {
      "x": -2,
      "y": 22,
      "z": -2,
      "name": "Plant_Crop_Mushroom_Block_Blue"
    },
    {
      "x": -2,
      "y": 1,
      "z": -1,
      "name": "Plant_Crop_Mushroom_Block_Blue_Trunk"
    },
    {
      "x": -2,
      "y": 2,
      "z": -1,
      "name": "Plant_Crop_Mushroom_Block_Blue_Trunk"
    },
    {
      "x": -2,
      "y": 3,
      "z": -1,
      "name": "Plant_Crop_Mushroom_Block_Blue_Trunk"
    },
    {
      "x": -2,
      "y": 4,
      "z": -1,
      "name": "Plant_Crop_Mushroom_Block_Blue_Trunk"
    },
    {
      "x": -2,
      "y": 5,
      "z": -1,
      "name": "Plant_Crop_Mushroom_Block_Blue_Trunk"
    },
    {
      "x": -2,
      "y": 6,
      "z": -1,
      "name": "Plant_Crop_Mushroom_Block_Blue_Trunk"
    },
    {
      "x": -2,
      "y": 7,
      "z": -1,
      "name": "Plant_Crop_Mushroom_Block_Blue_Trunk"
    },
    {
      "x": -2,
      "y": 8,
      "z": -1,
      "name": "Plant_Crop_Mushroom_Block_Blue_Trunk"
    },
    {
      "x": -2,
      "y": 15,
      "z": -1,
      "name": "Plant_Crop_Mushroom_Block_Blue_Mycelium"
    },
    {
      "x": -2,
      "y": 16,
      "z": -1,
      "name": "Plant_Crop_Mushroom_Block_Blue_Trunk"
    },
    {
      "x": -2,
      "y": 17,
      "z": -1,
      "name": "Plant_Crop_Mushroom_Block_Blue"
    },
    {
      "x": -2,
      "y": 18,
      "z": -1,
      "name": "Plant_Crop_Mushroom_Block_Blue"
    },
    {
      "x": -2,
      "y": 19,
      "z": -1,
      "name": "Plant_Crop_Mushroom_Block_Blue"
    },
    {
      "x": -2,
      "y": 20,
      "z": -1,
      "name": "Plant_Crop_Mushroom_Block_Blue"
    },
    {
      "x": -2,
      "y": 21,
      "z": -1,
      "name": "Plant_Crop_Mushroom_Block_Blue"
    },
    {
      "x": -2,
      "y": 22,
      "z": -1,
      "name": "Plant_Crop_Mushroom_Block_Blue"
    },
    {
      "x": -2,
      "y": 2,
      "z": 0,
      "name": "Plant_Crop_Mushroom_Block_Blue_Trunk"
    },
    {
      "x": -2,
      "y": 3,
      "z": 0,
      "name": "Plant_Crop_Mushroom_Block_Blue_Trunk"
    },
    {
      "x": -2,
      "y": 4,
      "z": 0,
      "name": "Plant_Crop_Mushroom_Block_Blue_Trunk"
    },
    {
      "x": -2,
      "y": 5,
      "z": 0,
      "name": "Plant_Crop_Mushroom_Block_Blue_Trunk"
    },
    {
      "x": -2,
      "y": 6,
      "z": 0,
      "name": "Plant_Crop_Mushroom_Block_Blue_Trunk"
    },
    {
      "x": -2,
      "y": 7,
      "z": 0,
      "name": "Plant_Crop_Mushroom_Block_Blue_Trunk"
    },
    {
      "x": -2,
      "y": 8,
      "z": 0,
      "name": "Plant_Crop_Mushroom_Block_Blue_Trunk"
    },
    {
      "x": -2,
      "y": 9,
      "z": 0,
      "name": "Plant_Crop_Mushroom_Block_Blue_Trunk"
    },
    {
      "x": -2,
      "y": 10,
      "z": 0,
      "name": "Plant_Crop_Mushroom_Glowing_Blue"
    },
    {
      "x": -2,
      "y": 14,
      "z": 0,
      "name": "Plant_Crop_Mushroom_Block_Blue_Mycelium"
    },
    {
      "x": -2,
      "y": 15,
      "z": 0,
      "name": "Plant_Crop_Mushroom_Block_Blue_Trunk"
    },
    {
      "x": -2,
      "y": 16,
      "z": 0,
      "name": "Plant_Crop_Mushroom_Block_Blue_Trunk"
    },
    {
      "x": -2,
      "y": 17,
      "z": 0,
      "name": "Plant_Crop_Mushroom_Block_Blue"
    },
    {
      "x": -2,
      "y": 18,
      "z": 0,
      "name": "Plant_Crop_Mushroom_Block_Blue"
    },
    {
      "x": -2,
      "y": 19,
      "z": 0,
      "name": "Plant_Crop_Mushroom_Block_Blue"
    },
    {
      "x": -2,
      "y": 20,
      "z": 0,
      "name": "Plant_Crop_Mushroom_Block_Blue"
    },
    {
      "x": -2,
      "y": 21,
      "z": 0,
      "name": "Plant_Crop_Mushroom_Block_Blue"
    },
    {
      "x": -2,
      "y": 22,
      "z": 0,
      "name": "Plant_Crop_Mushroom_Block_Blue"
    },
    {
      "x": -2,
      "y": 23,
      "z": 0,
      "name": "Plant_Crop_Mushroom_Glowing_Blue"
    },
    {
      "x": -2,
      "y": 1,
      "z": 1,
      "name": "Plant_Crop_Mushroom_Block_Blue_Trunk"
    },
    {
      "x": -2,
      "y": 2,
      "z": 1,
      "name": "Plant_Crop_Mushroom_Block_Blue_Trunk"
    },
    {
      "x": -2,
      "y": 3,
      "z": 1,
      "name": "Plant_Crop_Mushroom_Block_Blue_Trunk"
    },
    {
      "x": -2,
      "y": 4,
      "z": 1,
      "name": "Plant_Crop_Mushroom_Block_Blue_Trunk"
    },
    {
      "x": -2,
      "y": 5,
      "z": 1,
      "name": "Plant_Crop_Mushroom_Block_Blue_Trunk"
    },
    {
      "x": -2,
      "y": 6,
      "z": 1,
      "name": "Plant_Crop_Mushroom_Block_Blue_Trunk"
    },
    {
      "x": -2,
      "y": 7,
      "z": 1,
      "name": "Plant_Crop_Mushroom_Block_Blue_Trunk"
    },
    {
      "x": -2,
      "y": 8,
      "z": 1,
      "name": "Plant_Crop_Mushroom_Block_Blue_Trunk"
    },
    {
      "x": -2,
      "y": 9,
      "z": 1,
      "name": "Plant_Crop_Mushroom_Block_Blue_Trunk"
    },
    {
      "x": -2,
      "y": 10,
      "z": 1,
      "name": "Plant_Crop_Mushroom_Block_Blue_Trunk"
    },
    {
      "x": -2,
      "y": 11,
      "z": 1,
      "name": "Plant_Crop_Mushroom_Glowing_Blue"
    },
    {
      "x": -2,
      "y": 15,
      "z": 1,
      "name": "Plant_Crop_Mushroom_Block_Blue_Mycelium"
    },
    {
      "x": -2,
      "y": 16,
      "z": 1,
      "name": "Plant_Crop_Mushroom_Block_Blue_Trunk"
    },
    {
      "x": -2,
      "y": 17,
      "z": 1,
      "name": "Plant_Crop_Mushroom_Block_Blue"
    },
    {
      "x": -2,
      "y": 18,
      "z": 1,
      "name": "Plant_Crop_Mushroom_Block_Blue"
    },
    {
      "x": -2,
      "y": 19,
      "z": 1,
      "name": "Plant_Crop_Mushroom_Block_Blue"
    },
    {
      "x": -2,
      "y": 20,
      "z": 1,
      "name": "Plant_Crop_Mushroom_Block_Blue"
    },
    {
      "x": -2,
      "y": 21,
      "z": 1,
      "name": "Plant_Crop_Mushroom_Block_Blue"
    },
    {
      "x": -2,
      "y": 22,
      "z": 1,
      "name": "Plant_Crop_Mushroom_Block_Blue"
    },
    {
      "x": -2,
      "y": 2,
      "z": 2,
      "name": "Plant_Crop_Mushroom_Block_Blue_Trunk"
    },
    {
      "x": -2,
      "y": 3,
      "z": 2,
      "name": "Plant_Crop_Mushroom_Block_Blue_Trunk"
    },
    {
      "x": -2,
      "y": 4,
      "z": 2,
      "name": "Plant_Crop_Mushroom_Block_Blue_Trunk"
    },
    {
      "x": -2,
      "y": 5,
      "z": 2,
      "name": "Plant_Crop_Mushroom_Block_Blue_Trunk"
    },
    {
      "x": -2,
      "y": 6,
      "z": 2,
      "name": "Plant_Crop_Mushroom_Block_Blue_Trunk"
    },
    {
      "x": -2,
      "y": 7,
      "z": 2,
      "name": "Plant_Crop_Mushroom_Block_Blue_Trunk"
    },
    {
      "x": -2,
      "y": 8,
      "z": 2,
      "name": "Plant_Crop_Mushroom_Block_Blue_Trunk"
    },
    {
      "x": -2,
      "y": 15,
      "z": 2,
      "name": "Plant_Crop_Mushroom_Block_Blue_Mycelium"
    },
    {
      "x": -2,
      "y": 16,
      "z": 2,
      "name": "Plant_Crop_Mushroom_Block_Blue_Trunk"
    },
    {
      "x": -2,
      "y": 17,
      "z": 2,
      "name": "Plant_Crop_Mushroom_Block_Blue"
    },
    {
      "x": -2,
      "y": 18,
      "z": 2,
      "name": "Plant_Crop_Mushroom_Block_Blue"
    },
    {
      "x": -2,
      "y": 19,
      "z": 2,
      "name": "Plant_Crop_Mushroom_Block_Blue"
    },
    {
      "x": -2,
      "y": 20,
      "z": 2,
      "name": "Plant_Crop_Mushroom_Block_Blue"
    },
    {
      "x": -2,
      "y": 21,
      "z": 2,
      "name": "Plant_Crop_Mushroom_Block_Blue"
    },
    {
      "x": -2,
      "y": 22,
      "z": 2,
      "name": "Plant_Crop_Mushroom_Block_Blue"
    },
    {
      "x": -2,
      "y": 23,
      "z": 2,
      "name": "Plant_Crop_Mushroom_Glowing_Blue"
    },
    {
      "x": -2,
      "y": 2,
      "z": 3,
      "name": "Plant_Crop_Mushroom_Block_Blue_Trunk"
    },
    {
      "x": -2,
      "y": 3,
      "z": 3,
      "name": "Plant_Crop_Mushroom_Block_Blue_Trunk"
    },
    {
      "x": -2,
      "y": 4,
      "z": 3,
      "name": "Plant_Crop_Mushroom_Block_Blue_Trunk"
    },
    {
      "x": -2,
      "y": 5,
      "z": 3,
      "name": "Plant_Crop_Mushroom_Block_Blue_Trunk"
    },
    {
      "x": -2,
      "y": 16,
      "z": 3,
      "name": "Plant_Crop_Mushroom_Block_Blue_Mycelium"
    },
    {
      "x": -2,
      "y": 17,
      "z": 3,
      "name": "Plant_Crop_Mushroom_Block_Blue_Trunk"
    },
    {
      "x": -2,
      "y": 18,
      "z": 3,
      "name": "Plant_Crop_Mushroom_Block_Blue"
    },
    {
      "x": -2,
      "y": 19,
      "z": 3,
      "name": "Plant_Crop_Mushroom_Block_Blue"
    },
    {
      "x": -2,
      "y": 20,
      "z": 3,
      "name": "Plant_Crop_Mushroom_Block_Blue"
    },
    {
      "x": -2,
      "y": 21,
      "z": 3,
      "name": "Plant_Crop_Mushroom_Block_Blue"
    },
    {
      "x": -2,
      "y": 22,
      "z": 3,
      "name": "Plant_Crop_Mushroom_Glowing_Blue"
    },
    {
      "x": -2,
      "y": 2,
      "z": 4,
      "name": "Plant_Crop_Mushroom_Block_Blue_Trunk"
    },
    {
      "x": -2,
      "y": 3,
      "z": 4,
      "name": "Plant_Crop_Mushroom_Block_Blue_Trunk"
    },
    {
      "x": -2,
      "y": 17,
      "z": 4,
      "name": "Plant_Crop_Mushroom_Block_Blue_Mycelium"
    },
    {
      "x": -2,
      "y": 18,
      "z": 4,
      "name": "Plant_Crop_Mushroom_Block_Blue"
    },
    {
      "x": -2,
      "y": 19,
      "z": 4,
      "name": "Plant_Crop_Mushroom_Block_Blue"
    },
    {
      "x": -2,
      "y": 20,
      "z": 4,
      "name": "Plant_Crop_Mushroom_Block_Blue"
    },
    {
      "x": -2,
      "y": 21,
      "z": 4,
      "name": "Plant_Crop_Mushroom_Block_Blue"
    },
    {
      "x": -2,
      "y": 17,
      "z": 5,
      "name": "Plant_Crop_Mushroom_Block_Blue_Mycelium"
    },
    {
      "x": -2,
      "y": 18,
      "z": 5,
      "name": "Plant_Crop_Mushroom_Block_Blue"
    },
    {
      "x": -2,
      "y": 19,
      "z": 5,
      "name": "Plant_Crop_Mushroom_Block_Blue"
    },
    {
      "x": -2,
      "y": 20,
      "z": 5,
      "name": "Plant_Crop_Mushroom_Block_Blue"
    },
    {
      "x": -2,
      "y": 17,
      "z": 6,
      "name": "Plant_Crop_Mushroom_Block_Blue_Mycelium"
    },
    {
      "x": -2,
      "y": 18,
      "z": 6,
      "name": "Plant_Crop_Mushroom_Block_Blue"
    },
    {
      "x": -2,
      "y": 19,
      "z": 6,
      "name": "Plant_Crop_Mushroom_Block_Blue"
    },
    {
      "x": -2,
      "y": 20,
      "z": 6,
      "name": "Plant_Crop_Mushroom_Glowing_Blue"
    },
    {
      "x": -2,
      "y": 15,
      "z": 7,
      "name": "Plant_Crop_Mushroom_Block_Blue"
    },
    {
      "x": -2,
      "y": 16,
      "z": 7,
      "name": "Plant_Crop_Mushroom_Block_Blue"
    },
    {
      "x": -2,
      "y": 17,
      "z": 7,
      "name": "Plant_Crop_Mushroom_Block_Blue"
    },
    {
      "x": -2,
      "y": 18,
      "z": 7,
      "name": "Plant_Crop_Mushroom_Block_Blue"
    },
    {
      "x": -2,
      "y": 19,
      "z": 7,
      "name": "Plant_Crop_Mushroom_Glowing_Blue"
    },
    {
      "x": -1,
      "y": 16,
      "z": -8,
      "name": "Plant_Crop_Mushroom_Block_Blue"
    },
    {
      "x": -1,
      "y": 17,
      "z": -8,
      "name": "Plant_Crop_Mushroom_Block_Blue"
    },
    {
      "x": -1,
      "y": 18,
      "z": -8,
      "name": "Plant_Crop_Mushroom_Glowing_Blue"
    },
    {
      "x": -1,
      "y": 16,
      "z": -7,
      "name": "Plant_Crop_Mushroom_Block_Blue"
    },
    {
      "x": -1,
      "y": 17,
      "z": -7,
      "name": "Plant_Crop_Mushroom_Block_Blue"
    },
    {
      "x": -1,
      "y": 18,
      "z": -7,
      "name": "Plant_Crop_Mushroom_Block_Blue"
    },
    {
      "x": -1,
      "y": 19,
      "z": -7,
      "name": "Plant_Crop_Mushroom_Block_Blue"
    },
    {
      "x": -1,
      "y": 17,
      "z": -6,
      "name": "Plant_Crop_Mushroom_Block_Blue_Mycelium"
    },
    {
      "x": -1,
      "y": 18,
      "z": -6,
      "name": "Plant_Crop_Mushroom_Block_Blue"
    },
    {
      "x": -1,
      "y": 19,
      "z": -6,
      "name": "Plant_Crop_Mushroom_Block_Blue"
    },
    {
      "x": -1,
      "y": 20,
      "z": -6,
      "name": "Plant_Crop_Mushroom_Block_Blue"
    },
    {
      "x": -1,
      "y": 0,
      "z": -5,
      "name": "Plant_Crop_Mushroom_Block_Blue_Trunk"
    },
    {
      "x": -1,
      "y": 1,
      "z": -5,
      "name": "Plant_Crop_Mushroom_Block_Blue_Trunk"
    },
    {
      "x": -1,
      "y": 2,
      "z": -5,
      "name": "Plant_Crop_Mushroom_Block_Blue_Trunk"
    },
    {
      "x": -1,
      "y": 3,
      "z": -5,
      "name": "Plant_Crop_Mushroom_Block_Blue_Trunk"
    },
    {
      "x": -1,
      "y": 17,
      "z": -5,
      "name": "Plant_Crop_Mushroom_Block_Blue_Mycelium"
    },
    {
      "x": -1,
      "y": 18,
      "z": -5,
      "name": "Plant_Crop_Mushroom_Block_Blue"
    },
    {
      "x": -1,
      "y": 19,
      "z": -5,
      "name": "Plant_Crop_Mushroom_Block_Blue"
    },
    {
      "x": -1,
      "y": 20,
      "z": -5,
      "name": "Plant_Crop_Mushroom_Block_Blue"
    },
    {
      "x": -1,
      "y": 21,
      "z": -5,
      "name": "Plant_Crop_Mushroom_Glowing_Blue"
    },
    {
      "x": -1,
      "y": 2,
      "z": -4,
      "name": "Plant_Crop_Mushroom_Block_Blue_Trunk"
    },
    {
      "x": -1,
      "y": 3,
      "z": -4,
      "name": "Plant_Crop_Mushroom_Block_Blue_Trunk"
    },
    {
      "x": -1,
      "y": 4,
      "z": -4,
      "name": "Plant_Crop_Mushroom_Block_Blue_Trunk"
    },
    {
      "x": -1,
      "y": 5,
      "z": -4,
      "name": "Plant_Crop_Mushroom_Block_Blue_Trunk"
    },
    {
      "x": -1,
      "y": 17,
      "z": -4,
      "name": "Plant_Crop_Mushroom_Block_Blue_Mycelium"
    },
    {
      "x": -1,
      "y": 18,
      "z": -4,
      "name": "Plant_Crop_Mushroom_Block_Blue"
    },
    {
      "x": -1,
      "y": 19,
      "z": -4,
      "name": "Plant_Crop_Mushroom_Block_Blue"
    },
    {
      "x": -1,
      "y": 20,
      "z": -4,
      "name": "Plant_Crop_Mushroom_Block_Blue"
    },
    {
      "x": -1,
      "y": 21,
      "z": -4,
      "name": "Plant_Crop_Mushroom_Block_Blue"
    },
    {
      "x": -1,
      "y": 1,
      "z": -3,
      "name": "Plant_Crop_Mushroom_Block_Blue_Trunk"
    },
    {
      "x": -1,
      "y": 2,
      "z": -3,
      "name": "Plant_Crop_Mushroom_Block_Blue_Trunk"
    },
    {
      "x": -1,
      "y": 3,
      "z": -3,
      "name": "Plant_Crop_Mushroom_Block_Blue_Trunk"
    },
    {
      "x": -1,
      "y": 4,
      "z": -3,
      "name": "Plant_Crop_Mushroom_Block_Blue_Trunk"
    },
    {
      "x": -1,
      "y": 5,
      "z": -3,
      "name": "Plant_Crop_Mushroom_Block_Blue_Trunk"
    },
    {
      "x": -1,
      "y": 6,
      "z": -3,
      "name": "Plant_Crop_Mushroom_Block_Blue_Trunk"
    },
    {
      "x": -1,
      "y": 7,
      "z": -3,
      "name": "Plant_Crop_Mushroom_Block_Blue_Trunk"
    },
    {
      "x": -1,
      "y": 16,
      "z": -3,
      "name": "Plant_Crop_Mushroom_Block_Blue_Mycelium"
    },
    {
      "x": -1,
      "y": 17,
      "z": -3,
      "name": "Plant_Crop_Mushroom_Block_Blue_Trunk"
    },
    {
      "x": -1,
      "y": 18,
      "z": -3,
      "name": "Plant_Crop_Mushroom_Block_Blue"
    },
    {
      "x": -1,
      "y": 19,
      "z": -3,
      "name": "Plant_Crop_Mushroom_Block_Blue"
    },
    {
      "x": -1,
      "y": 20,
      "z": -3,
      "name": "Plant_Crop_Mushroom_Block_Blue"
    },
    {
      "x": -1,
      "y": 21,
      "z": -3,
      "name": "Plant_Crop_Mushroom_Block_Blue"
    },
    {
      "x": -1,
      "y": 22,
      "z": -3,
      "name": "Plant_Crop_Mushroom_Block_Blue"
    },
    {
      "x": -1,
      "y": 2,
      "z": -2,
      "name": "Plant_Crop_Mushroom_Block_Blue_Trunk"
    },
    {
      "x": -1,
      "y": 3,
      "z": -2,
      "name": "Plant_Crop_Mushroom_Block_Blue_Trunk"
    },
    {
      "x": -1,
      "y": 4,
      "z": -2,
      "name": "Plant_Crop_Mushroom_Block_Blue_Trunk"
    },
    {
      "x": -1,
      "y": 5,
      "z": -2,
      "name": "Plant_Crop_Mushroom_Block_Blue_Trunk"
    },
    {
      "x": -1,
      "y": 6,
      "z": -2,
      "name": "Plant_Crop_Mushroom_Block_Blue_Trunk"
    },
    {
      "x": -1,
      "y": 7,
      "z": -2,
      "name": "Plant_Crop_Mushroom_Block_Blue_Trunk"
    },
    {
      "x": -1,
      "y": 8,
      "z": -2,
      "name": "Plant_Crop_Mushroom_Block_Blue_Trunk"
    },
    {
      "x": -1,
      "y": 9,
      "z": -2,
      "name": "Plant_Crop_Mushroom_Glowing_Blue"
    },
    {
      "x": -1,
      "y": 15,
      "z": -2,
      "name": "Plant_Crop_Mushroom_Block_Blue_Mycelium"
    },
    {
      "x": -1,
      "y": 16,
      "z": -2,
      "name": "Plant_Crop_Mushroom_Block_Blue_Trunk"
    },
    {
      "x": -1,
      "y": 17,
      "z": -2,
      "name": "Plant_Crop_Mushroom_Block_Blue"
    },
    {
      "x": -1,
      "y": 18,
      "z": -2,
      "name": "Plant_Crop_Mushroom_Block_Blue"
    },
    {
      "x": -1,
      "y": 19,
      "z": -2,
      "name": "Plant_Crop_Mushroom_Block_Blue"
    },
    {
      "x": -1,
      "y": 20,
      "z": -2,
      "name": "Plant_Crop_Mushroom_Block_Blue"
    },
    {
      "x": -1,
      "y": 21,
      "z": -2,
      "name": "Plant_Crop_Mushroom_Block_Blue"
    },
    {
      "x": -1,
      "y": 22,
      "z": -2,
      "name": "Plant_Crop_Mushroom_Block_Blue"
    },
    {
      "x": -1,
      "y": 23,
      "z": -2,
      "name": "Plant_Crop_Mushroom_Glowing_Blue"
    },
    {
      "x": -1,
      "y": 0,
      "z": -1,
      "name": "Plant_Crop_Mushroom_Block_Blue_Trunk"
    },
    {
      "x": -1,
      "y": 1,
      "z": -1,
      "name": "Plant_Crop_Mushroom_Block_Blue_Trunk"
    },
    {
      "x": -1,
      "y": 2,
      "z": -1,
      "name": "Plant_Crop_Mushroom_Block_Blue_Trunk"
    },
    {
      "x": -1,
      "y": 3,
      "z": -1,
      "name": "Plant_Crop_Mushroom_Block_Blue_Trunk"
    },
    {
      "x": -1,
      "y": 4,
      "z": -1,
      "name": "Plant_Crop_Mushroom_Block_Blue_Trunk"
    },
    {
      "x": -1,
      "y": 5,
      "z": -1,
      "name": "Plant_Crop_Mushroom_Block_Blue_Trunk"
    },
    {
      "x": -1,
      "y": 6,
      "z": -1,
      "name": "Plant_Crop_Mushroom_Block_Blue_Trunk"
    },
    {
      "x": -1,
      "y": 7,
      "z": -1,
      "name": "Plant_Crop_Mushroom_Block_Blue_Trunk"
    },
    {
      "x": -1,
      "y": 8,
      "z": -1,
      "name": "Plant_Crop_Mushroom_Block_Blue_Trunk"
    },
    {
      "x": -1,
      "y": 9,
      "z": -1,
      "name": "Plant_Crop_Mushroom_Block_Blue_Trunk"
    },
    {
      "x": -1,
      "y": 10,
      "z": -1,
      "name": "Plant_Crop_Mushroom_Block_Blue_Trunk"
    },
    {
      "x": -1,
      "y": 11,
      "z": -1,
      "name": "Plant_Crop_Mushroom_Block_Blue_Trunk"
    },
    {
      "x": -1,
      "y": 12,
      "z": -1,
      "name": "Plant_Crop_Mushroom_Glowing_Blue"
    },
    {
      "x": -1,
      "y": 14,
      "z": -1,
      "name": "Plant_Crop_Mushroom_Block_Blue_Mycelium"
    },
    {
      "x": -1,
      "y": 15,
      "z": -1,
      "name": "Plant_Crop_Mushroom_Block_Blue_Trunk"
    },
    {
      "x": -1,
      "y": 16,
      "z": -1,
      "name": "Plant_Crop_Mushroom_Block_Blue_Trunk"
    },
    {
      "x": -1,
      "y": 17,
      "z": -1,
      "name": "Plant_Crop_Mushroom_Block_Blue"
    },
    {
      "x": -1,
      "y": 18,
      "z": -1,
      "name": "Plant_Crop_Mushroom_Block_Blue"
    },
    {
      "x": -1,
      "y": 19,
      "z": -1,
      "name": "Plant_Crop_Mushroom_Block_Blue"
    },
    {
      "x": -1,
      "y": 20,
      "z": -1,
      "name": "Plant_Crop_Mushroom_Block_Blue"
    },
    {
      "x": -1,
      "y": 21,
      "z": -1,
      "name": "Plant_Crop_Mushroom_Block_Blue"
    },
    {
      "x": -1,
      "y": 22,
      "z": -1,
      "name": "Plant_Crop_Mushroom_Block_Blue"
    },
    {
      "x": -1,
      "y": 2,
      "z": 0,
      "name": "Plant_Crop_Mushroom_Block_Blue_Trunk"
    },
    {
      "x": -1,
      "y": 3,
      "z": 0,
      "name": "Plant_Crop_Mushroom_Block_Blue_Trunk"
    },
    {
      "x": -1,
      "y": 4,
      "z": 0,
      "name": "Plant_Crop_Mushroom_Block_Blue_Trunk"
    },
    {
      "x": -1,
      "y": 5,
      "z": 0,
      "name": "Plant_Crop_Mushroom_Block_Blue_Trunk"
    },
    {
      "x": -1,
      "y": 6,
      "z": 0,
      "name": "Plant_Crop_Mushroom_Block_Blue_Trunk"
    },
    {
      "x": -1,
      "y": 7,
      "z": 0,
      "name": "Plant_Crop_Mushroom_Block_Blue_Trunk"
    },
    {
      "x": -1,
      "y": 8,
      "z": 0,
      "name": "Plant_Crop_Mushroom_Block_Blue_Trunk"
    },
    {
      "x": -1,
      "y": 9,
      "z": 0,
      "name": "Plant_Crop_Mushroom_Block_Blue_Trunk"
    },
    {
      "x": -1,
      "y": 10,
      "z": 0,
      "name": "Plant_Crop_Mushroom_Block_Blue_Trunk"
    },
    {
      "x": -1,
      "y": 11,
      "z": 0,
      "name": "Plant_Crop_Mushroom_Block_Blue_Trunk"
    },
    {
      "x": -1,
      "y": 12,
      "z": 0,
      "name": "Plant_Crop_Mushroom_Block_Blue_Trunk"
    },
    {
      "x": -1,
      "y": 13,
      "z": 0,
      "name": "Plant_Crop_Mushroom_Block_Blue_Trunk"
    },
    {
      "x": -1,
      "y": 14,
      "z": 0,
      "name": "Plant_Crop_Mushroom_Block_Blue_Trunk"
    },
    {
      "x": -1,
      "y": 15,
      "z": 0,
      "name": "Plant_Crop_Mushroom_Block_Blue_Trunk"
    },
    {
      "x": -1,
      "y": 16,
      "z": 0,
      "name": "Plant_Crop_Mushroom_Block_Blue_Trunk"
    },
    {
      "x": -1,
      "y": 17,
      "z": 0,
      "name": "Plant_Crop_Mushroom_Block_Blue"
    },
    {
      "x": -1,
      "y": 18,
      "z": 0,
      "name": "Plant_Crop_Mushroom_Block_Blue"
    },
    {
      "x": -1,
      "y": 19,
      "z": 0,
      "name": "Plant_Crop_Mushroom_Block_Blue"
    },
    {
      "x": -1,
      "y": 20,
      "z": 0,
      "name": "Plant_Crop_Mushroom_Block_Blue"
    },
    {
      "x": -1,
      "y": 21,
      "z": 0,
      "name": "Plant_Crop_Mushroom_Block_Blue"
    },
    {
      "x": -1,
      "y": 22,
      "z": 0,
      "name": "Plant_Crop_Mushroom_Block_Blue"
    },
    {
      "x": -1,
      "y": 2,
      "z": 1,
      "name": "Plant_Crop_Mushroom_Block_Blue_Trunk"
    },
    {
      "x": -1,
      "y": 3,
      "z": 1,
      "name": "Plant_Crop_Mushroom_Block_Blue_Trunk"
    },
    {
      "x": -1,
      "y": 4,
      "z": 1,
      "name": "Plant_Crop_Mushroom_Block_Blue_Trunk"
    },
    {
      "x": -1,
      "y": 5,
      "z": 1,
      "name": "Plant_Crop_Mushroom_Block_Blue_Trunk"
    },
    {
      "x": -1,
      "y": 6,
      "z": 1,
      "name": "Plant_Crop_Mushroom_Block_Blue_Trunk"
    },
    {
      "x": -1,
      "y": 7,
      "z": 1,
      "name": "Plant_Crop_Mushroom_Block_Blue_Trunk"
    },
    {
      "x": -1,
      "y": 8,
      "z": 1,
      "name": "Plant_Crop_Mushroom_Block_Blue_Trunk"
    },
    {
      "x": -1,
      "y": 9,
      "z": 1,
      "name": "Plant_Crop_Mushroom_Block_Blue_Trunk"
    },
    {
      "x": -1,
      "y": 10,
      "z": 1,
      "name": "Plant_Crop_Mushroom_Block_Blue_Trunk"
    },
    {
      "x": -1,
      "y": 11,
      "z": 1,
      "name": "Plant_Crop_Mushroom_Block_Blue_Trunk"
    },
    {
      "x": -1,
      "y": 12,
      "z": 1,
      "name": "Plant_Crop_Mushroom_Block_Blue_Trunk"
    },
    {
      "x": -1,
      "y": 13,
      "z": 1,
      "name": "Plant_Crop_Mushroom_Block_Blue_Trunk"
    },
    {
      "x": -1,
      "y": 14,
      "z": 1,
      "name": "Plant_Crop_Mushroom_Block_Blue_Trunk"
    },
    {
      "x": -1,
      "y": 15,
      "z": 1,
      "name": "Plant_Crop_Mushroom_Block_Blue_Trunk"
    },
    {
      "x": -1,
      "y": 16,
      "z": 1,
      "name": "Plant_Crop_Mushroom_Block_Blue_Trunk"
    },
    {
      "x": -1,
      "y": 17,
      "z": 1,
      "name": "Plant_Crop_Mushroom_Block_Blue"
    },
    {
      "x": -1,
      "y": 18,
      "z": 1,
      "name": "Plant_Crop_Mushroom_Block_Blue"
    },
    {
      "x": -1,
      "y": 19,
      "z": 1,
      "name": "Plant_Crop_Mushroom_Block_Blue"
    },
    {
      "x": -1,
      "y": 20,
      "z": 1,
      "name": "Plant_Crop_Mushroom_Block_Blue"
    },
    {
      "x": -1,
      "y": 21,
      "z": 1,
      "name": "Plant_Crop_Mushroom_Block_Blue"
    },
    {
      "x": -1,
      "y": 22,
      "z": 1,
      "name": "Plant_Crop_Mushroom_Block_Blue"
    },
    {
      "x": -1,
      "y": 23,
      "z": 1,
      "name": "Plant_Crop_Mushroom_Glowing_Blue"
    },
    {
      "x": -1,
      "y": 2,
      "z": 2,
      "name": "Plant_Crop_Mushroom_Block_Blue_Trunk"
    },
    {
      "x": -1,
      "y": 3,
      "z": 2,
      "name": "Plant_Crop_Mushroom_Block_Blue_Trunk"
    },
    {
      "x": -1,
      "y": 4,
      "z": 2,
      "name": "Plant_Crop_Mushroom_Block_Blue_Trunk"
    },
    {
      "x": -1,
      "y": 5,
      "z": 2,
      "name": "Plant_Crop_Mushroom_Block_Blue_Trunk"
    },
    {
      "x": -1,
      "y": 6,
      "z": 2,
      "name": "Plant_Crop_Mushroom_Block_Blue_Trunk"
    },
    {
      "x": -1,
      "y": 7,
      "z": 2,
      "name": "Plant_Crop_Mushroom_Block_Blue_Trunk"
    },
    {
      "x": -1,
      "y": 8,
      "z": 2,
      "name": "Plant_Crop_Mushroom_Block_Blue_Trunk"
    },
    {
      "x": -1,
      "y": 9,
      "z": 2,
      "name": "Plant_Crop_Mushroom_Block_Blue_Trunk"
    },
    {
      "x": -1,
      "y": 10,
      "z": 2,
      "name": "Plant_Crop_Mushroom_Block_Blue_Trunk"
    },
    {
      "x": -1,
      "y": 11,
      "z": 2,
      "name": "Plant_Crop_Mushroom_Block_Blue_Trunk"
    },
    {
      "x": -1,
      "y": 12,
      "z": 2,
      "name": "Plant_Crop_Mushroom_Glowing_Blue"
    },
    {
      "x": -1,
      "y": 15,
      "z": 2,
      "name": "Plant_Crop_Mushroom_Block_Blue_Mycelium"
    },
    {
      "x": -1,
      "y": 16,
      "z": 2,
      "name": "Plant_Crop_Mushroom_Block_Blue_Trunk"
    },
    {
      "x": -1,
      "y": 17,
      "z": 2,
      "name": "Plant_Crop_Mushroom_Block_Blue"
    },
    {
      "x": -1,
      "y": 18,
      "z": 2,
      "name": "Plant_Crop_Mushroom_Block_Blue"
    },
    {
      "x": -1,
      "y": 19,
      "z": 2,
      "name": "Plant_Crop_Mushroom_Block_Blue"
    },
    {
      "x": -1,
      "y": 20,
      "z": 2,
      "name": "Plant_Crop_Mushroom_Block_Blue"
    },
    {
      "x": -1,
      "y": 21,
      "z": 2,
      "name": "Plant_Crop_Mushroom_Block_Blue"
    },
    {
      "x": -1,
      "y": 22,
      "z": 2,
      "name": "Plant_Crop_Mushroom_Block_Blue"
    },
    {
      "x": -1,
      "y": 1,
      "z": 3,
      "name": "Plant_Crop_Mushroom_Block_Blue_Trunk"
    },
    {
      "x": -1,
      "y": 2,
      "z": 3,
      "name": "Plant_Crop_Mushroom_Block_Blue_Trunk"
    },
    {
      "x": -1,
      "y": 3,
      "z": 3,
      "name": "Plant_Crop_Mushroom_Block_Blue_Trunk"
    },
    {
      "x": -1,
      "y": 4,
      "z": 3,
      "name": "Plant_Crop_Mushroom_Block_Blue_Trunk"
    },
    {
      "x": -1,
      "y": 5,
      "z": 3,
      "name": "Plant_Crop_Mushroom_Block_Blue_Trunk"
    },
    {
      "x": -1,
      "y": 6,
      "z": 3,
      "name": "Plant_Crop_Mushroom_Block_Blue_Trunk"
    },
    {
      "x": -1,
      "y": 7,
      "z": 3,
      "name": "Plant_Crop_Mushroom_Block_Blue_Trunk"
    },
    {
      "x": -1,
      "y": 8,
      "z": 3,
      "name": "Plant_Crop_Mushroom_Glowing_Blue"
    },
    {
      "x": -1,
      "y": 16,
      "z": 3,
      "name": "Plant_Crop_Mushroom_Block_Blue_Mycelium"
    },
    {
      "x": -1,
      "y": 17,
      "z": 3,
      "name": "Plant_Crop_Mushroom_Block_Blue_Trunk"
    },
    {
      "x": -1,
      "y": 18,
      "z": 3,
      "name": "Plant_Crop_Mushroom_Block_Blue"
    },
    {
      "x": -1,
      "y": 19,
      "z": 3,
      "name": "Plant_Crop_Mushroom_Block_Blue"
    },
    {
      "x": -1,
      "y": 20,
      "z": 3,
      "name": "Plant_Crop_Mushroom_Block_Blue"
    },
    {
      "x": -1,
      "y": 21,
      "z": 3,
      "name": "Plant_Crop_Mushroom_Block_Blue"
    },
    {
      "x": -1,
      "y": 22,
      "z": 3,
      "name": "Plant_Crop_Mushroom_Block_Blue"
    },
    {
      "x": -1,
      "y": 2,
      "z": 4,
      "name": "Plant_Crop_Mushroom_Block_Blue_Trunk"
    },
    {
      "x": -1,
      "y": 3,
      "z": 4,
      "name": "Plant_Crop_Mushroom_Block_Blue_Trunk"
    },
    {
      "x": -1,
      "y": 4,
      "z": 4,
      "name": "Plant_Crop_Mushroom_Block_Blue_Trunk"
    },
    {
      "x": -1,
      "y": 5,
      "z": 4,
      "name": "Plant_Crop_Mushroom_Block_Blue_Trunk"
    },
    {
      "x": -1,
      "y": 17,
      "z": 4,
      "name": "Plant_Crop_Mushroom_Block_Blue_Mycelium"
    },
    {
      "x": -1,
      "y": 18,
      "z": 4,
      "name": "Plant_Crop_Mushroom_Block_Blue"
    },
    {
      "x": -1,
      "y": 19,
      "z": 4,
      "name": "Plant_Crop_Mushroom_Block_Blue"
    },
    {
      "x": -1,
      "y": 20,
      "z": 4,
      "name": "Plant_Crop_Mushroom_Block_Blue"
    },
    {
      "x": -1,
      "y": 21,
      "z": 4,
      "name": "Plant_Crop_Mushroom_Block_Blue"
    },
    {
      "x": -1,
      "y": 0,
      "z": 5,
      "name": "Plant_Crop_Mushroom_Block_Blue_Trunk"
    },
    {
      "x": -1,
      "y": 1,
      "z": 5,
      "name": "Plant_Crop_Mushroom_Block_Blue_Trunk"
    },
    {
      "x": -1,
      "y": 2,
      "z": 5,
      "name": "Plant_Crop_Mushroom_Block_Blue_Trunk"
    },
    {
      "x": -1,
      "y": 3,
      "z": 5,
      "name": "Plant_Crop_Mushroom_Block_Blue_Trunk"
    },
    {
      "x": -1,
      "y": 17,
      "z": 5,
      "name": "Plant_Crop_Mushroom_Block_Blue_Mycelium"
    },
    {
      "x": -1,
      "y": 18,
      "z": 5,
      "name": "Plant_Crop_Mushroom_Block_Blue"
    },
    {
      "x": -1,
      "y": 19,
      "z": 5,
      "name": "Plant_Crop_Mushroom_Block_Blue"
    },
    {
      "x": -1,
      "y": 20,
      "z": 5,
      "name": "Plant_Crop_Mushroom_Block_Blue"
    },
    {
      "x": -1,
      "y": 21,
      "z": 5,
      "name": "Plant_Crop_Mushroom_Glowing_Blue"
    },
    {
      "x": -1,
      "y": 17,
      "z": 6,
      "name": "Plant_Crop_Mushroom_Block_Blue_Mycelium"
    },
    {
      "x": -1,
      "y": 18,
      "z": 6,
      "name": "Plant_Crop_Mushroom_Block_Blue"
    },
    {
      "x": -1,
      "y": 19,
      "z": 6,
      "name": "Plant_Crop_Mushroom_Block_Blue"
    },
    {
      "x": -1,
      "y": 20,
      "z": 6,
      "name": "Plant_Crop_Mushroom_Block_Blue"
    },
    {
      "x": -1,
      "y": 14,
      "z": 7,
      "name": "Plant_Crop_Mushroom_Block_Blue"
    },
    {
      "x": -1,
      "y": 15,
      "z": 7,
      "name": "Plant_Crop_Mushroom_Block_Blue"
    },
    {
      "x": -1,
      "y": 16,
      "z": 7,
      "name": "Plant_Crop_Mushroom_Block_Blue"
    },
    {
      "x": -1,
      "y": 17,
      "z": 7,
      "name": "Plant_Crop_Mushroom_Block_Blue"
    },
    {
      "x": -1,
      "y": 18,
      "z": 7,
      "name": "Plant_Crop_Mushroom_Block_Blue"
    },
    {
      "x": -1,
      "y": 19,
      "z": 7,
      "name": "Plant_Crop_Mushroom_Block_Blue"
    },
    {
      "x": -1,
      "y": 16,
      "z": 8,
      "name": "Plant_Crop_Mushroom_Block_Blue"
    },
    {
      "x": -1,
      "y": 17,
      "z": 8,
      "name": "Plant_Crop_Mushroom_Block_Blue"
    },
    {
      "x": -1,
      "y": 18,
      "z": 8,
      "name": "Plant_Crop_Mushroom_Glowing_Blue"
    },
    {
      "x": 0,
      "y": 16,
      "z": -8,
      "name": "Plant_Crop_Mushroom_Block_Blue"
    },
    {
      "x": 0,
      "y": 17,
      "z": -8,
      "name": "Plant_Crop_Mushroom_Block_Blue"
    },
    {
      "x": 0,
      "y": 18,
      "z": -8,
      "name": "Plant_Crop_Mushroom_Block_Blue"
    },
    {
      "x": 0,
      "y": 16,
      "z": -7,
      "name": "Plant_Crop_Mushroom_Block_Blue"
    },
    {
      "x": 0,
      "y": 17,
      "z": -7,
      "name": "Plant_Crop_Mushroom_Block_Blue"
    },
    {
      "x": 0,
      "y": 18,
      "z": -7,
      "name": "Plant_Crop_Mushroom_Block_Blue"
    },
    {
      "x": 0,
      "y": 19,
      "z": -7,
      "name": "Plant_Crop_Mushroom_Block_Blue"
    },
    {
      "x": 0,
      "y": 20,
      "z": -7,
      "name": "Plant_Crop_Mushroom_Glowing_Blue"
    },
    {
      "x": 0,
      "y": 17,
      "z": -6,
      "name": "Plant_Crop_Mushroom_Block_Blue_Mycelium"
    },
    {
      "x": 0,
      "y": 18,
      "z": -6,
      "name": "Plant_Crop_Mushroom_Block_Blue"
    },
    {
      "x": 0,
      "y": 19,
      "z": -6,
      "name": "Plant_Crop_Mushroom_Block_Blue"
    },
    {
      "x": 0,
      "y": 20,
      "z": -6,
      "name": "Plant_Crop_Mushroom_Block_Blue"
    },
    {
      "x": 0,
      "y": 21,
      "z": -6,
      "name": "Plant_Crop_Mushroom_Glowing_Blue"
    },
    {
      "x": 0,
      "y": 1,
      "z": -5,
      "name": "Plant_Crop_Mushroom_Block_Blue_Trunk"
    },
    {
      "x": 0,
      "y": 2,
      "z": -5,
      "name": "Plant_Crop_Mushroom_Block_Blue_Trunk"
    },
    {
      "x": 0,
      "y": 3,
      "z": -5,
      "name": "Plant_Crop_Mushroom_Block_Blue_Trunk"
    },
    {
      "x": 0,
      "y": 17,
      "z": -5,
      "name": "Plant_Crop_Mushroom_Block_Blue_Mycelium"
    },
    {
      "x": 0,
      "y": 18,
      "z": -5,
      "name": "Plant_Crop_Mushroom_Block_Blue"
    },
    {
      "x": 0,
      "y": 19,
      "z": -5,
      "name": "Plant_Crop_Mushroom_Block_Blue"
    },
    {
      "x": 0,
      "y": 20,
      "z": -5,
      "name": "Plant_Crop_Mushroom_Block_Blue"
    },
    {
      "x": 0,
      "y": 21,
      "z": -5,
      "name": "Plant_Crop_Mushroom_Block_Blue"
    },
    {
      "x": 0,
      "y": 2,
      "z": -4,
      "name": "Plant_Crop_Mushroom_Block_Blue_Trunk"
    },
    {
      "x": 0,
      "y": 3,
      "z": -4,
      "name": "Plant_Crop_Mushroom_Block_Blue_Trunk"
    },
    {
      "x": 0,
      "y": 4,
      "z": -4,
      "name": "Plant_Crop_Mushroom_Block_Blue_Trunk"
    },
    {
      "x": 0,
      "y": 5,
      "z": -4,
      "name": "Plant_Crop_Mushroom_Block_Blue_Trunk"
    },
    {
      "x": 0,
      "y": 17,
      "z": -4,
      "name": "Plant_Crop_Mushroom_Block_Blue_Mycelium"
    },
    {
      "x": 0,
      "y": 18,
      "z": -4,
      "name": "Plant_Crop_Mushroom_Block_Blue"
    },
    {
      "x": 0,
      "y": 19,
      "z": -4,
      "name": "Plant_Crop_Mushroom_Block_Blue"
    },
    {
      "x": 0,
      "y": 20,
      "z": -4,
      "name": "Plant_Crop_Mushroom_Block_Blue"
    },
    {
      "x": 0,
      "y": 21,
      "z": -4,
      "name": "Plant_Crop_Mushroom_Block_Blue"
    },
    {
      "x": 0,
      "y": 22,
      "z": -4,
      "name": "Plant_Crop_Mushroom_Glowing_Blue"
    },
    {
      "x": 0,
      "y": 0,
      "z": -3,
      "name": "Plant_Crop_Mushroom_Block_Blue_Trunk"
    },
    {
      "x": 0,
      "y": 1,
      "z": -3,
      "name": "Plant_Crop_Mushroom_Block_Blue_Trunk"
    },
    {
      "x": 0,
      "y": 2,
      "z": -3,
      "name": "Plant_Crop_Mushroom_Block_Blue_Trunk"
    },
    {
      "x": 0,
      "y": 3,
      "z": -3,
      "name": "Plant_Crop_Mushroom_Block_Blue_Trunk"
    },
    {
      "x": 0,
      "y": 4,
      "z": -3,
      "name": "Plant_Crop_Mushroom_Block_Blue_Trunk"
    },
    {
      "x": 0,
      "y": 5,
      "z": -3,
      "name": "Plant_Crop_Mushroom_Block_Blue_Trunk"
    },
    {
      "x": 0,
      "y": 6,
      "z": -3,
      "name": "Plant_Crop_Mushroom_Block_Blue_Trunk"
    },
    {
      "x": 0,
      "y": 7,
      "z": -3,
      "name": "Plant_Crop_Mushroom_Block_Blue_Trunk"
    },
    {
      "x": 0,
      "y": 16,
      "z": -3,
      "name": "Plant_Crop_Mushroom_Block_Blue_Mycelium"
    },
    {
      "x": 0,
      "y": 17,
      "z": -3,
      "name": "Plant_Crop_Mushroom_Block_Blue_Trunk"
    },
    {
      "x": 0,
      "y": 18,
      "z": -3,
      "name": "Plant_Crop_Mushroom_Block_Blue"
    },
    {
      "x": 0,
      "y": 19,
      "z": -3,
      "name": "Plant_Crop_Mushroom_Block_Blue"
    },
    {
      "x": 0,
      "y": 20,
      "z": -3,
      "name": "Plant_Crop_Mushroom_Block_Blue"
    },
    {
      "x": 0,
      "y": 21,
      "z": -3,
      "name": "Plant_Crop_Mushroom_Block_Blue"
    },
    {
      "x": 0,
      "y": 22,
      "z": -3,
      "name": "Plant_Crop_Mushroom_Block_Blue"
    },
    {
      "x": 0,
      "y": 1,
      "z": -2,
      "name": "Plant_Crop_Mushroom_Block_Blue_Trunk"
    },
    {
      "x": 0,
      "y": 2,
      "z": -2,
      "name": "Plant_Crop_Mushroom_Block_Blue_Trunk"
    },
    {
      "x": 0,
      "y": 3,
      "z": -2,
      "name": "Plant_Crop_Mushroom_Block_Blue_Trunk"
    },
    {
      "x": 0,
      "y": 4,
      "z": -2,
      "name": "Plant_Crop_Mushroom_Block_Blue_Trunk"
    },
    {
      "x": 0,
      "y": 5,
      "z": -2,
      "name": "Plant_Crop_Mushroom_Block_Blue_Trunk"
    },
    {
      "x": 0,
      "y": 6,
      "z": -2,
      "name": "Plant_Crop_Mushroom_Block_Blue_Trunk"
    },
    {
      "x": 0,
      "y": 7,
      "z": -2,
      "name": "Plant_Crop_Mushroom_Block_Blue_Trunk"
    },
    {
      "x": 0,
      "y": 8,
      "z": -2,
      "name": "Plant_Crop_Mushroom_Block_Blue_Trunk"
    },
    {
      "x": 0,
      "y": 9,
      "z": -2,
      "name": "Plant_Crop_Mushroom_Block_Blue_Trunk"
    },
    {
      "x": 0,
      "y": 10,
      "z": -2,
      "name": "Plant_Crop_Mushroom_Block_Blue_Trunk"
    },
    {
      "x": 0,
      "y": 11,
      "z": -2,
      "name": "Plant_Crop_Mushroom_Glowing_Blue"
    },
    {
      "x": 0,
      "y": 15,
      "z": -2,
      "name": "Plant_Crop_Mushroom_Block_Blue_Mycelium"
    },
    {
      "x": 0,
      "y": 16,
      "z": -2,
      "name": "Plant_Crop_Mushroom_Block_Blue_Trunk"
    },
    {
      "x": 0,
      "y": 17,
      "z": -2,
      "name": "Plant_Crop_Mushroom_Block_Blue"
    },
    {
      "x": 0,
      "y": 18,
      "z": -2,
      "name": "Plant_Crop_Mushroom_Block_Blue"
    },
    {
      "x": 0,
      "y": 19,
      "z": -2,
      "name": "Plant_Crop_Mushroom_Block_Blue"
    },
    {
      "x": 0,
      "y": 20,
      "z": -2,
      "name": "Plant_Crop_Mushroom_Block_Blue"
    },
    {
      "x": 0,
      "y": 21,
      "z": -2,
      "name": "Plant_Crop_Mushroom_Block_Blue"
    },
    {
      "x": 0,
      "y": 22,
      "z": -2,
      "name": "Plant_Crop_Mushroom_Block_Blue"
    },
    {
      "x": 0,
      "y": 2,
      "z": -1,
      "name": "Plant_Crop_Mushroom_Block_Blue_Trunk"
    },
    {
      "x": 0,
      "y": 3,
      "z": -1,
      "name": "Plant_Crop_Mushroom_Block_Blue_Trunk"
    },
    {
      "x": 0,
      "y": 4,
      "z": -1,
      "name": "Plant_Crop_Mushroom_Block_Blue_Trunk"
    },
    {
      "x": 0,
      "y": 5,
      "z": -1,
      "name": "Plant_Crop_Mushroom_Block_Blue_Trunk"
    },
    {
      "x": 0,
      "y": 6,
      "z": -1,
      "name": "Plant_Crop_Mushroom_Block_Blue_Trunk"
    },
    {
      "x": 0,
      "y": 7,
      "z": -1,
      "name": "Plant_Crop_Mushroom_Block_Blue_Trunk"
    },
    {
      "x": 0,
      "y": 8,
      "z": -1,
      "name": "Plant_Crop_Mushroom_Block_Blue_Trunk"
    },
    {
      "x": 0,
      "y": 9,
      "z": -1,
      "name": "Plant_Crop_Mushroom_Block_Blue_Trunk"
    },
    {
      "x": 0,
      "y": 10,
      "z": -1,
      "name": "Plant_Crop_Mushroom_Block_Blue_Trunk"
    },
    {
      "x": 0,
      "y": 11,
      "z": -1,
      "name": "Plant_Crop_Mushroom_Block_Blue_Trunk"
    },
    {
      "x": 0,
      "y": 12,
      "z": -1,
      "name": "Plant_Crop_Mushroom_Block_Blue_Trunk"
    },
    {
      "x": 0,
      "y": 13,
      "z": -1,
      "name": "Plant_Crop_Mushroom_Block_Blue_Trunk"
    },
    {
      "x": 0,
      "y": 14,
      "z": -1,
      "name": "Plant_Crop_Mushroom_Block_Blue_Trunk"
    },
    {
      "x": 0,
      "y": 15,
      "z": -1,
      "name": "Plant_Crop_Mushroom_Block_Blue_Trunk"
    },
    {
      "x": 0,
      "y": 16,
      "z": -1,
      "name": "Plant_Crop_Mushroom_Block_Blue_Trunk"
    },
    {
      "x": 0,
      "y": 17,
      "z": -1,
      "name": "Plant_Crop_Mushroom_Block_Blue"
    },
    {
      "x": 0,
      "y": 18,
      "z": -1,
      "name": "Plant_Crop_Mushroom_Block_Blue"
    },
    {
      "x": 0,
      "y": 19,
      "z": -1,
      "name": "Plant_Crop_Mushroom_Block_Blue"
    },
    {
      "x": 0,
      "y": 20,
      "z": -1,
      "name": "Plant_Crop_Mushroom_Block_Blue"
    },
    {
      "x": 0,
      "y": 21,
      "z": -1,
      "name": "Plant_Crop_Mushroom_Block_Blue"
    },
    {
      "x": 0,
      "y": 22,
      "z": -1,
      "name": "Plant_Crop_Mushroom_Block_Blue"
    },
    {
      "x": 0,
      "y": 23,
      "z": -1,
      "name": "Plant_Crop_Mushroom_Glowing_Blue"
    },
    {
      "x": 0,
      "y": 2,
      "z": 0,
      "name": "Plant_Crop_Mushroom_Block_Blue_Trunk"
    },
    {
      "x": 0,
      "y": 3,
      "z": 0,
      "name": "Plant_Crop_Mushroom_Block_Blue_Trunk"
    },
    {
      "x": 0,
      "y": 4,
      "z": 0,
      "name": "Plant_Crop_Mushroom_Block_Blue_Trunk"
    },
    {
      "x": 0,
      "y": 5,
      "z": 0,
      "name": "Plant_Crop_Mushroom_Block_Blue_Trunk"
    },
    {
      "x": 0,
      "y": 6,
      "z": 0,
      "name": "Plant_Crop_Mushroom_Block_Blue_Trunk"
    },
    {
      "x": 0,
      "y": 7,
      "z": 0,
      "name": "Plant_Crop_Mushroom_Block_Blue_Trunk"
    },
    {
      "x": 0,
      "y": 8,
      "z": 0,
      "name": "Plant_Crop_Mushroom_Block_Blue_Trunk"
    },
    {
      "x": 0,
      "y": 9,
      "z": 0,
      "name": "Plant_Crop_Mushroom_Block_Blue_Trunk"
    },
    {
      "x": 0,
      "y": 10,
      "z": 0,
      "name": "Plant_Crop_Mushroom_Block_Blue_Trunk"
    },
    {
      "x": 0,
      "y": 11,
      "z": 0,
      "name": "Plant_Crop_Mushroom_Block_Blue_Trunk"
    },
    {
      "x": 0,
      "y": 12,
      "z": 0,
      "name": "Plant_Crop_Mushroom_Block_Blue_Trunk"
    },
    {
      "x": 0,
      "y": 13,
      "z": 0,
      "name": "Plant_Crop_Mushroom_Block_Blue_Trunk"
    },
    {
      "x": 0,
      "y": 14,
      "z": 0,
      "name": "Plant_Crop_Mushroom_Block_Blue_Trunk"
    },
    {
      "x": 0,
      "y": 15,
      "z": 0,
      "name": "Plant_Crop_Mushroom_Block_Blue_Trunk"
    },
    {
      "x": 0,
      "y": 16,
      "z": 0,
      "name": "Plant_Crop_Mushroom_Block_Blue_Trunk"
    },
    {
      "x": 0,
      "y": 17,
      "z": 0,
      "name": "Plant_Crop_Mushroom_Block_Blue"
    },
    {
      "x": 0,
      "y": 18,
      "z": 0,
      "name": "Plant_Crop_Mushroom_Block_Blue"
    },
    {
      "x": 0,
      "y": 19,
      "z": 0,
      "name": "Plant_Crop_Mushroom_Block_Blue"
    },
    {
      "x": 0,
      "y": 20,
      "z": 0,
      "name": "Plant_Crop_Mushroom_Block_Blue"
    },
    {
      "x": 0,
      "y": 21,
      "z": 0,
      "name": "Plant_Crop_Mushroom_Block_Blue"
    },
    {
      "x": 0,
      "y": 22,
      "z": 0,
      "name": "Plant_Crop_Mushroom_Block_Blue"
    },
    {
      "x": 0,
      "y": 23,
      "z": 0,
      "name": "Plant_Crop_Mushroom_Glowing_Blue"
    },
    {
      "x": 0,
      "y": 1,
      "z": 1,
      "name": "Plant_Crop_Mushroom_Block_Blue_Trunk"
    },
    {
      "x": 0,
      "y": 2,
      "z": 1,
      "name": "Plant_Crop_Mushroom_Block_Blue_Trunk"
    },
    {
      "x": 0,
      "y": 3,
      "z": 1,
      "name": "Plant_Crop_Mushroom_Block_Blue_Trunk"
    },
    {
      "x": 0,
      "y": 4,
      "z": 1,
      "name": "Plant_Crop_Mushroom_Block_Blue_Trunk"
    },
    {
      "x": 0,
      "y": 5,
      "z": 1,
      "name": "Plant_Crop_Mushroom_Block_Blue_Trunk"
    },
    {
      "x": 0,
      "y": 6,
      "z": 1,
      "name": "Plant_Crop_Mushroom_Block_Blue_Trunk"
    },
    {
      "x": 0,
      "y": 7,
      "z": 1,
      "name": "Plant_Crop_Mushroom_Block_Blue_Trunk"
    },
    {
      "x": 0,
      "y": 8,
      "z": 1,
      "name": "Plant_Crop_Mushroom_Block_Blue_Trunk"
    },
    {
      "x": 0,
      "y": 9,
      "z": 1,
      "name": "Plant_Crop_Mushroom_Block_Blue_Trunk"
    },
    {
      "x": 0,
      "y": 10,
      "z": 1,
      "name": "Plant_Crop_Mushroom_Block_Blue_Trunk"
    },
    {
      "x": 0,
      "y": 11,
      "z": 1,
      "name": "Plant_Crop_Mushroom_Block_Blue_Trunk"
    },
    {
      "x": 0,
      "y": 12,
      "z": 1,
      "name": "Plant_Crop_Mushroom_Block_Blue_Trunk"
    },
    {
      "x": 0,
      "y": 13,
      "z": 1,
      "name": "Plant_Crop_Mushroom_Block_Blue_Trunk"
    },
    {
      "x": 0,
      "y": 14,
      "z": 1,
      "name": "Plant_Crop_Mushroom_Block_Blue_Trunk"
    },
    {
      "x": 0,
      "y": 15,
      "z": 1,
      "name": "Plant_Crop_Mushroom_Block_Blue_Trunk"
    },
    {
      "x": 0,
      "y": 16,
      "z": 1,
      "name": "Plant_Crop_Mushroom_Block_Blue_Trunk"
    },
    {
      "x": 0,
      "y": 17,
      "z": 1,
      "name": "Plant_Crop_Mushroom_Block_Blue"
    },
    {
      "x": 0,
      "y": 18,
      "z": 1,
      "name": "Plant_Crop_Mushroom_Block_Blue"
    },
    {
      "x": 0,
      "y": 19,
      "z": 1,
      "name": "Plant_Crop_Mushroom_Block_Blue"
    },
    {
      "x": 0,
      "y": 20,
      "z": 1,
      "name": "Plant_Crop_Mushroom_Block_Blue"
    },
    {
      "x": 0,
      "y": 21,
      "z": 1,
      "name": "Plant_Crop_Mushroom_Block_Blue"
    },
    {
      "x": 0,
      "y": 22,
      "z": 1,
      "name": "Plant_Crop_Mushroom_Block_Blue"
    },
    {
      "x": 0,
      "y": 0,
      "z": 2,
      "name": "Plant_Crop_Mushroom_Block_Blue_Trunk"
    },
    {
      "x": 0,
      "y": 1,
      "z": 2,
      "name": "Plant_Crop_Mushroom_Block_Blue_Trunk"
    },
    {
      "x": 0,
      "y": 2,
      "z": 2,
      "name": "Plant_Crop_Mushroom_Block_Blue_Trunk"
    },
    {
      "x": 0,
      "y": 3,
      "z": 2,
      "name": "Plant_Crop_Mushroom_Block_Blue_Trunk"
    },
    {
      "x": 0,
      "y": 4,
      "z": 2,
      "name": "Plant_Crop_Mushroom_Block_Blue_Trunk"
    },
    {
      "x": 0,
      "y": 5,
      "z": 2,
      "name": "Plant_Crop_Mushroom_Block_Blue_Trunk"
    },
    {
      "x": 0,
      "y": 6,
      "z": 2,
      "name": "Plant_Crop_Mushroom_Block_Blue_Trunk"
    },
    {
      "x": 0,
      "y": 7,
      "z": 2,
      "name": "Plant_Crop_Mushroom_Block_Blue_Trunk"
    },
    {
      "x": 0,
      "y": 8,
      "z": 2,
      "name": "Plant_Crop_Mushroom_Block_Blue_Trunk"
    },
    {
      "x": 0,
      "y": 9,
      "z": 2,
      "name": "Plant_Crop_Mushroom_Block_Blue_Trunk"
    },
    {
      "x": 0,
      "y": 10,
      "z": 2,
      "name": "Plant_Crop_Mushroom_Block_Blue_Trunk"
    },
    {
      "x": 0,
      "y": 14,
      "z": 2,
      "name": "Plant_Crop_Mushroom_Block_Blue_Mycelium"
    },
    {
      "x": 0,
      "y": 15,
      "z": 2,
      "name": "Plant_Crop_Mushroom_Block_Blue_Trunk"
    },
    {
      "x": 0,
      "y": 16,
      "z": 2,
      "name": "Plant_Crop_Mushroom_Block_Blue_Trunk"
    },
    {
      "x": 0,
      "y": 17,
      "z": 2,
      "name": "Plant_Crop_Mushroom_Block_Blue"
    },
    {
      "x": 0,
      "y": 18,
      "z": 2,
      "name": "Plant_Crop_Mushroom_Block_Blue"
    },
    {
      "x": 0,
      "y": 19,
      "z": 2,
      "name": "Plant_Crop_Mushroom_Block_Blue"
    },
    {
      "x": 0,
      "y": 20,
      "z": 2,
      "name": "Plant_Crop_Mushroom_Block_Blue"
    },
    {
      "x": 0,
      "y": 21,
      "z": 2,
      "name": "Plant_Crop_Mushroom_Block_Blue"
    },
    {
      "x": 0,
      "y": 22,
      "z": 2,
      "name": "Plant_Crop_Mushroom_Block_Blue"
    },
    {
      "x": 0,
      "y": 2,
      "z": 3,
      "name": "Plant_Crop_Mushroom_Block_Blue_Trunk"
    },
    {
      "x": 0,
      "y": 3,
      "z": 3,
      "name": "Plant_Crop_Mushroom_Block_Blue_Trunk"
    },
    {
      "x": 0,
      "y": 4,
      "z": 3,
      "name": "Plant_Crop_Mushroom_Block_Blue_Trunk"
    },
    {
      "x": 0,
      "y": 5,
      "z": 3,
      "name": "Plant_Crop_Mushroom_Block_Blue_Trunk"
    },
    {
      "x": 0,
      "y": 6,
      "z": 3,
      "name": "Plant_Crop_Mushroom_Block_Blue_Trunk"
    },
    {
      "x": 0,
      "y": 7,
      "z": 3,
      "name": "Plant_Crop_Mushroom_Block_Blue_Trunk"
    },
    {
      "x": 0,
      "y": 16,
      "z": 3,
      "name": "Plant_Crop_Mushroom_Block_Blue_Mycelium"
    },
    {
      "x": 0,
      "y": 17,
      "z": 3,
      "name": "Plant_Crop_Mushroom_Block_Blue_Trunk"
    },
    {
      "x": 0,
      "y": 18,
      "z": 3,
      "name": "Plant_Crop_Mushroom_Block_Blue"
    },
    {
      "x": 0,
      "y": 19,
      "z": 3,
      "name": "Plant_Crop_Mushroom_Block_Blue"
    },
    {
      "x": 0,
      "y": 20,
      "z": 3,
      "name": "Plant_Crop_Mushroom_Block_Blue"
    },
    {
      "x": 0,
      "y": 21,
      "z": 3,
      "name": "Plant_Crop_Mushroom_Block_Blue"
    },
    {
      "x": 0,
      "y": 22,
      "z": 3,
      "name": "Plant_Crop_Mushroom_Block_Blue"
    },
    {
      "x": 0,
      "y": 1,
      "z": 4,
      "name": "Plant_Crop_Mushroom_Block_Blue_Trunk"
    },
    {
      "x": 0,
      "y": 2,
      "z": 4,
      "name": "Plant_Crop_Mushroom_Block_Blue_Trunk"
    },
    {
      "x": 0,
      "y": 3,
      "z": 4,
      "name": "Plant_Crop_Mushroom_Block_Blue_Trunk"
    },
    {
      "x": 0,
      "y": 4,
      "z": 4,
      "name": "Plant_Crop_Mushroom_Block_Blue_Trunk"
    },
    {
      "x": 0,
      "y": 5,
      "z": 4,
      "name": "Plant_Crop_Mushroom_Block_Blue_Trunk"
    },
    {
      "x": 0,
      "y": 17,
      "z": 4,
      "name": "Plant_Crop_Mushroom_Block_Blue_Mycelium"
    },
    {
      "x": 0,
      "y": 18,
      "z": 4,
      "name": "Plant_Crop_Mushroom_Block_Blue"
    },
    {
      "x": 0,
      "y": 19,
      "z": 4,
      "name": "Plant_Crop_Mushroom_Block_Blue"
    },
    {
      "x": 0,
      "y": 20,
      "z": 4,
      "name": "Plant_Crop_Mushroom_Block_Blue"
    },
    {
      "x": 0,
      "y": 21,
      "z": 4,
      "name": "Plant_Crop_Mushroom_Block_Blue"
    },
    {
      "x": 0,
      "y": 22,
      "z": 4,
      "name": "Plant_Crop_Mushroom_Glowing_Blue"
    },
    {
      "x": 0,
      "y": 2,
      "z": 5,
      "name": "Plant_Crop_Mushroom_Block_Blue_Trunk"
    },
    {
      "x": 0,
      "y": 3,
      "z": 5,
      "name": "Plant_Crop_Mushroom_Block_Blue_Trunk"
    },
    {
      "x": 0,
      "y": 17,
      "z": 5,
      "name": "Plant_Crop_Mushroom_Block_Blue_Mycelium"
    },
    {
      "x": 0,
      "y": 18,
      "z": 5,
      "name": "Plant_Crop_Mushroom_Block_Blue"
    },
    {
      "x": 0,
      "y": 19,
      "z": 5,
      "name": "Plant_Crop_Mushroom_Block_Blue"
    },
    {
      "x": 0,
      "y": 20,
      "z": 5,
      "name": "Plant_Crop_Mushroom_Block_Blue"
    },
    {
      "x": 0,
      "y": 21,
      "z": 5,
      "name": "Plant_Crop_Mushroom_Block_Blue"
    },
    {
      "x": 0,
      "y": 17,
      "z": 6,
      "name": "Plant_Crop_Mushroom_Block_Blue_Mycelium"
    },
    {
      "x": 0,
      "y": 18,
      "z": 6,
      "name": "Plant_Crop_Mushroom_Block_Blue"
    },
    {
      "x": 0,
      "y": 19,
      "z": 6,
      "name": "Plant_Crop_Mushroom_Block_Blue"
    },
    {
      "x": 0,
      "y": 20,
      "z": 6,
      "name": "Plant_Crop_Mushroom_Block_Blue"
    },
    {
      "x": 0,
      "y": 16,
      "z": 7,
      "name": "Plant_Crop_Mushroom_Block_Blue"
    },
    {
      "x": 0,
      "y": 17,
      "z": 7,
      "name": "Plant_Crop_Mushroom_Block_Blue"
    },
    {
      "x": 0,
      "y": 18,
      "z": 7,
      "name": "Plant_Crop_Mushroom_Block_Blue"
    },
    {
      "x": 0,
      "y": 19,
      "z": 7,
      "name": "Plant_Crop_Mushroom_Block_Blue"
    },
    {
      "x": 0,
      "y": 20,
      "z": 7,
      "name": "Plant_Crop_Mushroom_Glowing_Blue"
    },
    {
      "x": 0,
      "y": 16,
      "z": 8,
      "name": "Plant_Crop_Mushroom_Block_Blue"
    },
    {
      "x": 0,
      "y": 17,
      "z": 8,
      "name": "Plant_Crop_Mushroom_Block_Blue"
    },
    {
      "x": 0,
      "y": 18,
      "z": 8,
      "name": "Plant_Crop_Mushroom_Block_Blue"
    },
    {
      "x": 1,
      "y": 17,
      "z": -8,
      "name": "Plant_Crop_Mushroom_Block_Blue"
    },
    {
      "x": 1,
      "y": 16,
      "z": -7,
      "name": "Plant_Crop_Mushroom_Block_Blue"
    },
    {
      "x": 1,
      "y": 17,
      "z": -7,
      "name": "Plant_Crop_Mushroom_Block_Blue"
    },
    {
      "x": 1,
      "y": 18,
      "z": -7,
      "name": "Plant_Crop_Mushroom_Block_Blue"
    },
    {
      "x": 1,
      "y": 19,
      "z": -7,
      "name": "Plant_Crop_Mushroom_Block_Blue"
    },
    {
      "x": 1,
      "y": 17,
      "z": -6,
      "name": "Plant_Crop_Mushroom_Block_Blue_Mycelium"
    },
    {
      "x": 1,
      "y": 18,
      "z": -6,
      "name": "Plant_Crop_Mushroom_Block_Blue"
    },
    {
      "x": 1,
      "y": 19,
      "z": -6,
      "name": "Plant_Crop_Mushroom_Block_Blue"
    },
    {
      "x": 1,
      "y": 20,
      "z": -6,
      "name": "Plant_Crop_Mushroom_Block_Blue"
    },
    {
      "x": 1,
      "y": 2,
      "z": -5,
      "name": "Plant_Crop_Mushroom_Block_Blue_Trunk"
    },
    {
      "x": 1,
      "y": 3,
      "z": -5,
      "name": "Plant_Crop_Mushroom_Block_Blue_Trunk"
    },
    {
      "x": 1,
      "y": 17,
      "z": -5,
      "name": "Plant_Crop_Mushroom_Block_Blue_Mycelium"
    },
    {
      "x": 1,
      "y": 18,
      "z": -5,
      "name": "Plant_Crop_Mushroom_Block_Blue"
    },
    {
      "x": 1,
      "y": 19,
      "z": -5,
      "name": "Plant_Crop_Mushroom_Block_Blue"
    },
    {
      "x": 1,
      "y": 20,
      "z": -5,
      "name": "Plant_Crop_Mushroom_Block_Blue"
    },
    {
      "x": 1,
      "y": 21,
      "z": -5,
      "name": "Plant_Crop_Mushroom_Glowing_Blue"
    },
    {
      "x": 1,
      "y": 0,
      "z": -4,
      "name": "Plant_Crop_Mushroom_Block_Blue_Trunk"
    },
    {
      "x": 1,
      "y": 1,
      "z": -4,
      "name": "Plant_Crop_Mushroom_Block_Blue_Trunk"
    },
    {
      "x": 1,
      "y": 2,
      "z": -4,
      "name": "Plant_Crop_Mushroom_Block_Blue_Trunk"
    },
    {
      "x": 1,
      "y": 3,
      "z": -4,
      "name": "Plant_Crop_Mushroom_Block_Blue_Trunk"
    },
    {
      "x": 1,
      "y": 4,
      "z": -4,
      "name": "Plant_Crop_Mushroom_Block_Blue_Trunk"
    },
    {
      "x": 1,
      "y": 5,
      "z": -4,
      "name": "Plant_Crop_Mushroom_Block_Blue_Trunk"
    },
    {
      "x": 1,
      "y": 17,
      "z": -4,
      "name": "Plant_Crop_Mushroom_Block_Blue_Mycelium"
    },
    {
      "x": 1,
      "y": 18,
      "z": -4,
      "name": "Plant_Crop_Mushroom_Block_Blue"
    },
    {
      "x": 1,
      "y": 19,
      "z": -4,
      "name": "Plant_Crop_Mushroom_Block_Blue"
    },
    {
      "x": 1,
      "y": 20,
      "z": -4,
      "name": "Plant_Crop_Mushroom_Block_Blue"
    },
    {
      "x": 1,
      "y": 21,
      "z": -4,
      "name": "Plant_Crop_Mushroom_Block_Blue"
    },
    {
      "x": 1,
      "y": 2,
      "z": -3,
      "name": "Plant_Crop_Mushroom_Block_Blue_Trunk"
    },
    {
      "x": 1,
      "y": 3,
      "z": -3,
      "name": "Plant_Crop_Mushroom_Block_Blue_Trunk"
    },
    {
      "x": 1,
      "y": 4,
      "z": -3,
      "name": "Plant_Crop_Mushroom_Block_Blue_Trunk"
    },
    {
      "x": 1,
      "y": 5,
      "z": -3,
      "name": "Plant_Crop_Mushroom_Block_Blue_Trunk"
    },
    {
      "x": 1,
      "y": 6,
      "z": -3,
      "name": "Plant_Crop_Mushroom_Block_Blue_Trunk"
    },
    {
      "x": 1,
      "y": 7,
      "z": -3,
      "name": "Plant_Crop_Mushroom_Block_Blue_Trunk"
    },
    {
      "x": 1,
      "y": 16,
      "z": -3,
      "name": "Plant_Crop_Mushroom_Block_Blue_Mycelium"
    },
    {
      "x": 1,
      "y": 17,
      "z": -3,
      "name": "Plant_Crop_Mushroom_Block_Blue_Trunk"
    },
    {
      "x": 1,
      "y": 18,
      "z": -3,
      "name": "Plant_Crop_Mushroom_Block_Blue"
    },
    {
      "x": 1,
      "y": 19,
      "z": -3,
      "name": "Plant_Crop_Mushroom_Block_Blue"
    },
    {
      "x": 1,
      "y": 20,
      "z": -3,
      "name": "Plant_Crop_Mushroom_Block_Blue"
    },
    {
      "x": 1,
      "y": 21,
      "z": -3,
      "name": "Plant_Crop_Mushroom_Block_Blue"
    },
    {
      "x": 1,
      "y": 22,
      "z": -3,
      "name": "Plant_Crop_Mushroom_Block_Blue"
    },
    {
      "x": 1,
      "y": 2,
      "z": -2,
      "name": "Plant_Crop_Mushroom_Block_Blue_Trunk"
    },
    {
      "x": 1,
      "y": 3,
      "z": -2,
      "name": "Plant_Crop_Mushroom_Block_Blue_Trunk"
    },
    {
      "x": 1,
      "y": 4,
      "z": -2,
      "name": "Plant_Crop_Mushroom_Block_Blue_Trunk"
    },
    {
      "x": 1,
      "y": 5,
      "z": -2,
      "name": "Plant_Crop_Mushroom_Block_Blue_Trunk"
    },
    {
      "x": 1,
      "y": 6,
      "z": -2,
      "name": "Plant_Crop_Mushroom_Block_Blue_Trunk"
    },
    {
      "x": 1,
      "y": 7,
      "z": -2,
      "name": "Plant_Crop_Mushroom_Block_Blue_Trunk"
    },
    {
      "x": 1,
      "y": 8,
      "z": -2,
      "name": "Plant_Crop_Mushroom_Block_Blue_Trunk"
    },
    {
      "x": 1,
      "y": 9,
      "z": -2,
      "name": "Plant_Crop_Mushroom_Block_Blue_Trunk"
    },
    {
      "x": 1,
      "y": 15,
      "z": -2,
      "name": "Plant_Crop_Mushroom_Block_Blue_Mycelium"
    },
    {
      "x": 1,
      "y": 16,
      "z": -2,
      "name": "Plant_Crop_Mushroom_Block_Blue_Trunk"
    },
    {
      "x": 1,
      "y": 17,
      "z": -2,
      "name": "Plant_Crop_Mushroom_Block_Blue"
    },
    {
      "x": 1,
      "y": 18,
      "z": -2,
      "name": "Plant_Crop_Mushroom_Block_Blue"
    },
    {
      "x": 1,
      "y": 19,
      "z": -2,
      "name": "Plant_Crop_Mushroom_Block_Blue"
    },
    {
      "x": 1,
      "y": 20,
      "z": -2,
      "name": "Plant_Crop_Mushroom_Block_Blue"
    },
    {
      "x": 1,
      "y": 21,
      "z": -2,
      "name": "Plant_Crop_Mushroom_Block_Blue"
    },
    {
      "x": 1,
      "y": 22,
      "z": -2,
      "name": "Plant_Crop_Mushroom_Block_Blue"
    },
    {
      "x": 1,
      "y": 0,
      "z": -1,
      "name": "Plant_Crop_Mushroom_Block_Blue_Trunk"
    },
    {
      "x": 1,
      "y": 1,
      "z": -1,
      "name": "Plant_Crop_Mushroom_Block_Blue_Trunk"
    },
    {
      "x": 1,
      "y": 2,
      "z": -1,
      "name": "Plant_Crop_Mushroom_Block_Blue_Trunk"
    },
    {
      "x": 1,
      "y": 3,
      "z": -1,
      "name": "Plant_Crop_Mushroom_Block_Blue_Trunk"
    },
    {
      "x": 1,
      "y": 4,
      "z": -1,
      "name": "Plant_Crop_Mushroom_Block_Blue_Trunk"
    },
    {
      "x": 1,
      "y": 5,
      "z": -1,
      "name": "Plant_Crop_Mushroom_Block_Blue_Trunk"
    },
    {
      "x": 1,
      "y": 6,
      "z": -1,
      "name": "Plant_Crop_Mushroom_Block_Blue_Trunk"
    },
    {
      "x": 1,
      "y": 7,
      "z": -1,
      "name": "Plant_Crop_Mushroom_Block_Blue_Trunk"
    },
    {
      "x": 1,
      "y": 8,
      "z": -1,
      "name": "Plant_Crop_Mushroom_Block_Blue_Trunk"
    },
    {
      "x": 1,
      "y": 9,
      "z": -1,
      "name": "Plant_Crop_Mushroom_Block_Blue_Trunk"
    },
    {
      "x": 1,
      "y": 10,
      "z": -1,
      "name": "Plant_Crop_Mushroom_Block_Blue_Trunk"
    },
    {
      "x": 1,
      "y": 11,
      "z": -1,
      "name": "Plant_Crop_Mushroom_Block_Blue_Trunk"
    },
    {
      "x": 1,
      "y": 12,
      "z": -1,
      "name": "Plant_Crop_Mushroom_Block_Blue_Trunk"
    },
    {
      "x": 1,
      "y": 13,
      "z": -1,
      "name": "Plant_Crop_Mushroom_Block_Blue_Trunk"
    },
    {
      "x": 1,
      "y": 14,
      "z": -1,
      "name": "Plant_Crop_Mushroom_Block_Blue_Trunk"
    },
    {
      "x": 1,
      "y": 15,
      "z": -1,
      "name": "Plant_Crop_Mushroom_Block_Blue_Trunk"
    },
    {
      "x": 1,
      "y": 16,
      "z": -1,
      "name": "Plant_Crop_Mushroom_Block_Blue_Trunk"
    },
    {
      "x": 1,
      "y": 17,
      "z": -1,
      "name": "Plant_Crop_Mushroom_Block_Blue"
    },
    {
      "x": 1,
      "y": 18,
      "z": -1,
      "name": "Plant_Crop_Mushroom_Block_Blue"
    },
    {
      "x": 1,
      "y": 19,
      "z": -1,
      "name": "Plant_Crop_Mushroom_Block_Blue"
    },
    {
      "x": 1,
      "y": 20,
      "z": -1,
      "name": "Plant_Crop_Mushroom_Block_Blue"
    },
    {
      "x": 1,
      "y": 21,
      "z": -1,
      "name": "Plant_Crop_Mushroom_Block_Blue"
    },
    {
      "x": 1,
      "y": 22,
      "z": -1,
      "name": "Plant_Crop_Mushroom_Block_Blue"
    },
    {
      "x": 1,
      "y": 1,
      "z": 0,
      "name": "Plant_Crop_Mushroom_Block_Blue_Trunk"
    },
    {
      "x": 1,
      "y": 2,
      "z": 0,
      "name": "Plant_Crop_Mushroom_Block_Blue_Trunk"
    },
    {
      "x": 1,
      "y": 3,
      "z": 0,
      "name": "Plant_Crop_Mushroom_Block_Blue_Trunk"
    },
    {
      "x": 1,
      "y": 4,
      "z": 0,
      "name": "Plant_Crop_Mushroom_Block_Blue_Trunk"
    },
    {
      "x": 1,
      "y": 5,
      "z": 0,
      "name": "Plant_Crop_Mushroom_Block_Blue_Trunk"
    },
    {
      "x": 1,
      "y": 6,
      "z": 0,
      "name": "Plant_Crop_Mushroom_Block_Blue_Trunk"
    },
    {
      "x": 1,
      "y": 7,
      "z": 0,
      "name": "Plant_Crop_Mushroom_Block_Blue_Trunk"
