{
  "version": 8,
  "blockIdVersion": 11,
  "anchorX": 0,
  "anchorY": 0,
  "anchorZ": 0,
  "blocks": [
    {
      "x": -19,
      "y": 31,
      "z": -4,
      "name": "Plant_Crop_Mushroom_Block_Blue"
    },
    {
      "x": -19,
      "y": 32,
      "z": -4,
      "name": "Plant_Crop_Mushroom_Glowing_Blue"
    },
    {
      "x": -19,
      "y": 30,
      "z": -3,
      "name": "Plant_Crop_Mushroom_Block_Blue"
    },
    {
      "x": -19,
      "y": 31,
      "z": -3,
      "name": "Plant_Crop_Mushroom_Block_Blue"
    },
    {
      "x": -19,
      "y": 32,
      "z": -3,
      "name": "Plant_Crop_Mushroom_Block_Blue"
    },
    {
      "x": -19,
      "y": 33,
      "z": -3,
      "name": "Plant_Crop_Mushroom_Glowing_Blue"
    },
    {
      "x": -19,
      "y": 29,
      "z": -2,
      "name": "Plant_Crop_Mushroom_Block_Blue"
    },
    {
      "x": -19,
      "y": 30,
      "z": -2,
      "name": "Plant_Crop_Mushroom_Block_Blue"
    },
    {
      "x": -19,
      "y": 31,
      "z": -2,
      "name": "Plant_Crop_Mushroom_Block_Blue"
    },
    {
      "x": -19,
      "y": 32,
      "z": -2,
      "name": "Plant_Crop_Mushroom_Block_Blue"
    },
    {
      "x": -19,
      "y": 33,
      "z": -2,
      "name": "Plant_Crop_Mushroom_Block_Blue"
    },
    {
      "x": -19,
      "y": 28,
      "z": -1,
      "name": "Plant_Crop_Mushroom_Block_Blue"
    },
    {
      "x": -19,
      "y": 29,
      "z": -1,
      "name": "Plant_Crop_Mushroom_Block_Blue"
    },
    {
      "x": -19,
      "y": 30,
      "z": -1,
      "name": "Plant_Crop_Mushroom_Block_Blue"
    },
    {
      "x": -19,
      "y": 31,
      "z": -1,
      "name": "Plant_Crop_Mushroom_Block_Blue"
    },
    {
      "x": -19,
      "y": 32,
      "z": -1,
      "name": "Plant_Crop_Mushroom_Block_Blue"
    },
    {
      "x": -19,
      "y": 33,
      "z": -1,
      "name": "Plant_Crop_Mushroom_Block_Blue"
    },
    {
      "x": -19,
      "y": 29,
      "z": 0,
      "name": "Plant_Crop_Mushroom_Block_Blue"
    },
    {
      "x": -19,
      "y": 30,
      "z": 0,
      "name": "Plant_Crop_Mushroom_Block_Blue"
    },
    {
      "x": -19,
      "y": 31,
      "z": 0,
      "name": "Plant_Crop_Mushroom_Block_Blue"
    },
    {
      "x": -19,
      "y": 32,
      "z": 0,
      "name": "Plant_Crop_Mushroom_Block_Blue"
    },
    {
      "x": -19,
      "y": 33,
      "z": 0,
      "name": "Plant_Crop_Mushroom_Glowing_Blue"
    },
    {
      "x": -19,
      "y": 30,
      "z": 1,
      "name": "Plant_Crop_Mushroom_Block_Blue"
    },
    {
      "x": -19,
      "y": 31,
      "z": 1,
      "name": "Plant_Crop_Mushroom_Block_Blue"
    },
    {
      "x": -19,
      "y": 32,
      "z": 1,
      "name": "Plant_Crop_Mushroom_Block_Blue"
    },
    {
      "x": -19,
      "y": 30,
      "z": 2,
      "name": "Plant_Crop_Mushroom_Block_Blue"
    },
    {
      "x": -19,
      "y": 31,
      "z": 2,
      "name": "Plant_Crop_Mushroom_Block_Blue"
    },
    {
      "x": -19,
      "y": 32,
      "z": 2,
      "name": "Plant_Crop_Mushroom_Block_Blue"
    },
    {
      "x": -19,
      "y": 33,
      "z": 2,
      "name": "Plant_Crop_Mushroom_Block_Blue"
    },
    {
      "x": -19,
      "y": 30,
      "z": 3,
      "name": "Plant_Crop_Mushroom_Block_Blue"
    },
    {
      "x": -19,
      "y": 31,
      "z": 3,
      "name": "Plant_Crop_Mushroom_Block_Blue"
    },
    {
      "x": -19,
      "y": 32,
      "z": 3,
      "name": "Plant_Crop_Mushroom_Block_Blue"
    },
    {
      "x": -19,
      "y": 33,
      "z": 3,
      "name": "Plant_Crop_Mushroom_Glowing_Blue"
    },
    {
      "x": -19,
      "y": 30,
      "z": 4,
      "name": "Plant_Crop_Mushroom_Block_Blue"
    },
    {
      "x": -19,
      "y": 31,
      "z": 4,
      "name": "Plant_Crop_Mushroom_Block_Blue"
    },
    {
      "x": -19,
      "y": 32,
      "z": 4,
      "name": "Plant_Crop_Mushroom_Block_Blue"
    },
    {
      "x": -19,
      "y": 31,
      "z": 5,
      "name": "Plant_Crop_Mushroom_Block_Blue"
    },
    {
      "x": -19,
      "y": 32,
      "z": 5,
      "name": "Plant_Crop_Mushroom_Glowing_Blue"
    },
    {
      "x": -18,
      "y": 31,
      "z": -7,
      "name": "Plant_Crop_Mushroom_Block_Blue"
    },
    {
      "x": -18,
      "y": 32,
      "z": -7,
      "name": "Plant_Crop_Mushroom_Block_Blue"
    },
    {
      "x": -18,
      "y": 30,
      "z": -6,
      "name": "Plant_Crop_Mushroom_Block_Blue"
    },
    {
      "x": -18,
      "y": 31,
      "z": -6,
      "name": "Plant_Crop_Mushroom_Block_Blue"
    },
    {
      "x": -18,
      "y": 32,
      "z": -6,
      "name": "Plant_Crop_Mushroom_Block_Blue"
    },
    {
      "x": -18,
      "y": 33,
      "z": -6,
      "name": "Plant_Crop_Mushroom_Glowing_Blue"
    },
    {
      "x": -18,
      "y": 29,
      "z": -5,
      "name": "Plant_Crop_Mushroom_Block_Blue"
    },
    {
      "x": -18,
      "y": 30,
      "z": -5,
      "name": "Plant_Crop_Mushroom_Block_Blue"
    },
    {
      "x": -18,
      "y": 31,
      "z": -5,
      "name": "Plant_Crop_Mushroom_Block_Blue"
    },
    {
      "x": -18,
      "y": 32,
      "z": -5,
      "name": "Plant_Crop_Mushroom_Block_Blue"
    },
    {
      "x": -18,
      "y": 33,
      "z": -5,
      "name": "Plant_Crop_Mushroom_Block_Blue"
    },
    {
      "x": -18,
      "y": 29,
      "z": -4,
      "name": "Plant_Crop_Mushroom_Block_Blue"
    },
    {
      "x": -18,
      "y": 30,
      "z": -4,
      "name": "Plant_Crop_Mushroom_Block_Blue",
      "rotation": 1
    },
    {
      "x": -18,
      "y": 31,
      "z": -4,
      "name": "Plant_Crop_Mushroom_Block_Blue"
    },
    {
      "x": -18,
      "y": 32,
      "z": -4,
      "name": "Plant_Crop_Mushroom_Block_Blue"
    },
    {
      "x": -18,
      "y": 33,
      "z": -4,
      "name": "Plant_Crop_Mushroom_Block_Blue"
    },
    {
      "x": -18,
      "y": 34,
      "z": -4,
      "name": "Plant_Crop_Mushroom_Glowing_Blue"
    },
    {
      "x": -18,
      "y": 28,
      "z": -3,
      "name": "Plant_Crop_Mushroom_Block_Blue"
    },
    {
      "x": -18,
      "y": 29,
      "z": -3,
      "name": "Plant_Crop_Mushroom_Block_Blue",
      "rotation": 1
    },
    {
      "x": -18,
      "y": 30,
      "z": -3,
      "name": "Plant_Crop_Mushroom_Block_Blue",
      "rotation": 1
    },
    {
      "x": -18,
      "y": 31,
      "z": -3,
      "name": "Plant_Crop_Mushroom_Block_Blue",
      "rotation": 1
    },
    {
      "x": -18,
      "y": 32,
      "z": -3,
      "name": "Plant_Crop_Mushroom_Block_Blue"
    },
    {
      "x": -18,
      "y": 33,
      "z": -3,
      "name": "Plant_Crop_Mushroom_Block_Blue"
    },
    {
      "x": -18,
      "y": 34,
      "z": -3,
      "name": "Plant_Crop_Mushroom_Block_Blue"
    },
    {
      "x": -18,
      "y": 35,
      "z": -3,
      "name": "Plant_Crop_Mushroom_Glowing_Blue"
    },
    {
      "x": -18,
      "y": 18,
      "z": -2,
      "name": "Plant_Crop_Mushroom_Block_Blue_Mycelium"
    },
    {
      "x": -18,
      "y": 19,
      "z": -2,
      "name": "Plant_Crop_Mushroom_Block_Blue_Trunk"
    },
    {
      "x": -18,
      "y": 20,
      "z": -2,
      "name": "Plant_Crop_Mushroom_Block_Blue_Branch",
      "support": 15
    },
    {
      "x": -18,
      "y": 21,
      "z": -2,
      "name": "Plant_Crop_Mushroom_Block_Blue_Branch",
      "support": 15
    },
    {
      "x": -18,
      "y": 22,
      "z": -2,
      "name": "Plant_Crop_Mushroom_Block_Blue_Branch",
      "support": 15
    },
    {
      "x": -18,
      "y": 23,
      "z": -2,
      "name": "Plant_Crop_Mushroom_Block_Blue_Branch",
      "support": 15
    },
    {
      "x": -18,
      "y": 24,
      "z": -2,
      "name": "Plant_Crop_Mushroom_Block_Blue_Branch",
      "support": 15
    },
    {
      "x": -18,
      "y": 25,
      "z": -2,
      "name": "Plant_Crop_Mushroom_Block_Blue_Branch",
      "support": 15
    },
    {
      "x": -18,
      "y": 26,
      "z": -2,
      "name": "Plant_Crop_Mushroom_Block_Blue_Branch",
      "support": 15
    },
    {
      "x": -18,
      "y": 27,
      "z": -2,
      "name": "Plant_Crop_Mushroom_Block_Blue_Branch",
      "support": 15
    },
    {
      "x": -18,
      "y": 28,
      "z": -2,
      "name": "Plant_Crop_Mushroom_Block_Blue"
    },
    {
      "x": -18,
      "y": 29,
      "z": -2,
      "name": "Plant_Crop_Mushroom_Block_Blue",
      "rotation": 1
    },
    {
      "x": -18,
      "y": 30,
      "z": -2,
      "name": "Plant_Crop_Mushroom_Block_Blue",
      "rotation": 1
    },
    {
      "x": -18,
      "y": 31,
      "z": -2,
      "name": "Plant_Crop_Mushroom_Block_Blue",
      "rotation": 1
    },
    {
      "x": -18,
      "y": 32,
      "z": -2,
      "name": "Plant_Crop_Mushroom_Block_Blue",
      "rotation": 1
    },
    {
      "x": -18,
      "y": 33,
      "z": -2,
      "name": "Plant_Crop_Mushroom_Glowing_Blue",
      "rotation": 1
    },
    {
      "x": -18,
      "y": 34,
      "z": -2,
      "name": "Plant_Crop_Mushroom_Block_Blue"
    },
    {
      "x": -18,
      "y": 35,
      "z": -2,
      "name": "Plant_Crop_Mushroom_Glowing_Blue"
    },
    {
      "x": -18,
      "y": 28,
      "z": -1,
      "name": "Plant_Crop_Mushroom_Block_Blue"
    },
    {
      "x": -18,
      "y": 29,
      "z": -1,
      "name": "Plant_Crop_Mushroom_Block_Blue",
      "rotation": 1
    },
    {
      "x": -18,
      "y": 30,
      "z": -1,
      "name": "Plant_Crop_Mushroom_Block_Blue",
      "rotation": 1
    },
    {
      "x": -18,
      "y": 31,
      "z": -1,
      "name": "Plant_Crop_Mushroom_Block_Blue",
      "rotation": 1
    },
    {
      "x": -18,
      "y": 32,
      "z": -1,
      "name": "Plant_Crop_Mushroom_Block_Blue",
      "rotation": 1
    },
    {
      "x": -18,
      "y": 33,
      "z": -1,
      "name": "Plant_Crop_Mushroom_Glowing_Blue",
      "rotation": 1
    },
    {
      "x": -18,
      "y": 34,
      "z": -1,
      "name": "Plant_Crop_Mushroom_Block_Blue"
    },
    {
      "x": -18,
      "y": 28,
      "z": 0,
      "name": "Plant_Crop_Mushroom_Block_Blue"
    },
    {
      "x": -18,
      "y": 29,
      "z": 0,
      "name": "Plant_Crop_Mushroom_Block_Blue",
      "rotation": 1
    },
    {
      "x": -18,
      "y": 30,
      "z": 0,
      "name": "Plant_Crop_Mushroom_Block_Blue",
      "rotation": 1
    },
    {
      "x": -18,
      "y": 31,
      "z": 0,
      "name": "Plant_Crop_Mushroom_Block_Blue",
      "rotation": 1
    },
    {
      "x": -18,
      "y": 32,
      "z": 0,
      "name": "Plant_Crop_Mushroom_Block_Blue",
      "rotation": 1
    },
    {
      "x": -18,
      "y": 33,
      "z": 0,
      "name": "Plant_Crop_Mushroom_Block_Blue"
    },
    {
      "x": -18,
      "y": 34,
      "z": 0,
      "name": "Plant_Crop_Mushroom_Block_Blue"
    },
    {
      "x": -18,
      "y": 35,
      "z": 0,
      "name": "Plant_Crop_Mushroom_Glowing_Blue"
    },
    {
      "x": -18,
      "y": 28,
      "z": 1,
      "name": "Plant_Crop_Mushroom_Block_Blue"
    },
    {
      "x": -18,
      "y": 29,
      "z": 1,
      "name": "Plant_Crop_Mushroom_Block_Blue"
    },
    {
      "x": -18,
      "y": 30,
      "z": 1,
      "name": "Plant_Crop_Mushroom_Block_Blue",
      "rotation": 1
    },
    {
      "x": -18,
      "y": 31,
      "z": 1,
      "name": "Plant_Crop_Mushroom_Block_Blue",
      "rotation": 1
    },
    {
      "x": -18,
      "y": 32,
      "z": 1,
      "name": "Plant_Crop_Mushroom_Block_Blue",
      "rotation": 1
    },
    {
      "x": -18,
      "y": 33,
      "z": 1,
      "name": "Plant_Crop_Mushroom_Block_Blue"
    },
    {
      "x": -18,
      "y": 34,
      "z": 1,
      "name": "Plant_Crop_Mushroom_Block_Blue"
    },
    {
      "x": -18,
      "y": 35,
      "z": 1,
      "name": "Plant_Crop_Mushroom_Glowing_Blue"
    },
    {
      "x": -18,
      "y": 28,
      "z": 2,
      "name": "Plant_Crop_Mushroom_Block_Blue"
    },
    {
      "x": -18,
      "y": 29,
      "z": 2,
      "name": "Plant_Crop_Mushroom_Block_Blue"
    },
    {
      "x": -18,
      "y": 30,
      "z": 2,
      "name": "Plant_Crop_Mushroom_Block_Blue",
      "rotation": 1
    },
    {
      "x": -18,
      "y": 31,
      "z": 2,
      "name": "Plant_Crop_Mushroom_Block_Blue",
      "rotation": 1
    },
    {
      "x": -18,
      "y": 32,
      "z": 2,
      "name": "Plant_Crop_Mushroom_Block_Blue",
      "rotation": 1
    },
    {
      "x": -18,
      "y": 33,
      "z": 2,
      "name": "Plant_Crop_Mushroom_Glowing_Blue",
      "rotation": 1
    },
    {
      "x": -18,
      "y": 34,
      "z": 2,
      "name": "Plant_Crop_Mushroom_Block_Blue"
    },
    {
      "x": -18,
      "y": 35,
      "z": 2,
      "name": "Plant_Crop_Mushroom_Glowing_Blue"
    },
    {
      "x": -18,
      "y": 28,
      "z": 3,
      "name": "Plant_Crop_Mushroom_Block_Blue"
    },
    {
      "x": -18,
      "y": 29,
      "z": 3,
      "name": "Plant_Crop_Mushroom_Block_Blue"
    },
    {
      "x": -18,
      "y": 30,
      "z": 3,
      "name": "Plant_Crop_Mushroom_Block_Blue",
      "rotation": 1
    },
    {
      "x": -18,
      "y": 31,
      "z": 3,
      "name": "Plant_Crop_Mushroom_Block_Blue",
      "rotation": 1
    },
    {
      "x": -18,
      "y": 32,
      "z": 3,
      "name": "Plant_Crop_Mushroom_Block_Blue",
      "rotation": 1
    },
    {
      "x": -18,
      "y": 33,
      "z": 3,
      "name": "Plant_Crop_Mushroom_Block_Blue"
    },
    {
      "x": -18,
      "y": 34,
      "z": 3,
      "name": "Plant_Crop_Mushroom_Block_Blue"
    },
    {
      "x": -18,
      "y": 29,
      "z": 4,
      "name": "Plant_Crop_Mushroom_Block_Blue"
    },
    {
      "x": -18,
      "y": 30,
      "z": 4,
      "name": "Plant_Crop_Mushroom_Block_Blue",
      "rotation": 1
    },
    {
      "x": -18,
      "y": 31,
      "z": 4,
      "name": "Plant_Crop_Mushroom_Block_Blue",
      "rotation": 1
    },
    {
      "x": -18,
      "y": 32,
      "z": 4,
      "name": "Plant_Crop_Mushroom_Block_Blue",
      "rotation": 1
    },
    {
      "x": -18,
      "y": 33,
      "z": 4,
      "name": "Plant_Crop_Mushroom_Block_Blue"
    },
    {
      "x": -18,
      "y": 34,
      "z": 4,
      "name": "Plant_Crop_Mushroom_Block_Blue"
    },
    {
      "x": -18,
      "y": 29,
      "z": 5,
      "name": "Plant_Crop_Mushroom_Block_Blue"
    },
    {
      "x": -18,
      "y": 30,
      "z": 5,
      "name": "Plant_Crop_Mushroom_Block_Blue"
    },
    {
      "x": -18,
      "y": 31,
      "z": 5,
      "name": "Plant_Crop_Mushroom_Block_Blue"
    },
    {
      "x": -18,
      "y": 32,
      "z": 5,
      "name": "Plant_Crop_Mushroom_Block_Blue"
    },
    {
      "x": -18,
      "y": 33,
      "z": 5,
      "name": "Plant_Crop_Mushroom_Block_Blue"
    },
    {
      "x": -18,
      "y": 28,
      "z": 6,
      "name": "Plant_Crop_Mushroom_Block_Blue"
    },
    {
      "x": -18,
      "y": 29,
      "z": 6,
      "name": "Plant_Crop_Mushroom_Block_Blue"
    },
    {
      "x": -18,
      "y": 30,
      "z": 6,
      "name": "Plant_Crop_Mushroom_Block_Blue"
    },
    {
      "x": -18,
      "y": 31,
      "z": 6,
      "name": "Plant_Crop_Mushroom_Block_Blue"
    },
    {
      "x": -18,
      "y": 32,
      "z": 6,
      "name": "Plant_Crop_Mushroom_Block_Blue"
    },
    {
      "x": -18,
      "y": 33,
      "z": 6,
      "name": "Plant_Crop_Mushroom_Block_Blue"
    },
    {
      "x": -18,
      "y": 31,
      "z": 7,
      "name": "Plant_Crop_Mushroom_Block_Blue"
    },
    {
      "x": -18,
      "y": 32,
      "z": 7,
      "name": "Plant_Crop_Mushroom_Block_Blue"
    },
    {
      "x": -18,
      "y": 33,
      "z": 7,
      "name": "Plant_Crop_Mushroom_Glowing_Blue"
    },
    {
      "x": -17,
      "y": 31,
      "z": -10,
      "name": "Plant_Crop_Mushroom_Block_Blue"
    },
    {
      "x": -17,
      "y": 32,
      "z": -10,
      "name": "Plant_Crop_Mushroom_Block_Blue"
    },
    {
      "x": -17,
      "y": 33,
      "z": -10,
      "name": "Plant_Crop_Mushroom_Glowing_Blue"
    },
    {
      "x": -17,
      "y": 29,
      "z": -9,
      "name": "Plant_Crop_Mushroom_Block_Blue"
    },
    {
      "x": -17,
      "y": 30,
      "z": -9,
      "name": "Plant_Crop_Mushroom_Block_Blue"
    },
    {
      "x": -17,
      "y": 31,
      "z": -9,
      "name": "Plant_Crop_Mushroom_Block_Blue",
      "rotation": 1
    },
    {
      "x": -17,
      "y": 32,
      "z": -9,
      "name": "Plant_Crop_Mushroom_Block_Blue",
      "rotation": 1
    },
    {
      "x": -17,
      "y": 33,
      "z": -9,
      "name": "Plant_Crop_Mushroom_Block_Blue"
    },
    {
      "x": -17,
      "y": 29,
      "z": -8,
      "name": "Plant_Crop_Mushroom_Block_Blue"
    },
    {
      "x": -17,
      "y": 30,
      "z": -8,
      "name": "Plant_Crop_Mushroom_Block_Blue"
    },
    {
      "x": -17,
      "y": 31,
      "z": -8,
      "name": "Plant_Crop_Mushroom_Block_Blue",
      "rotation": 1
    },
    {
      "x": -17,
      "y": 32,
      "z": -8,
      "name": "Plant_Crop_Mushroom_Block_Blue",
      "rotation": 1
    },
    {
      "x": -17,
      "y": 33,
      "z": -8,
      "name": "Plant_Crop_Mushroom_Block_Blue"
    },
    {
      "x": -17,
      "y": 34,
      "z": -8,
      "name": "Plant_Crop_Mushroom_Block_Blue"
    },
    {
      "x": -17,
      "y": 20,
      "z": -7,
      "name": "Plant_Crop_Mushroom_Block_Blue_Mycelium"
    },
    {
      "x": -17,
      "y": 21,
      "z": -7,
      "name": "Plant_Crop_Mushroom_Block_Blue_Trunk"
    },
    {
      "x": -17,
      "y": 22,
      "z": -7,
      "name": "Plant_Crop_Mushroom_Block_Blue_Branch",
      "support": 15
    },
    {
      "x": -17,
      "y": 23,
      "z": -7,
      "name": "Plant_Crop_Mushroom_Block_Blue_Branch",
      "support": 15
    },
    {
      "x": -17,
      "y": 24,
      "z": -7,
      "name": "Plant_Crop_Mushroom_Block_Blue_Branch",
      "support": 15
    },
    {
      "x": -17,
      "y": 25,
      "z": -7,
      "name": "Plant_Crop_Mushroom_Block_Blue_Branch",
      "support": 15
    },
    {
      "x": -17,
      "y": 26,
      "z": -7,
      "name": "Plant_Crop_Mushroom_Block_Blue_Branch",
      "support": 15
    },
    {
      "x": -17,
      "y": 27,
      "z": -7,
      "name": "Plant_Crop_Mushroom_Block_Blue_Branch",
      "support": 15
    },
    {
      "x": -17,
      "y": 28,
      "z": -7,
      "name": "Plant_Crop_Mushroom_Block_Blue"
    },
    {
      "x": -17,
      "y": 29,
      "z": -7,
      "name": "Plant_Crop_Mushroom_Block_Blue"
    },
    {
      "x": -17,
      "y": 30,
      "z": -7,
      "name": "Plant_Crop_Mushroom_Block_Blue",
      "rotation": 1
    },
    {
      "x": -17,
      "y": 31,
      "z": -7,
      "name": "Plant_Crop_Mushroom_Block_Blue",
      "rotation": 1
    },
    {
      "x": -17,
      "y": 32,
      "z": -7,
      "name": "Plant_Crop_Mushroom_Block_Blue",
      "rotation": 1
    },
    {
      "x": -17,
      "y": 33,
      "z": -7,
      "name": "Plant_Crop_Mushroom_Block_Blue",
      "rotation": 1
    },
    {
      "x": -17,
      "y": 34,
      "z": -7,
      "name": "Plant_Crop_Mushroom_Block_Blue"
    },
    {
      "x": -17,
      "y": 35,
      "z": -7,
      "name": "Plant_Crop_Mushroom_Glowing_Blue"
    },
    {
      "x": -17,
      "y": 28,
      "z": -6,
      "name": "Plant_Crop_Mushroom_Block_Blue"
    },
    {
      "x": -17,
      "y": 29,
      "z": -6,
      "name": "Plant_Crop_Mushroom_Block_Blue"
    },
    {
      "x": -17,
      "y": 30,
      "z": -6,
      "name": "Plant_Crop_Mushroom_Block_Blue",
      "rotation": 1
    },
    {
      "x": -17,
      "y": 31,
      "z": -6,
      "name": "Plant_Crop_Mushroom_Block_Blue",
      "rotation": 1
    },
    {
      "x": -17,
      "y": 32,
      "z": -6,
      "name": "Plant_Crop_Mushroom_Block_Blue",
      "rotation": 1
    },
    {
      "x": -17,
      "y": 33,
      "z": -6,
      "name": "Plant_Crop_Mushroom_Block_Blue",
      "rotation": 1
    },
    {
      "x": -17,
      "y": 34,
      "z": -6,
      "name": "Plant_Crop_Mushroom_Block_Blue"
    },
    {
      "x": -17,
      "y": 35,
      "z": -6,
      "name": "Plant_Crop_Mushroom_Block_Blue"
    },
    {
      "x": -17,
      "y": 28,
      "z": -5,
      "name": "Plant_Crop_Mushroom_Block_Blue"
    },
    {
      "x": -17,
      "y": 29,
      "z": -5,
      "name": "Plant_Crop_Mushroom_Block_Blue",
      "rotation": 1
    },
    {
      "x": -17,
      "y": 30,
      "z": -5,
      "name": "Plant_Crop_Mushroom_Block_Blue",
      "rotation": 1
    },
    {
      "x": -17,
      "y": 31,
      "z": -5,
      "name": "Plant_Crop_Mushroom_Block_Blue",
      "rotation": 1
    },
    {
      "x": -17,
      "y": 32,
      "z": -5,
      "name": "Plant_Crop_Mushroom_Block_Blue",
      "rotation": 1
    },
    {
      "x": -17,
      "y": 33,
      "z": -5,
      "name": "Plant_Crop_Mushroom_Block_Blue",
      "rotation": 1
    },
    {
      "x": -17,
      "y": 34,
      "z": -5,
      "name": "Plant_Crop_Mushroom_Block_Blue"
    },
    {
      "x": -17,
      "y": 35,
      "z": -5,
      "name": "Plant_Crop_Mushroom_Block_Blue"
    },
    {
      "x": -17,
      "y": 36,
      "z": -5,
      "name": "Plant_Crop_Mushroom_Glowing_Blue"
    },
    {
      "x": -17,
      "y": 28,
      "z": -4,
      "name": "Plant_Crop_Mushroom_Block_Blue"
    },
    {
      "x": -17,
      "y": 29,
      "z": -4,
      "name": "Plant_Crop_Mushroom_Block_Blue",
      "rotation": 1
    },
    {
      "x": -17,
      "y": 30,
      "z": -4,
      "name": "Plant_Crop_Mushroom_Block_Blue",
      "rotation": 1
    },
    {
      "x": -17,
      "y": 31,
      "z": -4,
      "name": "Plant_Crop_Mushroom_Block_Blue",
      "rotation": 1
    },
    {
      "x": -17,
      "y": 32,
      "z": -4,
      "name": "Plant_Crop_Mushroom_Block_Blue",
      "rotation": 1
    },
    {
      "x": -17,
      "y": 33,
      "z": -4,
      "name": "Plant_Crop_Mushroom_Block_Blue",
      "rotation": 1
    },
    {
      "x": -17,
      "y": 34,
      "z": -4,
      "name": "Plant_Crop_Mushroom_Block_Blue"
    },
    {
      "x": -17,
      "y": 35,
      "z": -4,
      "name": "Plant_Crop_Mushroom_Block_Blue"
    },
    {
      "x": -17,
      "y": 27,
      "z": -3,
      "name": "Plant_Crop_Mushroom_Block_Blue"
    },
    {
      "x": -17,
      "y": 28,
      "z": -3,
      "name": "Plant_Crop_Mushroom_Block_Blue",
      "rotation": 1
    },
    {
      "x": -17,
      "y": 29,
      "z": -3,
      "name": "Plant_Crop_Mushroom_Block_Blue",
      "rotation": 1
    },
    {
      "x": -17,
      "y": 30,
      "z": -3,
      "name": "Plant_Crop_Mushroom_Block_Blue",
      "rotation": 1
    },
    {
      "x": -17,
      "y": 31,
      "z": -3,
      "name": "Plant_Crop_Mushroom_Block_Blue",
      "rotation": 1
    },
    {
      "x": -17,
      "y": 32,
      "z": -3,
      "name": "Plant_Crop_Mushroom_Block_Blue",
      "rotation": 1
    },
    {
      "x": -17,
      "y": 33,
      "z": -3,
      "name": "Plant_Crop_Mushroom_Block_Blue",
      "rotation": 1
    },
    {
      "x": -17,
      "y": 34,
      "z": -3,
      "name": "Plant_Crop_Mushroom_Block_Blue",
      "rotation": 1
    },
    {
      "x": -17,
      "y": 35,
      "z": -3,
      "name": "Plant_Crop_Mushroom_Block_Blue"
    },
    {
      "x": -17,
      "y": 36,
      "z": -3,
      "name": "Plant_Crop_Mushroom_Glowing_Blue"
    },
    {
      "x": -17,
      "y": 27,
      "z": -2,
      "name": "Plant_Crop_Mushroom_Block_Blue"
    },
    {
      "x": -17,
      "y": 28,
      "z": -2,
      "name": "Plant_Crop_Mushroom_Block_Blue",
      "rotation": 1
    },
    {
      "x": -17,
      "y": 29,
      "z": -2,
      "name": "Plant_Crop_Mushroom_Block_Blue",
      "rotation": 1
    },
    {
      "x": -17,
      "y": 30,
      "z": -2,
      "name": "Plant_Crop_Mushroom_Block_Blue",
      "rotation": 1
    },
    {
      "x": -17,
      "y": 31,
      "z": -2,
      "name": "Plant_Crop_Mushroom_Block_Blue",
      "rotation": 1
    },
    {
      "x": -17,
      "y": 32,
      "z": -2,
      "name": "Plant_Crop_Mushroom_Block_Blue",
      "rotation": 1
    },
    {
      "x": -17,
      "y": 33,
      "z": -2,
      "name": "Plant_Crop_Mushroom_Block_Blue",
      "rotation": 1
    },
    {
      "x": -17,
      "y": 34,
      "z": -2,
      "name": "Plant_Crop_Mushroom_Block_Blue",
      "rotation": 1
    },
    {
      "x": -17,
      "y": 35,
      "z": -2,
      "name": "Plant_Crop_Mushroom_Block_Blue"
    },
    {
      "x": -17,
      "y": 36,
      "z": -2,
      "name": "Plant_Crop_Mushroom_Block_Blue"
    },
    {
      "x": -17,
      "y": 27,
      "z": -1,
      "name": "Plant_Crop_Mushroom_Block_Blue"
    },
    {
      "x": -17,
      "y": 28,
      "z": -1,
      "name": "Plant_Crop_Mushroom_Block_Blue"
    },
    {
      "x": -17,
      "y": 29,
      "z": -1,
      "name": "Plant_Crop_Mushroom_Block_Blue",
      "rotation": 1
    },
    {
      "x": -17,
      "y": 30,
      "z": -1,
      "name": "Plant_Crop_Mushroom_Block_Blue",
      "rotation": 1
    },
    {
      "x": -17,
      "y": 31,
      "z": -1,
      "name": "Plant_Crop_Mushroom_Block_Blue",
      "rotation": 1
    },
    {
      "x": -17,
      "y": 32,
      "z": -1,
      "name": "Plant_Crop_Mushroom_Block_Blue",
      "rotation": 1
    },
    {
      "x": -17,
      "y": 33,
      "z": -1,
      "name": "Plant_Crop_Mushroom_Block_Blue",
      "rotation": 1
    },
    {
      "x": -17,
      "y": 34,
      "z": -1,
      "name": "Plant_Crop_Mushroom_Block_Blue",
      "rotation": 1
    },
    {
      "x": -17,
      "y": 35,
      "z": -1,
      "name": "Plant_Crop_Mushroom_Block_Blue"
    },
    {
      "x": -17,
      "y": 36,
      "z": -1,
      "name": "Plant_Crop_Mushroom_Block_Blue"
    },
    {
      "x": -17,
      "y": 22,
      "z": 0,
      "name": "Plant_Crop_Mushroom_Block_Blue_Mycelium"
    },
    {
      "x": -17,
      "y": 23,
      "z": 0,
      "name": "Plant_Crop_Mushroom_Block_Blue_Trunk"
    },
    {
      "x": -17,
      "y": 24,
      "z": 0,
      "name": "Plant_Crop_Mushroom_Block_Blue_Branch",
      "support": 15
    },
    {
      "x": -17,
      "y": 25,
      "z": 0,
      "name": "Plant_Crop_Mushroom_Block_Blue_Branch",
      "support": 15
    },
    {
      "x": -17,
      "y": 26,
      "z": 0,
      "name": "Plant_Crop_Mushroom_Block_Blue_Branch",
      "support": 15
    },
    {
      "x": -17,
      "y": 27,
      "z": 0,
      "name": "Plant_Crop_Mushroom_Block_Blue"
    },
    {
      "x": -17,
      "y": 28,
      "z": 0,
      "name": "Plant_Crop_Mushroom_Block_Blue"
    },
    {
      "x": -17,
      "y": 29,
      "z": 0,
      "name": "Plant_Crop_Mushroom_Block_Blue",
      "rotation": 1
    },
    {
      "x": -17,
      "y": 30,
      "z": 0,
      "name": "Plant_Crop_Mushroom_Block_Blue",
      "rotation": 1
    },
    {
      "x": -17,
      "y": 31,
      "z": 0,
      "name": "Plant_Crop_Mushroom_Block_Blue",
      "rotation": 1
    },
    {
      "x": -17,
      "y": 32,
      "z": 0,
      "name": "Plant_Crop_Mushroom_Block_Blue",
      "rotation": 1
    },
    {
      "x": -17,
      "y": 33,
      "z": 0,
      "name": "Plant_Crop_Mushroom_Block_Blue",
      "rotation": 1
    },
    {
      "x": -17,
      "y": 34,
      "z": 0,
      "name": "Plant_Crop_Mushroom_Block_Blue",
      "rotation": 1
    },
    {
      "x": -17,
      "y": 35,
      "z": 0,
      "name": "Plant_Crop_Mushroom_Block_Blue"
    },
    {
      "x": -17,
      "y": 36,
      "z": 0,
      "name": "Plant_Crop_Mushroom_Block_Blue"
    },
    {
      "x": -17,
      "y": 37,
      "z": 0,
      "name": "Plant_Crop_Mushroom_Glowing_Blue"
    },
    {
      "x": -17,
      "y": 27,
      "z": 1,
      "name": "Plant_Crop_Mushroom_Block_Blue"
    },
    {
      "x": -17,
      "y": 28,
      "z": 1,
      "name": "Plant_Crop_Mushroom_Block_Blue"
    },
    {
      "x": -17,
      "y": 29,
      "z": 1,
      "name": "Plant_Crop_Mushroom_Block_Blue",
      "rotation": 1
    },
    {
      "x": -17,
      "y": 30,
      "z": 1,
      "name": "Plant_Crop_Mushroom_Block_Blue",
      "rotation": 1
    },
    {
      "x": -17,
      "y": 31,
      "z": 1,
      "name": "Plant_Crop_Mushroom_Block_Blue",
      "rotation": 1
    },
    {
      "x": -17,
      "y": 32,
      "z": 1,
      "name": "Plant_Crop_Mushroom_Block_Blue",
      "rotation": 1
    },
    {
      "x": -17,
      "y": 33,
      "z": 1,
      "name": "Plant_Crop_Mushroom_Block_Blue",
      "rotation": 1
    },
    {
      "x": -17,
      "y": 34,
      "z": 1,
      "name": "Plant_Crop_Mushroom_Block_Blue",
      "rotation": 1
    },
    {
      "x": -17,
      "y": 35,
      "z": 1,
      "name": "Plant_Crop_Mushroom_Block_Blue"
    },
    {
      "x": -17,
      "y": 36,
      "z": 1,
      "name": "Plant_Crop_Mushroom_Block_Blue"
    },
    {
      "x": -17,
      "y": 27,
      "z": 2,
      "name": "Plant_Crop_Mushroom_Block_Blue"
    },
    {
      "x": -17,
      "y": 28,
      "z": 2,
      "name": "Plant_Crop_Mushroom_Block_Blue"
    },
    {
      "x": -17,
      "y": 29,
      "z": 2,
      "name": "Plant_Crop_Mushroom_Block_Blue",
      "rotation": 1
    },
    {
      "x": -17,
      "y": 30,
      "z": 2,
      "name": "Plant_Crop_Mushroom_Block_Blue",
      "rotation": 1
    },
    {
      "x": -17,
      "y": 31,
      "z": 2,
      "name": "Plant_Crop_Mushroom_Block_Blue",
      "rotation": 1
    },
    {
      "x": -17,
      "y": 32,
      "z": 2,
      "name": "Plant_Crop_Mushroom_Block_Blue",
      "rotation": 1
    },
    {
      "x": -17,
      "y": 33,
      "z": 2,
      "name": "Plant_Crop_Mushroom_Block_Blue",
      "rotation": 1
    },
    {
      "x": -17,
      "y": 34,
      "z": 2,
      "name": "Plant_Crop_Mushroom_Block_Blue",
      "rotation": 1
    },
    {
      "x": -17,
      "y": 35,
      "z": 2,
      "name": "Plant_Crop_Mushroom_Block_Blue"
    },
    {
      "x": -17,
      "y": 36,
      "z": 2,
      "name": "Plant_Crop_Mushroom_Block_Blue"
    },
    {
      "x": -17,
      "y": 37,
      "z": 2,
      "name": "Plant_Crop_Mushroom_Glowing_Blue"
    },
    {
      "x": -17,
      "y": 28,
      "z": 3,
      "name": "Plant_Crop_Mushroom_Block_Blue",
      "rotation": 1
    },
    {
      "x": -17,
      "y": 29,
      "z": 3,
      "name": "Plant_Crop_Mushroom_Block_Blue",
      "rotation": 1
    },
    {
      "x": -17,
      "y": 30,
      "z": 3,
      "name": "Plant_Crop_Mushroom_Block_Blue",
      "rotation": 1
    },
    {
      "x": -17,
      "y": 31,
      "z": 3,
      "name": "Plant_Crop_Mushroom_Block_Blue",
      "rotation": 1
    },
    {
      "x": -17,
      "y": 32,
      "z": 3,
      "name": "Plant_Crop_Mushroom_Block_Blue",
      "rotation": 1
    },
    {
      "x": -17,
      "y": 33,
      "z": 3,
      "name": "Plant_Crop_Mushroom_Block_Blue",
      "rotation": 1
    },
    {
      "x": -17,
      "y": 34,
      "z": 3,
      "name": "Plant_Crop_Mushroom_Block_Blue",
      "rotation": 1
    },
    {
      "x": -17,
      "y": 35,
      "z": 3,
      "name": "Plant_Crop_Mushroom_Block_Blue"
    },
    {
      "x": -17,
      "y": 36,
      "z": 3,
      "name": "Plant_Crop_Mushroom_Block_Blue"
    },
    {
      "x": -17,
      "y": 28,
      "z": 4,
      "name": "Plant_Crop_Mushroom_Block_Blue"
    },
    {
      "x": -17,
      "y": 29,
      "z": 4,
      "name": "Plant_Crop_Mushroom_Block_Blue",
      "rotation": 1
    },
    {
      "x": -17,
      "y": 30,
      "z": 4,
      "name": "Plant_Crop_Mushroom_Block_Blue",
      "rotation": 1
    },
    {
      "x": -17,
      "y": 31,
      "z": 4,
      "name": "Plant_Crop_Mushroom_Block_Blue",
      "rotation": 1
    },
    {
      "x": -17,
      "y": 32,
      "z": 4,
      "name": "Plant_Crop_Mushroom_Block_Blue",
      "rotation": 1
    },
    {
      "x": -17,
      "y": 33,
      "z": 4,
      "name": "Plant_Crop_Mushroom_Block_Blue",
      "rotation": 1
    },
    {
      "x": -17,
      "y": 34,
      "z": 4,
      "name": "Plant_Crop_Mushroom_Block_Blue",
      "rotation": 1
    },
    {
      "x": -17,
      "y": 35,
      "z": 4,
      "name": "Plant_Crop_Mushroom_Block_Blue"
    },
    {
      "x": -17,
      "y": 28,
      "z": 5,
      "name": "Plant_Crop_Mushroom_Block_Blue"
    },
    {
      "x": -17,
      "y": 29,
      "z": 5,
      "name": "Plant_Crop_Mushroom_Block_Blue",
      "rotation": 1
    },
    {
      "x": -17,
      "y": 30,
      "z": 5,
      "name": "Plant_Crop_Mushroom_Block_Blue",
      "rotation": 1
    },
    {
      "x": -17,
      "y": 31,
      "z": 5,
      "name": "Plant_Crop_Mushroom_Block_Blue",
      "rotation": 1
    },
    {
      "x": -17,
      "y": 32,
      "z": 5,
      "name": "Plant_Crop_Mushroom_Block_Blue",
      "rotation": 1
    },
    {
      "x": -17,
      "y": 33,
      "z": 5,
      "name": "Plant_Crop_Mushroom_Block_Blue",
      "rotation": 1
    },
    {
      "x": -17,
      "y": 34,
      "z": 5,
      "name": "Plant_Crop_Mushroom_Block_Blue"
    },
    {
      "x": -17,
      "y": 35,
      "z": 5,
      "name": "Plant_Crop_Mushroom_Block_Blue"
    },
    {
      "x": -17,
      "y": 36,
      "z": 5,
      "name": "Plant_Crop_Mushroom_Glowing_Blue"
    },
    {
      "x": -17,
      "y": 27,
      "z": 6,
      "name": "Plant_Crop_Mushroom_Block_Blue"
    },
    {
      "x": -17,
      "y": 28,
      "z": 6,
      "name": "Plant_Crop_Mushroom_Block_Blue",
      "rotation": 1
    },
    {
      "x": -17,
      "y": 29,
      "z": 6,
      "name": "Plant_Crop_Mushroom_Block_Blue",
      "rotation": 1
    },
    {
      "x": -17,
      "y": 30,
      "z": 6,
      "name": "Plant_Crop_Mushroom_Block_Blue",
      "rotation": 1
    },
    {
      "x": -17,
      "y": 31,
      "z": 6,
      "name": "Plant_Crop_Mushroom_Block_Blue",
      "rotation": 1
    },
    {
      "x": -17,
      "y": 32,
      "z": 6,
      "name": "Plant_Crop_Mushroom_Block_Blue",
      "rotation": 1
    },
    {
      "x": -17,
      "y": 33,
      "z": 6,
      "name": "Plant_Crop_Mushroom_Block_Blue",
      "rotation": 1
    },
    {
      "x": -17,
      "y": 34,
      "z": 6,
      "name": "Plant_Crop_Mushroom_Block_Blue"
    },
    {
      "x": -17,
      "y": 35,
      "z": 6,
      "name": "Plant_Crop_Mushroom_Block_Blue"
    },
    {
      "x": -17,
      "y": 28,
      "z": 7,
      "name": "Plant_Crop_Mushroom_Block_Blue"
    },
    {
      "x": -17,
      "y": 29,
      "z": 7,
      "name": "Plant_Crop_Mushroom_Block_Blue"
    },
    {
      "x": -17,
      "y": 30,
      "z": 7,
      "name": "Plant_Crop_Mushroom_Block_Blue",
      "rotation": 1
    },
    {
      "x": -17,
      "y": 31,
      "z": 7,
      "name": "Plant_Crop_Mushroom_Block_Blue",
      "rotation": 1
    },
    {
      "x": -17,
      "y": 32,
      "z": 7,
      "name": "Plant_Crop_Mushroom_Block_Blue",
      "rotation": 1
    },
    {
      "x": -17,
      "y": 33,
      "z": 7,
      "name": "Plant_Crop_Mushroom_Block_Blue",
      "rotation": 1
    },
    {
      "x": -17,
      "y": 34,
      "z": 7,
      "name": "Plant_Crop_Mushroom_Block_Blue"
    },
    {
      "x": -17,
      "y": 35,
      "z": 7,
      "name": "Plant_Crop_Mushroom_Block_Blue"
    },
    {
      "x": -17,
      "y": 29,
      "z": 8,
      "name": "Plant_Crop_Mushroom_Block_Blue"
    },
    {
      "x": -17,
      "y": 30,
      "z": 8,
      "name": "Plant_Crop_Mushroom_Block_Blue",
      "rotation": 1
    },
    {
      "x": -17,
      "y": 31,
      "z": 8,
      "name": "Plant_Crop_Mushroom_Block_Blue",
      "rotation": 1
    },
    {
      "x": -17,
      "y": 32,
      "z": 8,
      "name": "Plant_Crop_Mushroom_Block_Blue",
      "rotation": 1
    },
    {
      "x": -17,
      "y": 33,
      "z": 8,
      "name": "Plant_Crop_Mushroom_Block_Blue",
      "rotation": 1
    },
    {
      "x": -17,
      "y": 34,
      "z": 8,
      "name": "Plant_Crop_Mushroom_Block_Blue"
    },
    {
      "x": -17,
      "y": 35,
      "z": 8,
      "name": "Plant_Crop_Mushroom_Block_Blue"
    },
    {
      "x": -17,
      "y": 29,
      "z": 9,
      "name": "Plant_Crop_Mushroom_Block_Blue"
    },
    {
      "x": -17,
      "y": 30,
      "z": 9,
      "name": "Plant_Crop_Mushroom_Block_Blue"
    },
    {
      "x": -17,
      "y": 31,
      "z": 9,
      "name": "Plant_Crop_Mushroom_Block_Blue",
      "rotation": 1
    },
    {
      "x": -17,
      "y": 32,
      "z": 9,
      "name": "Plant_Crop_Mushroom_Block_Blue",
      "rotation": 1
    },
    {
      "x": -17,
      "y": 33,
      "z": 9,
      "name": "Plant_Crop_Mushroom_Block_Blue"
    },
    {
      "x": -17,
      "y": 34,
      "z": 9,
      "name": "Plant_Crop_Mushroom_Block_Blue"
    },
    {
      "x": -17,
      "y": 35,
      "z": 9,
      "name": "Plant_Crop_Mushroom_Glowing_Blue"
    },
    {
      "x": -17,
      "y": 30,
      "z": 10,
      "name": "Plant_Crop_Mushroom_Block_Blue"
    },
    {
      "x": -17,
      "y": 31,
      "z": 10,
      "name": "Plant_Crop_Mushroom_Block_Blue",
      "rotation": 1
    },
    {
      "x": -17,
      "y": 32,
      "z": 10,
      "name": "Plant_Crop_Mushroom_Block_Blue",
      "rotation": 1
    },
    {
      "x": -17,
      "y": 33,
      "z": 10,
      "name": "Plant_Crop_Mushroom_Block_Blue"
    },
    {
      "x": -17,
      "y": 34,
      "z": 10,
      "name": "Plant_Crop_Mushroom_Glowing_Blue"
    },
    {
      "x": -16,
      "y": 30,
      "z": -11,
      "name": "Plant_Crop_Mushroom_Block_Blue",
      "rotation": 1
    },
    {
      "x": -16,
      "y": 31,
      "z": -11,
      "name": "Plant_Crop_Mushroom_Block_Blue",
      "rotation": 1
    },
    {
      "x": -16,
      "y": 32,
      "z": -11,
      "name": "Plant_Crop_Mushroom_Block_Blue",
      "rotation": 1
    },
    {
      "x": -16,
      "y": 33,
      "z": -11,
      "name": "Plant_Crop_Mushroom_Block_Blue",
      "rotation": 1
    },
    {
      "x": -16,
      "y": 34,
      "z": -11,
      "name": "Plant_Crop_Mushroom_Block_Blue"
    },
    {
      "x": -16,
      "y": 35,
      "z": -11,
      "name": "Plant_Crop_Mushroom_Block_Blue"
    },
    {
      "x": -16,
      "y": 29,
      "z": -10,
      "name": "Plant_Crop_Mushroom_Block_Blue"
    },
    {
      "x": -16,
      "y": 30,
      "z": -10,
      "name": "Plant_Crop_Mushroom_Block_Blue",
      "rotation": 1
    },
    {
      "x": -16,
      "y": 31,
      "z": -10,
      "name": "Plant_Crop_Mushroom_Block_Blue",
      "rotation": 1
    },
    {
      "x": -16,
      "y": 32,
      "z": -10,
      "name": "Plant_Crop_Mushroom_Block_Blue",
      "rotation": 1
    },
    {
      "x": -16,
      "y": 33,
      "z": -10,
      "name": "Plant_Crop_Mushroom_Block_Blue",
      "rotation": 1
    },
    {
      "x": -16,
      "y": 34,
      "z": -10,
      "name": "Plant_Crop_Mushroom_Block_Blue",
      "rotation": 1
    },
    {
      "x": -16,
      "y": 35,
      "z": -10,
      "name": "Plant_Crop_Mushroom_Block_Blue"
    },
    {
      "x": -16,
      "y": 28,
      "z": -9,
      "name": "Plant_Crop_Mushroom_Block_Blue"
    },
    {
      "x": -16,
      "y": 29,
      "z": -9,
      "name": "Plant_Crop_Mushroom_Block_Blue",
      "rotation": 1
    },
    {
      "x": -16,
      "y": 30,
      "z": -9,
      "name": "Plant_Crop_Mushroom_Block_Blue",
      "rotation": 1
    },
    {
      "x": -16,
      "y": 31,
      "z": -9,
      "name": "Plant_Crop_Mushroom_Block_Blue",
      "rotation": 1
    },
    {
      "x": -16,
      "y": 32,
      "z": -9,
      "name": "Plant_Crop_Mushroom_Block_Blue",
      "rotation": 1
    },
    {
      "x": -16,
      "y": 33,
      "z": -9,
      "name": "Plant_Crop_Mushroom_Block_Blue",
      "rotation": 1
    },
    {
      "x": -16,
      "y": 34,
      "z": -9,
      "name": "Plant_Crop_Mushroom_Block_Blue",
      "rotation": 1
    },
    {
      "x": -16,
      "y": 35,
      "z": -9,
      "name": "Plant_Crop_Mushroom_Block_Blue"
    },
    {
      "x": -16,
      "y": 36,
      "z": -9,
      "name": "Plant_Crop_Mushroom_Glowing_Blue"
    },
    {
      "x": -16,
      "y": 28,
      "z": -8,
      "name": "Plant_Crop_Mushroom_Block_Blue"
    },
    {
      "x": -16,
      "y": 29,
      "z": -8,
      "name": "Plant_Crop_Mushroom_Block_Blue",
      "rotation": 1
    },
    {
      "x": -16,
      "y": 30,
      "z": -8,
      "name": "Plant_Crop_Mushroom_Block_Blue",
      "rotation": 1
    },
    {
      "x": -16,
      "y": 31,
      "z": -8,
      "name": "Plant_Crop_Mushroom_Block_Blue",
      "rotation": 1
    },
    {
      "x": -16,
      "y": 32,
      "z": -8,
      "name": "Plant_Crop_Mushroom_Block_Blue",
      "rotation": 1
    },
    {
      "x": -16,
      "y": 33,
      "z": -8,
      "name": "Plant_Crop_Mushroom_Block_Blue",
      "rotation": 1
    },
    {
      "x": -16,
      "y": 34,
      "z": -8,
      "name": "Plant_Crop_Mushroom_Block_Blue",
      "rotation": 1
    },
    {
      "x": -16,
      "y": 35,
      "z": -8,
      "name": "Plant_Crop_Mushroom_Block_Blue"
    },
    {
      "x": -16,
      "y": 36,
      "z": -8,
      "name": "Plant_Crop_Mushroom_Glowing_Blue"
    },
    {
      "x": -16,
      "y": 27,
      "z": -7,
      "name": "Plant_Crop_Mushroom_Block_Blue"
    },
    {
      "x": -16,
      "y": 28,
      "z": -7,
      "name": "Plant_Crop_Mushroom_Block_Blue",
      "rotation": 1
    },
    {
      "x": -16,
      "y": 29,
      "z": -7,
      "name": "Plant_Crop_Mushroom_Block_Blue",
      "rotation": 1
    },
    {
      "x": -16,
      "y": 30,
      "z": -7,
      "name": "Plant_Crop_Mushroom_Block_Blue",
      "rotation": 1
    },
    {
      "x": -16,
      "y": 31,
      "z": -7,
      "name": "Plant_Crop_Mushroom_Block_Blue",
      "rotation": 1
    },
    {
      "x": -16,
      "y": 32,
      "z": -7,
      "name": "Plant_Crop_Mushroom_Block_Blue",
      "rotation": 1
    },
    {
      "x": -16,
      "y": 33,
      "z": -7,
      "name": "Plant_Crop_Mushroom_Block_Blue",
      "rotation": 1
    },
    {
      "x": -16,
      "y": 34,
      "z": -7,
      "name": "Plant_Crop_Mushroom_Block_Blue",
      "rotation": 1
    },
    {
      "x": -16,
      "y": 35,
      "z": -7,
      "name": "Plant_Crop_Mushroom_Block_Blue"
    },
    {
      "x": -16,
      "y": 27,
      "z": -6,
      "name": "Plant_Crop_Mushroom_Block_Blue"
    },
    {
      "x": -16,
      "y": 28,
      "z": -6,
      "name": "Plant_Crop_Mushroom_Block_Blue",
      "rotation": 1
    },
    {
      "x": -16,
      "y": 29,
      "z": -6,
      "name": "Plant_Crop_Mushroom_Block_Blue",
      "rotation": 1
    },
    {
      "x": -16,
      "y": 30,
      "z": -6,
      "name": "Plant_Crop_Mushroom_Block_Blue",
      "rotation": 1
    },
    {
      "x": -16,
      "y": 31,
      "z": -6,
      "name": "Plant_Crop_Mushroom_Block_Blue",
      "rotation": 1
    },
    {
      "x": -16,
      "y": 32,
      "z": -6,
      "name": "Plant_Crop_Mushroom_Block_Blue",
      "rotation": 1
    },
    {
      "x": -16,
      "y": 33,
      "z": -6,
      "name": "Plant_Crop_Mushroom_Block_Blue",
      "rotation": 1
    },
    {
      "x": -16,
      "y": 34,
      "z": -6,
      "name": "Plant_Crop_Mushroom_Block_Blue",
      "rotation": 1
    },
    {
      "x": -16,
      "y": 35,
      "z": -6,
      "name": "Plant_Crop_Mushroom_Block_Blue",
      "rotation": 1
    },
    {
      "x": -16,
      "y": 36,
      "z": -6,
      "name": "Plant_Crop_Mushroom_Block_Blue"
    },
    {
      "x": -16,
      "y": 27,
      "z": -5,
      "name": "Plant_Crop_Mushroom_Block_Blue"
    },
    {
      "x": -16,
      "y": 28,
      "z": -5,
      "name": "Plant_Crop_Mushroom_Block_Blue",
      "rotation": 1
    },
    {
      "x": -16,
      "y": 29,
      "z": -5,
      "name": "Plant_Crop_Mushroom_Block_Blue",
      "rotation": 1
    },
    {
      "x": -16,
      "y": 30,
      "z": -5,
      "name": "Plant_Crop_Mushroom_Block_Blue",
      "rotation": 1
    },
    {
      "x": -16,
      "y": 31,
      "z": -5,
      "name": "Plant_Crop_Mushroom_Block_Blue",
      "rotation": 1
    },
    {
      "x": -16,
      "y": 32,
      "z": -5,
      "name": "Plant_Crop_Mushroom_Block_Blue",
      "rotation": 1
    },
    {
      "x": -16,
      "y": 33,
      "z": -5,
      "name": "Plant_Crop_Mushroom_Block_Blue",
      "rotation": 1
    },
    {
      "x": -16,
      "y": 34,
      "z": -5,
      "name": "Plant_Crop_Mushroom_Block_Blue",
      "rotation": 1
    },
    {
      "x": -16,
      "y": 35,
      "z": -5,
      "name": "Plant_Crop_Mushroom_Block_Blue",
      "rotation": 1
    },
    {
      "x": -16,
      "y": 36,
      "z": -5,
      "name": "Plant_Crop_Mushroom_Block_Blue"
    },
    {
      "x": -16,
      "y": 17,
      "z": -4,
      "name": "Plant_Crop_Mushroom_Block_Blue_Mycelium"
    },
    {
      "x": -16,
      "y": 18,
      "z": -4,
      "name": "Plant_Crop_Mushroom_Block_Blue_Trunk"
    },
    {
      "x": -16,
      "y": 19,
      "z": -4,
      "name": "Plant_Crop_Mushroom_Block_Blue_Branch",
      "support": 15
    },
    {
      "x": -16,
      "y": 20,
      "z": -4,
      "name": "Plant_Crop_Mushroom_Block_Blue_Branch",
      "support": 15
    },
    {
      "x": -16,
      "y": 21,
      "z": -4,
      "name": "Plant_Crop_Mushroom_Block_Blue_Branch",
      "support": 15
    },
    {
      "x": -16,
      "y": 22,
      "z": -4,
      "name": "Plant_Crop_Mushroom_Block_Blue_Branch",
      "support": 15
    },
    {
      "x": -16,
      "y": 23,
      "z": -4,
      "name": "Plant_Crop_Mushroom_Block_Blue_Branch",
      "support": 15
    },
    {
      "x": -16,
      "y": 24,
      "z": -4,
      "name": "Plant_Crop_Mushroom_Block_Blue_Branch",
      "support": 15
    },
    {
      "x": -16,
      "y": 25,
      "z": -4,
      "name": "Plant_Crop_Mushroom_Block_Blue_Branch",
      "support": 15
    },
    {
      "x": -16,
      "y": 26,
      "z": -4,
      "name": "Plant_Crop_Mushroom_Block_Blue_Branch",
      "support": 15
    },
    {
      "x": -16,
      "y": 27,
      "z": -4,
      "name": "Plant_Crop_Mushroom_Block_Blue"
    },
    {
      "x": -16,
      "y": 28,
      "z": -4,
      "name": "Plant_Crop_Mushroom_Block_Blue",
      "rotation": 1
    },
    {
      "x": -16,
      "y": 29,
      "z": -4,
      "name": "Plant_Crop_Mushroom_Block_Blue",
      "rotation": 1
    },
    {
      "x": -16,
      "y": 30,
      "z": -4,
      "name": "Plant_Crop_Mushroom_Block_Blue",
      "rotation": 1
    },
    {
      "x": -16,
      "y": 31,
      "z": -4,
      "name": "Plant_Crop_Mushroom_Block_Blue",
      "rotation": 1
    },
    {
      "x": -16,
      "y": 32,
      "z": -4,
      "name": "Plant_Crop_Mushroom_Block_Blue",
      "rotation": 1
    },
    {
      "x": -16,
      "y": 33,
      "z": -4,
      "name": "Plant_Crop_Mushroom_Block_Blue",
      "rotation": 1
    },
    {
      "x": -16,
      "y": 34,
      "z": -4,
      "name": "Plant_Crop_Mushroom_Block_Blue",
      "rotation": 1
    },
    {
      "x": -16,
      "y": 35,
      "z": -4,
      "name": "Plant_Crop_Mushroom_Block_Blue",
      "rotation": 1
    },
    {
      "x": -16,
      "y": 36,
      "z": -4,
      "name": "Plant_Crop_Mushroom_Block_Blue"
    },
    {
      "x": -16,
      "y": 37,
      "z": -4,
      "name": "Plant_Crop_Mushroom_Glowing_Blue"
    },
    {
      "x": -16,
      "y": 26,
      "z": -3,
      "name": "Plant_Crop_Mushroom_Block_Blue"
    },
    {
      "x": -16,
      "y": 27,
      "z": -3,
      "name": "Plant_Crop_Mushroom_Block_Blue"
    },
    {
      "x": -16,
      "y": 28,
      "z": -3,
      "name": "Plant_Crop_Mushroom_Block_Blue",
      "rotation": 1
    },
    {
      "x": -16,
      "y": 29,
      "z": -3,
      "name": "Plant_Crop_Mushroom_Block_Blue",
      "rotation": 1
    },
    {
      "x": -16,
      "y": 30,
      "z": -3,
      "name": "Plant_Crop_Mushroom_Block_Blue",
      "rotation": 1
    },
    {
      "x": -16,
      "y": 31,
      "z": -3,
      "name": "Plant_Crop_Mushroom_Block_Blue",
      "rotation": 1
    },
    {
      "x": -16,
      "y": 32,
      "z": -3,
      "name": "Plant_Crop_Mushroom_Block_Blue",
      "rotation": 1
    },
    {
      "x": -16,
      "y": 33,
      "z": -3,
      "name": "Plant_Crop_Mushroom_Block_Blue",
      "rotation": 1
    },
    {
      "x": -16,
      "y": 34,
      "z": -3,
      "name": "Plant_Crop_Mushroom_Block_Blue",
      "rotation": 1
    },
    {
      "x": -16,
      "y": 35,
      "z": -3,
      "name": "Plant_Crop_Mushroom_Block_Blue",
      "rotation": 1
    },
    {
      "x": -16,
      "y": 36,
      "z": -3,
      "name": "Plant_Crop_Mushroom_Block_Blue"
    },
    {
      "x": -16,
      "y": 26,
      "z": -2,
      "name": "Plant_Crop_Mushroom_Block_Blue"
    },
    {
      "x": -16,
      "y": 27,
      "z": -2,
      "name": "Plant_Crop_Mushroom_Block_Blue"
    },
    {
      "x": -16,
      "y": 28,
      "z": -2,
      "name": "Plant_Crop_Mushroom_Block_Blue",
      "rotation": 1
    },
    {
      "x": -16,
      "y": 29,
      "z": -2,
      "name": "Plant_Crop_Mushroom_Block_Blue",
      "rotation": 1
    },
    {
      "x": -16,
      "y": 30,
      "z": -2,
      "name": "Plant_Crop_Mushroom_Block_Blue",
      "rotation": 1
    },
    {
      "x": -16,
      "y": 31,
      "z": -2,
      "name": "Plant_Crop_Mushroom_Block_Blue",
      "rotation": 1
    },
    {
      "x": -16,
      "y": 32,
      "z": -2,
      "name": "Plant_Crop_Mushroom_Block_Blue",
      "rotation": 1
    },
    {
      "x": -16,
      "y": 33,
      "z": -2,
      "name": "Plant_Crop_Mushroom_Block_Blue",
      "rotation": 1
    },
    {
      "x": -16,
      "y": 34,
      "z": -2,
      "name": "Plant_Crop_Mushroom_Block_Blue",
      "rotation": 1
    },
    {
      "x": -16,
      "y": 35,
      "z": -2,
      "name": "Plant_Crop_Mushroom_Block_Blue",
      "rotation": 1
    },
    {
      "x": -16,
      "y": 36,
      "z": -2,
      "name": "Plant_Crop_Mushroom_Block_Blue"
    },
    {
      "x": -16,
      "y": 26,
      "z": -1,
      "name": "Plant_Crop_Mushroom_Block_Blue"
    },
    {
      "x": -16,
      "y": 27,
      "z": -1,
      "name": "Plant_Crop_Mushroom_Block_Blue"
    },
    {
      "x": -16,
      "y": 28,
      "z": -1,
      "name": "Plant_Crop_Mushroom_Block_Blue",
      "rotation": 1
    },
    {
      "x": -16,
      "y": 29,
      "z": -1,
      "name": "Plant_Crop_Mushroom_Block_Blue",
      "rotation": 1
    },
    {
      "x": -16,
      "y": 30,
      "z": -1,
      "name": "Plant_Crop_Mushroom_Block_Blue",
      "rotation": 1
    },
    {
      "x": -16,
      "y": 31,
      "z": -1,
      "name": "Plant_Crop_Mushroom_Block_Blue",
      "rotation": 1
    },
    {
      "x": -16,
      "y": 32,
      "z": -1,
      "name": "Plant_Crop_Mushroom_Block_Blue",
      "rotation": 1
    },
    {
      "x": -16,
      "y": 33,
      "z": -1,
      "name": "Plant_Crop_Mushroom_Block_Blue",
      "rotation": 1
    },
    {
      "x": -16,
      "y": 34,
      "z": -1,
      "name": "Plant_Crop_Mushroom_Block_Blue",
      "rotation": 1
    },
    {
      "x": -16,
      "y": 35,
      "z": -1,
      "name": "Plant_Crop_Mushroom_Block_Blue",
      "rotation": 1
    },
    {
      "x": -16,
      "y": 36,
      "z": -1,
      "name": "Plant_Crop_Mushroom_Block_Blue"
    },
    {
      "x": -16,
      "y": 37,
      "z": -1,
      "name": "Plant_Crop_Mushroom_Block_Blue"
    },
    {
      "x": -16,
      "y": 26,
      "z": 0,
      "name": "Plant_Crop_Mushroom_Block_Blue"
    },
    {
      "x": -16,
      "y": 27,
      "z": 0,
      "name": "Plant_Crop_Mushroom_Block_Blue"
    },
    {
      "x": -16,
      "y": 28,
      "z": 0,
      "name": "Plant_Crop_Mushroom_Block_Blue",
      "rotation": 1
    },
    {
      "x": -16,
      "y": 29,
      "z": 0,
      "name": "Plant_Crop_Mushroom_Block_Blue",
      "rotation": 1
    },
    {
      "x": -16,
      "y": 30,
      "z": 0,
      "name": "Plant_Crop_Mushroom_Block_Blue",
      "rotation": 1
    },
    {
      "x": -16,
      "y": 31,
      "z": 0,
      "name": "Plant_Crop_Mushroom_Block_Blue",
      "rotation": 1
    },
    {
      "x": -16,
      "y": 32,
      "z": 0,
      "name": "Plant_Crop_Mushroom_Block_Blue",
      "rotation": 1
    },
    {
      "x": -16,
      "y": 33,
      "z": 0,
      "name": "Plant_Crop_Mushroom_Block_Blue",
      "rotation": 1
    },
    {
      "x": -16,
      "y": 34,
      "z": 0,
      "name": "Plant_Crop_Mushroom_Block_Blue",
      "rotation": 1
    },
    {
      "x": -16,
      "y": 35,
      "z": 0,
      "name": "Plant_Crop_Mushroom_Block_Blue",
      "rotation": 1
    },
    {
      "x": -16,
      "y": 36,
      "z": 0,
      "name": "Plant_Crop_Mushroom_Block_Blue"
    },
    {
      "x": -16,
      "y": 37,
      "z": 0,
      "name": "Plant_Crop_Mushroom_Block_Blue"
    },
    {
      "x": -16,
      "y": 38,
      "z": 0,
      "name": "Plant_Crop_Mushroom_Glowing_Blue"
    },
    {
      "x": -16,
      "y": 26,
      "z": 1,
      "name": "Plant_Crop_Mushroom_Block_Blue"
    },
    {
      "x": -16,
      "y": 27,
      "z": 1,
      "name": "Plant_Crop_Mushroom_Block_Blue"
    },
    {
      "x": -16,
      "y": 28,
      "z": 1,
      "name": "Plant_Crop_Mushroom_Block_Blue",
      "rotation": 1
    },
    {
      "x": -16,
      "y": 29,
      "z": 1,
      "name": "Plant_Crop_Mushroom_Block_Blue",
      "rotation": 1
    },
    {
      "x": -16,
      "y": 30,
      "z": 1,
      "name": "Plant_Crop_Mushroom_Block_Blue",
      "rotation": 1
    },
    {
      "x": -16,
      "y": 31,
      "z": 1,
      "name": "Plant_Crop_Mushroom_Block_Blue",
      "rotation": 1
    },
    {
      "x": -16,
      "y": 32,
      "z": 1,
      "name": "Plant_Crop_Mushroom_Block_Blue",
      "rotation": 1
    },
    {
      "x": -16,
      "y": 33,
      "z": 1,
      "name": "Plant_Crop_Mushroom_Block_Blue",
      "rotation": 1
    },
    {
      "x": -16,
      "y": 34,
      "z": 1,
      "name": "Plant_Crop_Mushroom_Block_Blue",
      "rotation": 1
    },
    {
      "x": -16,
      "y": 35,
      "z": 1,
      "name": "Plant_Crop_Mushroom_Block_Blue",
      "rotation": 1
    },
    {
      "x": -16,
      "y": 36,
      "z": 1,
      "name": "Plant_Crop_Mushroom_Block_Blue"
    },
    {
      "x": -16,
      "y": 37,
      "z": 1,
      "name": "Plant_Crop_Mushroom_Block_Blue"
    },
    {
      "x": -16,
      "y": 38,
      "z": 1,
      "name": "Plant_Crop_Mushroom_Glowing_Blue"
    },
    {
      "x": -16,
      "y": 16,
      "z": 2,
      "name": "Plant_Crop_Mushroom_Block_Blue_Mycelium"
    },
    {
      "x": -16,
      "y": 17,
      "z": 2,
      "name": "Plant_Crop_Mushroom_Block_Blue_Trunk"
    },
    {
      "x": -16,
      "y": 18,
      "z": 2,
      "name": "Plant_Crop_Mushroom_Block_Blue_Branch",
      "support": 15
    },
    {
      "x": -16,
      "y": 19,
      "z": 2,
      "name": "Plant_Crop_Mushroom_Block_Blue_Branch",
      "support": 15
    },
    {
      "x": -16,
      "y": 20,
      "z": 2,
      "name": "Plant_Crop_Mushroom_Block_Blue_Branch",
      "support": 15
    },
    {
      "x": -16,
      "y": 21,
      "z": 2,
      "name": "Plant_Crop_Mushroom_Block_Blue_Branch",
      "support": 15
    },
    {
      "x": -16,
      "y": 22,
      "z": 2,
      "name": "Plant_Crop_Mushroom_Block_Blue_Branch",
      "support": 15
    },
    {
      "x": -16,
      "y": 23,
      "z": 2,
      "name": "Plant_Crop_Mushroom_Block_Blue_Branch",
      "support": 15
    },
    {
      "x": -16,
      "y": 24,
      "z": 2,
      "name": "Plant_Crop_Mushroom_Block_Blue_Branch",
      "support": 15
    },
    {
      "x": -16,
      "y": 25,
      "z": 2,
      "name": "Plant_Crop_Mushroom_Block_Blue_Branch",
      "support": 15
    },
    {
      "x": -16,
      "y": 26,
      "z": 2,
      "name": "Plant_Crop_Mushroom_Block_Blue_Branch",
      "support": 15
    },
    {
      "x": -16,
      "y": 27,
      "z": 2,
      "name": "Plant_Crop_Mushroom_Block_Blue"
    },
    {
      "x": -16,
      "y": 28,
      "z": 2,
      "name": "Plant_Crop_Mushroom_Block_Blue",
      "rotation": 1
    },
    {
      "x": -16,
      "y": 29,
      "z": 2,
      "name": "Plant_Crop_Mushroom_Block_Blue",
      "rotation": 1
    },
    {
      "x": -16,
      "y": 30,
      "z": 2,
      "name": "Plant_Crop_Mushroom_Block_Blue",
      "rotation": 1
    },
    {
      "x": -16,
      "y": 31,
      "z": 2,
      "name": "Plant_Crop_Mushroom_Block_Blue",
      "rotation": 1
    },
    {
      "x": -16,
      "y": 32,
      "z": 2,
      "name": "Plant_Crop_Mushroom_Block_Blue",
      "rotation": 1
    },
    {
      "x": -16,
      "y": 33,
      "z": 2,
      "name": "Plant_Crop_Mushroom_Block_Blue",
      "rotation": 1
    },
    {
      "x": -16,
      "y": 34,
      "z": 2,
      "name": "Plant_Crop_Mushroom_Block_Blue",
      "rotation": 1
    },
    {
      "x": -16,
      "y": 35,
      "z": 2,
      "name": "Plant_Crop_Mushroom_Block_Blue",
      "rotation": 1
    },
    {
      "x": -16,
      "y": 36,
      "z": 2,
      "name": "Plant_Crop_Mushroom_Block_Blue"
    },
    {
      "x": -16,
      "y": 37,
      "z": 2,
      "name": "Plant_Crop_Mushroom_Block_Blue"
    },
    {
      "x": -16,
      "y": 27,
      "z": 3,
      "name": "Plant_Crop_Mushroom_Block_Blue"
    },
    {
      "x": -16,
      "y": 28,
      "z": 3,
      "name": "Plant_Crop_Mushroom_Block_Blue",
      "rotation": 1
    },
    {
      "x": -16,
      "y": 29,
      "z": 3,
      "name": "Plant_Crop_Mushroom_Block_Blue",
      "rotation": 1
    },
    {
      "x": -16,
      "y": 30,
      "z": 3,
      "name": "Plant_Crop_Mushroom_Block_Blue",
      "rotation": 1
    },
    {
      "x": -16,
      "y": 31,
      "z": 3,
      "name": "Plant_Crop_Mushroom_Block_Blue",
      "rotation": 1
    },
    {
      "x": -16,
      "y": 32,
      "z": 3,
      "name": "Plant_Crop_Mushroom_Block_Blue",
      "rotation": 1
    },
    {
      "x": -16,
      "y": 33,
      "z": 3,
      "name": "Plant_Crop_Mushroom_Block_Blue",
      "rotation": 1
    },
    {
      "x": -16,
      "y": 34,
      "z": 3,
      "name": "Plant_Crop_Mushroom_Block_Blue",
      "rotation": 1
    },
    {
      "x": -16,
      "y": 35,
      "z": 3,
      "name": "Plant_Crop_Mushroom_Block_Blue",
      "rotation": 1
    },
    {
      "x": -16,
      "y": 36,
      "z": 3,
      "name": "Plant_Crop_Mushroom_Block_Blue"
    },
    {
      "x": -16,
      "y": 37,
      "z": 3,
      "name": "Plant_Crop_Mushroom_Glowing_Blue"
    },
    {
      "x": -16,
      "y": 27,
      "z": 4,
      "name": "Plant_Crop_Mushroom_Block_Blue"
    },
    {
      "x": -16,
      "y": 28,
      "z": 4,
      "name": "Plant_Crop_Mushroom_Block_Blue",
      "rotation": 1
    },
    {
      "x": -16,
      "y": 29,
      "z": 4,
      "name": "Plant_Crop_Mushroom_Block_Blue",
      "rotation": 1
    },
    {
      "x": -16,
      "y": 30,
      "z": 4,
      "name": "Plant_Crop_Mushroom_Block_Blue",
      "rotation": 1
    },
    {
      "x": -16,
      "y": 31,
      "z": 4,
      "name": "Plant_Crop_Mushroom_Block_Blue",
      "rotation": 1
    },
    {
      "x": -16,
      "y": 32,
      "z": 4,
      "name": "Plant_Crop_Mushroom_Block_Blue",
      "rotation": 1
    },
    {
      "x": -16,
      "y": 33,
      "z": 4,
      "name": "Plant_Crop_Mushroom_Block_Blue",
      "rotation": 1
    },
    {
      "x": -16,
      "y": 34,
      "z": 4,
      "name": "Plant_Crop_Mushroom_Block_Blue",
      "rotation": 1
    },
    {
      "x": -16,
      "y": 35,
      "z": 4,
      "name": "Plant_Crop_Mushroom_Block_Blue",
      "rotation": 1
    },
    {
      "x": -16,
      "y": 36,
      "z": 4,
      "name": "Plant_Crop_Mushroom_Block_Blue"
    },
    {
      "x": -16,
      "y": 17,
      "z": 5,
      "name": "Plant_Crop_Mushroom_Block_Blue_Mycelium"
    },
    {
      "x": -16,
      "y": 18,
      "z": 5,
      "name": "Plant_Crop_Mushroom_Block_Blue_Trunk"
    },
    {
      "x": -16,
      "y": 19,
      "z": 5,
      "name": "Plant_Crop_Mushroom_Block_Blue_Branch",
      "support": 15
    },
    {
      "x": -16,
      "y": 20,
      "z": 5,
      "name": "Plant_Crop_Mushroom_Block_Blue_Branch",
      "support": 15
    },
    {
      "x": -16,
      "y": 21,
      "z": 5,
      "name": "Plant_Crop_Mushroom_Block_Blue_Branch",
      "support": 15
    },
    {
      "x": -16,
      "y": 22,
      "z": 5,
      "name": "Plant_Crop_Mushroom_Block_Blue_Branch",
      "support": 15
    },
    {
      "x": -16,
      "y": 23,
      "z": 5,
      "name": "Plant_Crop_Mushroom_Block_Blue_Branch",
      "support": 15
    },
    {
      "x": -16,
      "y": 24,
      "z": 5,
      "name": "Plant_Crop_Mushroom_Block_Blue_Branch",
      "support": 15
    },
    {
      "x": -16,
      "y": 25,
      "z": 5,
      "name": "Plant_Crop_Mushroom_Block_Blue_Branch",
      "support": 15
    },
    {
      "x": -16,
      "y": 26,
      "z": 5,
      "name": "Plant_Crop_Mushroom_Block_Blue_Branch",
      "support": 15
    },
    {
      "x": -16,
      "y": 27,
      "z": 5,
      "name": "Plant_Crop_Mushroom_Block_Blue"
    },
    {
      "x": -16,
      "y": 28,
      "z": 5,
      "name": "Plant_Crop_Mushroom_Block_Blue",
      "rotation": 1
    },
    {
      "x": -16,
      "y": 29,
      "z": 5,
      "name": "Plant_Crop_Mushroom_Block_Blue",
      "rotation": 1
    },
    {
      "x": -16,
      "y": 30,
      "z": 5,
      "name": "Plant_Crop_Mushroom_Block_Blue",
      "rotation": 1
    },
    {
      "x": -16,
      "y": 31,
      "z": 5,
      "name": "Plant_Crop_Mushroom_Block_Blue",
      "rotation": 1
    },
    {
      "x": -16,
      "y": 32,
      "z": 5,
      "name": "Plant_Crop_Mushroom_Block_Blue",
      "rotation": 1
    },
    {
      "x": -16,
      "y": 33,
      "z": 5,
      "name": "Plant_Crop_Mushroom_Block_Blue",
      "rotation": 1
    },
    {
      "x": -16,
      "y": 34,
      "z": 5,
      "name": "Plant_Crop_Mushroom_Block_Blue",
      "rotation": 1
    },
    {
      "x": -16,
      "y": 35,
      "z": 5,
      "name": "Plant_Crop_Mushroom_Block_Blue",
      "rotation": 1
    },
    {
      "x": -16,
      "y": 36,
      "z": 5,
      "name": "Plant_Crop_Mushroom_Block_Blue"
    },
    {
      "x": -16,
      "y": 27,
      "z": 6,
      "name": "Plant_Crop_Mushroom_Block_Blue"
    },
    {
      "x": -16,
      "y": 28,
      "z": 6,
      "name": "Plant_Crop_Mushroom_Block_Blue",
      "rotation": 1
    },
    {
      "x": -16,
      "y": 29,
      "z": 6,
      "name": "Plant_Crop_Mushroom_Block_Blue",
      "rotation": 1
    },
    {
      "x": -16,
      "y": 30,
      "z": 6,
      "name": "Plant_Crop_Mushroom_Block_Blue",
      "rotation": 1
    },
    {
      "x": -16,
      "y": 31,
      "z": 6,
      "name": "Plant_Crop_Mushroom_Block_Blue",
      "rotation": 1
    },
    {
      "x": -16,
      "y": 32,
      "z": 6,
      "name": "Plant_Crop_Mushroom_Block_Blue",
      "rotation": 1
    },
    {
      "x": -16,
      "y": 33,
      "z": 6,
      "name": "Plant_Crop_Mushroom_Block_Blue",
      "rotation": 1
    },
    {
      "x": -16,
      "y": 34,
      "z": 6,
      "name": "Plant_Crop_Mushroom_Block_Blue",
      "rotation": 1
    },
    {
      "x": -16,
      "y": 35,
      "z": 6,
      "name": "Plant_Crop_Mushroom_Block_Blue",
      "rotation": 1
    },
    {
      "x": -16,
      "y": 36,
      "z": 6,
      "name": "Plant_Crop_Mushroom_Block_Blue"
    },
    {
      "x": -16,
      "y": 37,
      "z": 6,
      "name": "Plant_Crop_Mushroom_Glowing_Blue"
    },
    {
      "x": -16,
      "y": 27,
      "z": 7,
      "name": "Plant_Crop_Mushroom_Block_Blue"
    },
    {
      "x": -16,
      "y": 28,
      "z": 7,
      "name": "Plant_Crop_Mushroom_Block_Blue",
      "rotation": 1
    },
    {
      "x": -16,
      "y": 29,
      "z": 7,
      "name": "Plant_Crop_Mushroom_Block_Blue",
      "rotation": 1
    },
    {
      "x": -16,
      "y": 30,
      "z": 7,
      "name": "Plant_Crop_Mushroom_Block_Blue",
      "rotation": 1
    },
    {
      "x": -16,
      "y": 31,
      "z": 7,
      "name": "Plant_Crop_Mushroom_Block_Blue",
      "rotation": 1
    },
    {
      "x": -16,
      "y": 32,
      "z": 7,
      "name": "Plant_Crop_Mushroom_Block_Blue",
      "rotation": 1
    },
    {
      "x": -16,
      "y": 33,
      "z": 7,
      "name": "Plant_Crop_Mushroom_Block_Blue",
      "rotation": 1
    },
    {
      "x": -16,
      "y": 34,
      "z": 7,
      "name": "Plant_Crop_Mushroom_Block_Blue",
      "rotation": 1
    },
    {
      "x": -16,
      "y": 35,
      "z": 7,
      "name": "Plant_Crop_Mushroom_Block_Blue",
      "rotation": 1
    },
    {
      "x": -16,
      "y": 36,
      "z": 7,
      "name": "Plant_Crop_Mushroom_Block_Blue"
    },
    {
      "x": -16,
      "y": 27,
      "z": 8,
      "name": "Plant_Crop_Mushroom_Block_Blue"
    },
    {
      "x": -16,
      "y": 28,
      "z": 8,
      "name": "Plant_Crop_Mushroom_Block_Blue"
    },
    {
      "x": -16,
      "y": 29,
      "z": 8,
      "name": "Plant_Crop_Mushroom_Block_Blue",
      "rotation": 1
    },
    {
      "x": -16,
      "y": 30,
      "z": 8,
      "name": "Plant_Crop_Mushroom_Block_Blue",
      "rotation": 1
    },
    {
      "x": -16,
      "y": 31,
      "z": 8,
      "name": "Plant_Crop_Mushroom_Block_Blue",
      "rotation": 1
    },
    {
      "x": -16,
      "y": 32,
      "z": 8,
      "name": "Plant_Crop_Mushroom_Block_Blue",
      "rotation": 1
    },
    {
      "x": -16,
      "y": 33,
      "z": 8,
      "name": "Plant_Crop_Mushroom_Block_Blue",
      "rotation": 1
    },
    {
      "x": -16,
      "y": 34,
      "z": 8,
      "name": "Plant_Crop_Mushroom_Block_Blue",
      "rotation": 1
    },
    {
      "x": -16,
      "y": 35,
      "z": 8,
      "name": "Plant_Crop_Mushroom_Block_Blue",
      "rotation": 1
    },
    {
      "x": -16,
      "y": 36,
      "z": 8,
      "name": "Plant_Crop_Mushroom_Block_Blue"
    },
    {
      "x": -16,
      "y": 37,
      "z": 8,
      "name": "Plant_Crop_Mushroom_Glowing_Blue"
    },
    {
      "x": -16,
      "y": 28,
      "z": 9,
      "name": "Plant_Crop_Mushroom_Block_Blue"
    },
    {
      "x": -16,
      "y": 29,
      "z": 9,
      "name": "Plant_Crop_Mushroom_Block_Blue",
      "rotation": 1
    },
    {
      "x": -16,
      "y": 30,
      "z": 9,
      "name": "Plant_Crop_Mushroom_Block_Blue",
      "rotation": 1
    },
    {
      "x": -16,
      "y": 31,
      "z": 9,
      "name": "Plant_Crop_Mushroom_Block_Blue",
      "rotation": 1
    },
    {
      "x": -16,
      "y": 32,
      "z": 9,
      "name": "Plant_Crop_Mushroom_Block_Blue",
      "rotation": 1
    },
    {
      "x": -16,
      "y": 33,
      "z": 9,
      "name": "Plant_Crop_Mushroom_Block_Blue",
      "rotation": 1
    },
    {
      "x": -16,
      "y": 34,
      "z": 9,
      "name": "Plant_Crop_Mushroom_Block_Blue",
      "rotation": 1
    },
    {
      "x": -16,
      "y": 35,
      "z": 9,
      "name": "Plant_Crop_Mushroom_Block_Blue"
    },
    {
      "x": -16,
      "y": 28,
      "z": 10,
      "name": "Plant_Crop_Mushroom_Block_Blue"
    },
    {
      "x": -16,
      "y": 29,
      "z": 10,
      "name": "Plant_Crop_Mushroom_Block_Blue"
    },
    {
      "x": -16,
      "y": 30,
      "z": 10,
      "name": "Plant_Crop_Mushroom_Block_Blue",
      "rotation": 1
    },
    {
      "x": -16,
      "y": 31,
      "z": 10,
      "name": "Plant_Crop_Mushroom_Block_Blue",
      "rotation": 1
    },
    {
      "x": -16,
      "y": 32,
      "z": 10,
      "name": "Plant_Crop_Mushroom_Block_Blue",
      "rotation": 1
    },
    {
      "x": -16,
      "y": 33,
      "z": 10,
      "name": "Plant_Crop_Mushroom_Block_Blue",
      "rotation": 1
    },
    {
      "x": -16,
      "y": 34,
      "z": 10,
      "name": "Plant_Crop_Mushroom_Block_Blue",
      "rotation": 1
    },
    {
      "x": -16,
      "y": 35,
      "z": 10,
      "name": "Plant_Crop_Mushroom_Block_Blue"
    },
    {
      "x": -16,
      "y": 17,
      "z": 11,
      "name": "Plant_Crop_Mushroom_Block_Blue_Mycelium"
    },
    {
      "x": -16,
      "y": 18,
      "z": 11,
      "name": "Plant_Crop_Mushroom_Block_Blue_Trunk"
    },
    {
      "x": -16,
      "y": 19,
      "z": 11,
      "name": "Plant_Crop_Mushroom_Block_Blue_Branch",
      "support": 15
    },
    {
      "x": -16,
      "y": 20,
      "z": 11,
      "name": "Plant_Crop_Mushroom_Block_Blue_Branch",
      "support": 15
    },
    {
      "x": -16,
      "y": 21,
      "z": 11,
      "name": "Plant_Crop_Mushroom_Block_Blue_Branch",
      "support": 15
    },
    {
      "x": -16,
      "y": 22,
      "z": 11,
      "name": "Plant_Crop_Mushroom_Block_Blue_Branch",
      "support": 15
    },
    {
      "x": -16,
      "y": 23,
      "z": 11,
      "name": "Plant_Crop_Mushroom_Block_Blue_Branch",
      "support": 15
    },
    {
      "x": -16,
      "y": 24,
      "z": 11,
      "name": "Plant_Crop_Mushroom_Block_Blue_Branch",
      "support": 15
    },
    {
      "x": -16,
      "y": 25,
      "z": 11,
      "name": "Plant_Crop_Mushroom_Block_Blue_Branch",
      "support": 15
    },
    {
      "x": -16,
      "y": 26,
      "z": 11,
      "name": "Plant_Crop_Mushroom_Block_Blue_Branch",
      "support": 15
    },
    {
      "x": -16,
      "y": 27,
      "z": 11,
      "name": "Plant_Crop_Mushroom_Block_Blue_Branch",
      "support": 15
    },
    {
      "x": -16,
      "y": 28,
      "z": 11,
      "name": "Plant_Crop_Mushroom_Block_Blue"
    },
    {
      "x": -16,
      "y": 29,
      "z": 11,
      "name": "Plant_Crop_Mushroom_Block_Blue"
    },
    {
      "x": -16,
      "y": 30,
      "z": 11,
      "name": "Plant_Crop_Mushroom_Block_Blue",
      "rotation": 1
    },
    {
      "x": -16,
      "y": 31,
      "z": 11,
      "name": "Plant_Crop_Mushroom_Block_Blue",
      "rotation": 1
    },
    {
      "x": -16,
      "y": 32,
      "z": 11,
      "name": "Plant_Crop_Mushroom_Block_Blue",
      "rotation": 1
    },
    {
      "x": -16,
      "y": 33,
      "z": 11,
      "name": "Plant_Crop_Mushroom_Block_Blue",
      "rotation": 1
    },
    {
      "x": -16,
      "y": 34,
      "z": 11,
      "name": "Plant_Crop_Mushroom_Block_Blue",
      "rotation": 1
    },
    {
      "x": -16,
      "y": 35,
      "z": 11,
      "name": "Plant_Crop_Mushroom_Block_Blue"
    },
    {
      "x": -16,
      "y": 29,
      "z": 12,
      "name": "Plant_Crop_Mushroom_Block_Blue"
    },
    {
      "x": -16,
      "y": 30,
      "z": 12,
      "name": "Plant_Crop_Mushroom_Block_Blue",
      "rotation": 1
    },
    {
      "x": -16,
      "y": 31,
      "z": 12,
      "name": "Plant_Crop_Mushroom_Block_Blue",
      "rotation": 1
    },
    {
      "x": -16,
      "y": 32,
      "z": 12,
      "name": "Plant_Crop_Mushroom_Block_Blue",
      "rotation": 1
    },
    {
      "x": -16,
      "y": 33,
      "z": 12,
      "name": "Plant_Crop_Mushroom_Block_Blue",
      "rotation": 1
    },
    {
      "x": -16,
      "y": 34,
      "z": 12,
      "name": "Plant_Crop_Mushroom_Glowing_Blue"
    },
    {
      "x": -15,
      "y": 30,
      "z": -13,
      "name": "Plant_Crop_Mushroom_Block_Blue"
    },
    {
      "x": -15,
      "y": 31,
      "z": -13,
      "name": "Plant_Crop_Mushroom_Block_Blue",
      "rotation": 1
    },
    {
      "x": -15,
      "y": 32,
      "z": -13,
      "name": "Plant_Crop_Mushroom_Glowing_Blue"
    },
    {
      "x": -15,
      "y": 29,
      "z": -12,
      "name": "Plant_Crop_Mushroom_Block_Blue",
      "rotation": 1
    },
    {
      "x": -15,
      "y": 30,
      "z": -12,
      "name": "Plant_Crop_Mushroom_Block_Blue",
      "rotation": 1
    },
    {
      "x": -15,
      "y": 31,
      "z": -12,
      "name": "Plant_Crop_Mushroom_Block_Blue",
      "rotation": 1
    },
    {
      "x": -15,
      "y": 32,
      "z": -12,
      "name": "Plant_Crop_Mushroom_Block_Blue",
      "rotation": 1
    },
    {
      "x": -15,
      "y": 33,
      "z": -12,
      "name": "Plant_Crop_Mushroom_Block_Blue",
      "rotation": 1
    },
    {
      "x": -15,
      "y": 34,
      "z": -12,
      "name": "Plant_Crop_Mushroom_Block_Blue",
      "rotation": 1
    },
    {
      "x": -15,
      "y": 35,
      "z": -12,
      "name": "Plant_Crop_Mushroom_Block_Blue"
    },
    {
      "x": -15,
      "y": 23,
      "z": -11,
      "name": "Plant_Crop_Mushroom_Block_Blue_Mycelium"
    },
    {
      "x": -15,
      "y": 24,
      "z": -11,
      "name": "Plant_Crop_Mushroom_Block_Blue_Trunk"
    },
    {
      "x": -15,
      "y": 25,
      "z": -11,
      "name": "Plant_Crop_Mushroom_Block_Blue_Branch",
      "support": 15
    },
    {
      "x": -15,
      "y": 26,
      "z": -11,
      "name": "Plant_Crop_Mushroom_Block_Blue_Branch",
      "support": 15
    },
    {
      "x": -15,
      "y": 27,
      "z": -11,
      "name": "Plant_Crop_Mushroom_Block_Blue_Branch",
      "support": 15
    },
    {
      "x": -15,
      "y": 28,
      "z": -11,
      "name": "Plant_Crop_Mushroom_Block_Blue"
    },
    {
      "x": -15,
      "y": 29,
      "z": -11,
      "name": "Plant_Crop_Mushroom_Block_Blue",
      "rotation": 1
    },
    {
      "x": -15,
      "y": 30,
      "z": -11,
      "name": "Plant_Crop_Mushroom_Block_Blue",
      "rotation": 1
    },
    {
      "x": -15,
      "y": 31,
      "z": -11,
      "name": "Plant_Crop_Mushroom_Block_Blue",
      "rotation": 1
    },
    {
      "x": -15,
      "y": 32,
      "z": -11,
      "name": "Plant_Crop_Mushroom_Block_Blue",
      "rotation": 1
    },
    {
      "x": -15,
      "y": 33,
      "z": -11,
      "name": "Plant_Crop_Mushroom_Block_Blue",
      "rotation": 1
    },
    {
      "x": -15,
      "y": 34,
      "z": -11,
      "name": "Plant_Crop_Mushroom_Block_Blue",
      "rotation": 1
    },
    {
      "x": -15,
      "y": 35,
      "z": -11,
      "name": "Plant_Crop_Mushroom_Block_Blue",
      "rotation": 1
    },
    {
      "x": -15,
      "y": 36,
      "z": -11,
      "name": "Plant_Crop_Mushroom_Block_Blue"
    },
    {
      "x": -15,
      "y": 27,
      "z": -10,
      "name": "Plant_Crop_Mushroom_Block_Blue"
    },
    {
      "x": -15,
      "y": 28,
      "z": -10,
      "name": "Plant_Crop_Mushroom_Block_Blue"
    },
    {
      "x": -15,
      "y": 29,
      "z": -10,
      "name": "Plant_Crop_Mushroom_Block_Blue",
      "rotation": 1
    },
    {
      "x": -15,
      "y": 30,
      "z": -10,
      "name": "Plant_Crop_Mushroom_Block_Blue",
      "rotation": 1
    },
    {
      "x": -15,
      "y": 31,
      "z": -10,
      "name": "Plant_Crop_Mushroom_Block_Blue",
      "rotation": 1
    },
    {
      "x": -15,
      "y": 32,
      "z": -10,
      "name": "Plant_Crop_Mushroom_Block_Blue",
      "rotation": 1
    },
    {
      "x": -15,
      "y": 33,
      "z": -10,
      "name": "Plant_Crop_Mushroom_Block_Blue",
      "rotation": 1
    },
    {
      "x": -15,
      "y": 34,
      "z": -10,
      "name": "Plant_Crop_Mushroom_Block_Blue",
      "rotation": 1
    },
    {
      "x": -15,
      "y": 35,
      "z": -10,
      "name": "Plant_Crop_Mushroom_Block_Blue",
      "rotation": 1
    },
    {
      "x": -15,
      "y": 36,
      "z": -10,
      "name": "Plant_Crop_Mushroom_Block_Blue"
    },
    {
      "x": -15,
      "y": 27,
      "z": -9,
      "name": "Plant_Crop_Mushroom_Block_Blue"
    },
    {
      "x": -15,
      "y": 28,
      "z": -9,
      "name": "Plant_Crop_Mushroom_Block_Blue"
    },
    {
      "x": -15,
      "y": 29,
      "z": -9,
      "name": "Plant_Crop_Mushroom_Block_Blue",
      "rotation": 1
    },
    {
      "x": -15,
      "y": 30,
      "z": -9,
      "name": "Plant_Crop_Mushroom_Block_Blue",
      "rotation": 1
    },
    {
      "x": -15,
      "y": 31,
      "z": -9,
      "name": "Plant_Crop_Mushroom_Block_Blue",
      "rotation": 1
    },
    {
      "x": -15,
      "y": 32,
      "z": -9,
      "name": "Plant_Crop_Mushroom_Block_Blue",
      "rotation": 1
    },
    {
      "x": -15,
      "y": 33,
      "z": -9,
      "name": "Plant_Crop_Mushroom_Block_Blue",
      "rotation": 1
    },
    {
      "x": -15,
      "y": 34,
      "z": -9,
      "name": "Plant_Crop_Mushroom_Block_Blue",
      "rotation": 1
    },
    {
      "x": -15,
      "y": 35,
      "z": -9,
      "name": "Plant_Crop_Mushroom_Block_Blue",
      "rotation": 1
    },
    {
      "x": -15,
      "y": 36,
      "z": -9,
      "name": "Plant_Crop_Mushroom_Block_Blue"
    },
    {
      "x": -15,
      "y": 26,
      "z": -8,
      "name": "Plant_Crop_Mushroom_Block_Blue"
    },
    {
      "x": -15,
      "y": 27,
      "z": -8,
      "name": "Plant_Crop_Mushroom_Block_Blue",
      "rotation": 1
    },
    {
      "x": -15,
      "y": 28,
      "z": -8,
      "name": "Plant_Crop_Mushroom_Block_Blue",
      "rotation": 1
    },
    {
      "x": -15,
      "y": 29,
      "z": -8,
      "name": "Plant_Crop_Mushroom_Block_Blue",
      "rotation": 1
    },
    {
      "x": -15,
      "y": 30,
      "z": -8,
      "name": "Plant_Crop_Mushroom_Block_Blue",
      "rotation": 1
    },
    {
      "x": -15,
      "y": 31,
      "z": -8,
      "name": "Plant_Crop_Mushroom_Block_Blue",
      "rotation": 1
    },
    {
      "x": -15,
      "y": 32,
      "z": -8,
      "name": "Plant_Crop_Mushroom_Block_Blue",
      "rotation": 1
    },
    {
      "x": -15,
      "y": 33,
      "z": -8,
      "name": "Plant_Crop_Mushroom_Block_Blue",
      "rotation": 1
    },
    {
      "x": -15,
      "y": 34,
      "z": -8,
      "name": "Plant_Crop_Mushroom_Block_Blue",
      "rotation": 1
    },
    {
      "x": -15,
      "y": 35,
      "z": -8,
      "name": "Plant_Crop_Mushroom_Block_Blue",
      "rotation": 1
    },
    {
      "x": -15,
      "y": 36,
      "z": -8,
      "name": "Plant_Crop_Mushroom_Block_Blue"
    },
    {
      "x": -15,
      "y": 26,
      "z": -7,
      "name": "Plant_Crop_Mushroom_Block_Blue"
    },
    {
      "x": -15,
      "y": 27,
      "z": -7,
      "name": "Plant_Crop_Mushroom_Block_Blue",
      "rotation": 1
    },
    {
      "x": -15,
      "y": 28,
      "z": -7,
      "name": "Plant_Crop_Mushroom_Block_Blue",
      "rotation": 1
    },
    {
      "x": -15,
      "y": 29,
      "z": -7,
      "name": "Plant_Crop_Mushroom_Block_Blue",
      "rotation": 1
    },
    {
      "x": -15,
      "y": 30,
      "z": -7,
      "name": "Plant_Crop_Mushroom_Block_Blue",
      "rotation": 1
    },
    {
      "x": -15,
      "y": 31,
      "z": -7,
      "name": "Plant_Crop_Mushroom_Block_Blue",
      "rotation": 1
    },
    {
      "x": -15,
      "y": 32,
      "z": -7,
      "name": "Plant_Crop_Mushroom_Block_Blue",
      "rotation": 1
    },
    {
      "x": -15,
      "y": 33,
      "z": -7,
      "name": "Plant_Crop_Mushroom_Block_Blue",
      "rotation": 1
    },
    {
      "x": -15,
      "y": 34,
      "z": -7,
      "name": "Plant_Crop_Mushroom_Block_Blue",
      "rotation": 1
    },
    {
      "x": -15,
      "y": 35,
      "z": -7,
      "name": "Plant_Crop_Mushroom_Block_Blue",
      "rotation": 1
    },
    {
      "x": -15,
      "y": 36,
      "z": -7,
      "name": "Plant_Crop_Mushroom_Block_Blue"
    },
    {
      "x": -15,
      "y": 26,
      "z": -6,
      "name": "Plant_Crop_Mushroom_Block_Blue"
    },
    {
      "x": -15,
      "y": 27,
      "z": -6,
      "name": "Plant_Crop_Mushroom_Block_Blue",
      "rotation": 1
    },
    {
      "x": -15,
      "y": 28,
      "z": -6,
      "name": "Plant_Crop_Mushroom_Block_Blue",
      "rotation": 1
    },
    {
      "x": -15,
      "y": 29,
      "z": -6,
      "name": "Plant_Crop_Mushroom_Block_Blue",
      "rotation": 1
    },
    {
      "x": -15,
      "y": 30,
      "z": -6,
      "name": "Plant_Crop_Mushroom_Block_Blue",
      "rotation": 1
    },
    {
      "x": -15,
      "y": 31,
      "z": -6,
      "name": "Plant_Crop_Mushroom_Block_Blue",
      "rotation": 1
    },
    {
      "x": -15,
      "y": 32,
      "z": -6,
      "name": "Plant_Crop_Mushroom_Block_Blue",
      "rotation": 1
    },
    {
      "x": -15,
      "y": 33,
      "z": -6,
      "name": "Plant_Crop_Mushroom_Block_Blue",
      "rotation": 1
    },
    {
      "x": -15,
      "y": 34,
      "z": -6,
      "name": "Plant_Crop_Mushroom_Block_Blue",
      "rotation": 1
    },
    {
      "x": -15,
      "y": 35,
      "z": -6,
      "name": "Plant_Crop_Mushroom_Block_Blue",
      "rotation": 1
    },
    {
      "x": -15,
      "y": 36,
      "z": -6,
      "name": "Plant_Crop_Mushroom_Block_Blue",
      "rotation": 1
    },
    {
      "x": -15,
      "y": 37,
      "z": -6,
      "name": "Plant_Crop_Mushroom_Block_Blue"
    },
    {
      "x": -15,
      "y": 26,
      "z": -5,
      "name": "Plant_Crop_Mushroom_Block_Blue"
    },
    {
      "x": -15,
      "y": 27,
      "z": -5,
      "name": "Plant_Crop_Mushroom_Block_Blue",
      "rotation": 1
    },
    {
      "x": -15,
      "y": 28,
      "z": -5,
      "name": "Plant_Crop_Mushroom_Block_Blue",
      "rotation": 1
    },
    {
      "x": -15,
      "y": 29,
      "z": -5,
      "name": "Plant_Crop_Mushroom_Block_Blue",
      "rotation": 1
    },
    {
      "x": -15,
      "y": 30,
      "z": -5,
      "name": "Plant_Crop_Mushroom_Block_Blue",
      "rotation": 1
    },
    {
      "x": -15,
      "y": 31,
      "z": -5,
      "name": "Plant_Crop_Mushroom_Block_Blue",
      "rotation": 1
    },
    {
      "x": -15,
      "y": 32,
      "z": -5,
      "name": "Plant_Crop_Mushroom_Block_Blue",
      "rotation": 1
    },
    {
      "x": -15,
      "y": 33,
      "z": -5,
      "name": "Plant_Crop_Mushroom_Block_Blue",
      "rotation": 1
    },
    {
      "x": -15,
      "y": 34,
      "z": -5,
      "name": "Plant_Crop_Mushroom_Block_Blue",
      "rotation": 1
    },
    {
      "x": -15,
      "y": 35,
      "z": -5,
      "name": "Plant_Crop_Mushroom_Block_Blue",
      "rotation": 1
    },
    {
      "x": -15,
      "y": 36,
      "z": -5,
      "name": "Plant_Crop_Mushroom_Block_Blue",
      "rotation": 1
    },
    {
      "x": -15,
      "y": 37,
      "z": -5,
      "name": "Plant_Crop_Mushroom_Block_Blue"
    },
    {
      "x": -15,
      "y": 26,
      "z": -4,
      "name": "Plant_Crop_Mushroom_Block_Blue"
    },
    {
      "x": -15,
      "y": 27,
      "z": -4,
      "name": "Plant_Crop_Mushroom_Block_Blue",
      "rotation": 1
    },
    {
      "x": -15,
      "y": 28,
      "z": -4,
      "name": "Plant_Crop_Mushroom_Block_Blue",
      "rotation": 1
    },
    {
      "x": -15,
      "y": 29,
      "z": -4,
      "name": "Plant_Crop_Mushroom_Block_Blue",
      "rotation": 1
    },
    {
      "x": -15,
      "y": 30,
      "z": -4,
      "name": "Plant_Crop_Mushroom_Block_Blue",
      "rotation": 1
    },
    {
      "x": -15,
      "y": 31,
      "z": -4,
      "name": "Plant_Crop_Mushroom_Block_Blue",
      "rotation": 1
    },
    {
      "x": -15,
      "y": 32,
      "z": -4,
      "name": "Plant_Crop_Mushroom_Block_Blue",
      "rotation": 1
    },
    {
      "x": -15,
      "y": 33,
      "z": -4,
      "name": "Plant_Crop_Mushroom_Block_Blue",
      "rotation": 1
    },
    {
      "x": -15,
      "y": 34,
      "z": -4,
      "name": "Plant_Crop_Mushroom_Block_Blue",
      "rotation": 1
    },
    {
      "x": -15,
      "y": 35,
      "z": -4,
      "name": "Plant_Crop_Mushroom_Block_Blue",
      "rotation": 1
    },
    {
      "x": -15,
      "y": 36,
      "z": -4,
      "name": "Plant_Crop_Mushroom_Block_Blue",
      "rotation": 1
    },
    {
      "x": -15,
      "y": 37,
      "z": -4,
      "name": "Plant_Crop_Mushroom_Block_Blue"
    },
    {
      "x": -15,
      "y": 27,
      "z": -3,
      "name": "Plant_Crop_Mushroom_Block_Blue",
      "rotation": 1
    },
    {
      "x": -15,
      "y": 28,
      "z": -3,
      "name": "Plant_Crop_Mushroom_Block_Blue",
      "rotation": 1
    },
    {
      "x": -15,
      "y": 29,
      "z": -3,
      "name": "Plant_Crop_Mushroom_Block_Blue",
      "rotation": 1
    },
    {
      "x": -15,
      "y": 30,
      "z": -3,
      "name": "Plant_Crop_Mushroom_Block_Blue",
      "rotation": 1
    },
    {
      "x": -15,
      "y": 31,
      "z": -3,
      "name": "Plant_Crop_Mushroom_Block_Blue",
      "rotation": 1
    },
    {
      "x": -15,
      "y": 32,
      "z": -3,
      "name": "Plant_Crop_Mushroom_Block_Blue",
      "rotation": 1
    },
    {
      "x": -15,
      "y": 33,
      "z": -3,
      "name": "Plant_Crop_Mushroom_Block_Blue",
      "rotation": 1
    },
    {
      "x": -15,
      "y": 34,
      "z": -3,
      "name": "Plant_Crop_Mushroom_Block_Blue",
      "rotation": 1
    },
    {
      "x": -15,
      "y": 35,
      "z": -3,
      "name": "Plant_Crop_Mushroom_Block_Blue",
      "rotation": 1
    },
    {
      "x": -15,
      "y": 36,
      "z": -3,
      "name": "Plant_Crop_Mushroom_Block_Blue",
      "rotation": 1
    },
    {
      "x": -15,
      "y": 37,
      "z": -3,
      "name": "Plant_Crop_Mushroom_Block_Blue"
    },
    {
      "x": -15,
      "y": 38,
      "z": -3,
      "name": "Plant_Crop_Mushroom_Glowing_Blue"
    },
    {
      "x": -15,
      "y": 27,
      "z": -2,
      "name": "Plant_Crop_Mushroom_Block_Blue",
      "rotation": 1
    },
    {
      "x": -15,
      "y": 28,
      "z": -2,
      "name": "Plant_Crop_Mushroom_Block_Blue",
      "rotation": 1
    },
    {
      "x": -15,
      "y": 29,
      "z": -2,
      "name": "Plant_Crop_Mushroom_Block_Blue",
      "rotation": 1
    },
    {
      "x": -15,
      "y": 30,
      "z": -2,
      "name": "Plant_Crop_Mushroom_Block_Blue",
      "rotation": 1
    },
    {
      "x": -15,
      "y": 31,
      "z": -2,
      "name": "Plant_Crop_Mushroom_Block_Blue",
      "rotation": 1
    },
    {
      "x": -15,
      "y": 32,
      "z": -2,
      "name": "Plant_Crop_Mushroom_Block_Blue",
      "rotation": 1
    },
    {
      "x": -15,
      "y": 33,
      "z": -2,
      "name": "Plant_Crop_Mushroom_Block_Blue",
      "rotation": 1
    },
    {
      "x": -15,
      "y": 34,
      "z": -2,
      "name": "Plant_Crop_Mushroom_Block_Blue",
      "rotation": 1
    },
    {
      "x": -15,
      "y": 35,
      "z": -2,
      "name": "Plant_Crop_Mushroom_Block_Blue",
      "rotation": 1
    },
    {
      "x": -15,
      "y": 36,
      "z": -2,
      "name": "Plant_Crop_Mushroom_Block_Blue",
      "rotation": 1
    },
    {
      "x": -15,
      "y": 37,
      "z": -2,
      "name": "Plant_Crop_Mushroom_Block_Blue"
    },
    {
      "x": -15,
      "y": 38,
      "z": -2,
      "name": "Plant_Crop_Mushroom_Glowing_Blue"
    },
    {
      "x": -15,
      "y": 27,
      "z": -1,
      "name": "Plant_Crop_Mushroom_Block_Blue",
      "rotation": 1
    },
    {
      "x": -15,
      "y": 28,
      "z": -1,
      "name": "Plant_Crop_Mushroom_Block_Blue",
      "rotation": 1
    },
    {
      "x": -15,
      "y": 29,
      "z": -1,
      "name": "Plant_Crop_Mushroom_Block_Blue",
      "rotation": 1
    },
    {
      "x": -15,
      "y": 30,
      "z": -1,
      "name": "Plant_Crop_Mushroom_Block_Blue",
      "rotation": 1
    },
    {
      "x": -15,
      "y": 31,
      "z": -1,
      "name": "Plant_Crop_Mushroom_Block_Blue",
      "rotation": 1
    },
    {
      "x": -15,
      "y": 32,
      "z": -1,
      "name": "Plant_Crop_Mushroom_Block_Blue",
      "rotation": 1
    },
    {
      "x": -15,
      "y": 33,
      "z": -1,
      "name": "Plant_Crop_Mushroom_Block_Blue",
      "rotation": 1
    },
    {
      "x": -15,
      "y": 34,
      "z": -1,
      "name": "Plant_Crop_Mushroom_Block_Blue",
      "rotation": 1
    },
    {
      "x": -15,
      "y": 35,
      "z": -1,
      "name": "Plant_Crop_Mushroom_Block_Blue",
      "rotation": 1
    },
    {
      "x": -15,
      "y": 36,
      "z": -1,
      "name": "Plant_Crop_Mushroom_Block_Blue",
      "rotation": 1
    },
    {
      "x": -15,
      "y": 37,
      "z": -1,
      "name": "Plant_Crop_Mushroom_Block_Blue"
    },
    {
      "x": -15,
      "y": 38,
      "z": -1,
      "name": "Plant_Crop_Mushroom_Block_Blue"
    },
    {
      "x": -15,
      "y": 27,
      "z": 0,
      "name": "Plant_Crop_Mushroom_Block_Blue",
      "rotation": 1
    },
    {
      "x": -15,
      "y": 28,
      "z": 0,
      "name": "Plant_Crop_Mushroom_Block_Blue",
      "rotation": 1
    },
    {
      "x": -15,
      "y": 29,
      "z": 0,
      "name": "Plant_Crop_Mushroom_Block_Blue",
      "rotation": 1
    },
    {
      "x": -15,
      "y": 30,
      "z": 0,
      "name": "Plant_Crop_Mushroom_Block_Blue",
      "rotation": 1
    },
    {
      "x": -15,
      "y": 31,
      "z": 0,
      "name": "Plant_Crop_Mushroom_Block_Blue",
      "rotation": 1
    },
    {
      "x": -15,
      "y": 32,
      "z": 0,
      "name": "Plant_Crop_Mushroom_Block_Blue",
      "rotation": 1
    },
    {
      "x": -15,
      "y": 33,
      "z": 0,
      "name": "Plant_Crop_Mushroom_Block_Blue",
      "rotation": 1
    },
    {
      "x": -15,
      "y": 34,
      "z": 0,
      "name": "Plant_Crop_Mushroom_Block_Blue",
      "rotation": 1
    },
    {
      "x": -15,
      "y": 35,
      "z": 0,
      "name": "Plant_Crop_Mushroom_Block_Blue",
      "rotation": 1
    },
    {
      "x": -15,
      "y": 36,
      "z": 0,
      "name": "Plant_Crop_Mushroom_Block_Blue",
      "rotation": 1
    },
    {
      "x": -15,
      "y": 37,
      "z": 0,
      "name": "Plant_Crop_Mushroom_Block_Blue"
    },
    {
      "x": -15,
      "y": 38,
      "z": 0,
      "name": "Plant_Crop_Mushroom_Block_Blue"
    },
    {
      "x": -15,
      "y": 27,
      "z": 1,
      "name": "Plant_Crop_Mushroom_Block_Blue",
      "rotation": 1
    },
    {
      "x": -15,
      "y": 28,
      "z": 1,
      "name": "Plant_Crop_Mushroom_Block_Blue",
      "rotation": 1
    },
    {
      "x": -15,
      "y": 29,
      "z": 1,
      "name": "Plant_Crop_Mushroom_Block_Blue",
      "rotation": 1
    },
    {
      "x": -15,
      "y": 30,
      "z": 1,
      "name": "Plant_Crop_Mushroom_Block_Blue",
      "rotation": 1
    },
    {
      "x": -15,
      "y": 31,
      "z": 1,
      "name": "Plant_Crop_Mushroom_Block_Blue",
      "rotation": 1
    },
    {
      "x": -15,
      "y": 32,
      "z": 1,
      "name": "Plant_Crop_Mushroom_Block_Blue",
      "rotation": 1
    },
    {
      "x": -15,
      "y": 33,
      "z": 1,
      "name": "Plant_Crop_Mushroom_Block_Blue",
      "rotation": 1
    },
    {
      "x": -15,
      "y": 34,
      "z": 1,
      "name": "Plant_Crop_Mushroom_Block_Blue",
      "rotation": 1
    },
    {
      "x": -15,
      "y": 35,
      "z": 1,
      "name": "Plant_Crop_Mushroom_Block_Blue",
      "rotation": 1
    },
    {
      "x": -15,
      "y": 36,
      "z": 1,
      "name": "Plant_Crop_Mushroom_Block_Blue",
      "rotation": 1
    },
    {
      "x": -15,
      "y": 37,
      "z": 1,
      "name": "Plant_Crop_Mushroom_Block_Blue"
    },
    {
      "x": -15,
      "y": 38,
      "z": 1,
      "name": "Plant_Crop_Mushroom_Block_Blue"
    },
    {
      "x": -15,
      "y": 26,
      "z": 2,
      "name": "Plant_Crop_Mushroom_Block_Blue"
    },
    {
      "x": -15,
      "y": 27,
      "z": 2,
      "name": "Plant_Crop_Mushroom_Block_Blue",
      "rotation": 1
    },
    {
      "x": -15,
      "y": 28,
      "z": 2,
      "name": "Plant_Crop_Mushroom_Block_Blue",
      "rotation": 1
    },
    {
      "x": -15,
      "y": 29,
      "z": 2,
      "name": "Plant_Crop_Mushroom_Block_Blue",
      "rotation": 1
    },
    {
      "x": -15,
      "y": 30,
      "z": 2,
      "name": "Plant_Crop_Mushroom_Block_Blue",
      "rotation": 1
    },
    {
      "x": -15,
      "y": 31,
      "z": 2,
      "name": "Plant_Crop_Mushroom_Block_Blue",
      "rotation": 1
    },
    {
      "x": -15,
      "y": 32,
      "z": 2,
      "name": "Plant_Crop_Mushroom_Block_Blue",
      "rotation": 1
    },
    {
      "x": -15,
      "y": 33,
      "z": 2,
      "name": "Plant_Crop_Mushroom_Block_Blue",
      "rotation": 1
    },
    {
      "x": -15,
      "y": 34,
      "z": 2,
      "name": "Plant_Crop_Mushroom_Block_Blue",
      "rotation": 1
    },
    {
      "x": -15,
      "y": 35,
      "z": 2,
      "name": "Plant_Crop_Mushroom_Block_Blue",
      "rotation": 1
    },
    {
      "x": -15,
      "y": 36,
      "z": 2,
      "name": "Plant_Crop_Mushroom_Block_Blue",
      "rotation": 1
    },
    {
      "x": -15,
      "y": 37,
      "z": 2,
      "name": "Plant_Crop_Mushroom_Block_Blue"
    },
    {
      "x": -15,
      "y": 38,
      "z": 2,
      "name": "Plant_Crop_Mushroom_Block_Blue"
    },
    {
      "x": -15,
      "y": 26,
      "z": 3,
      "name": "Plant_Crop_Mushroom_Block_Blue"
    },
    {
      "x": -15,
      "y": 27,
      "z": 3,
      "name": "Plant_Crop_Mushroom_Block_Blue",
      "rotation": 1
    },
    {
      "x": -15,
      "y": 28,
      "z": 3,
      "name": "Plant_Crop_Mushroom_Block_Blue",
      "rotation": 1
    },
    {
      "x": -15,
      "y": 29,
      "z": 3,
      "name": "Plant_Crop_Mushroom_Block_Blue",
      "rotation": 1
    },
    {
      "x": -15,
      "y": 30,
      "z": 3,
      "name": "Plant_Crop_Mushroom_Block_Blue",
      "rotation": 1
    },
    {
      "x": -15,
      "y": 31,
      "z": 3,
      "name": "Plant_Crop_Mushroom_Block_Blue",
      "rotation": 1
    },
    {
      "x": -15,
      "y": 32,
      "z": 3,
      "name": "Plant_Crop_Mushroom_Block_Blue",
      "rotation": 1
    },
    {
      "x": -15,
      "y": 33,
      "z": 3,
      "name": "Plant_Crop_Mushroom_Block_Blue",
      "rotation": 1
    },
    {
      "x": -15,
      "y": 34,
      "z": 3,
      "name": "Plant_Crop_Mushroom_Block_Blue",
      "rotation": 1
    },
    {
      "x": -15,
      "y": 35,
      "z": 3,
      "name": "Plant_Crop_Mushroom_Block_Blue",
      "rotation": 1
    },
    {
      "x": -15,
      "y": 36,
      "z": 3,
      "name": "Plant_Crop_Mushroom_Block_Blue",
      "rotation": 1
    },
    {
      "x": -15,
      "y": 37,
      "z": 3,
      "name": "Plant_Crop_Mushroom_Block_Blue"
    },
    {
      "x": -15,
      "y": 26,
      "z": 4,
      "name": "Plant_Crop_Mushroom_Block_Blue"
    },
    {
      "x": -15,
      "y": 27,
      "z": 4,
      "name": "Plant_Crop_Mushroom_Block_Blue",
      "rotation": 1
    },
    {
      "x": -15,
      "y": 28,
      "z": 4,
      "name": "Plant_Crop_Mushroom_Block_Blue",
      "rotation": 1
    },
    {
      "x": -15,
      "y": 29,
      "z": 4,
      "name": "Plant_Crop_Mushroom_Block_Blue",
      "rotation": 1
    },
    {
      "x": -15,
      "y": 30,
      "z": 4,
      "name": "Plant_Crop_Mushroom_Block_Blue",
      "rotation": 1
    },
    {
      "x": -15,
      "y": 31,
      "z": 4,
      "name": "Plant_Crop_Mushroom_Block_Blue",
      "rotation": 1
    },
    {
      "x": -15,
      "y": 32,
      "z": 4,
      "name": "Plant_Crop_Mushroom_Block_Blue",
      "rotation": 1
    },
    {
      "x": -15,
      "y": 33,
      "z": 4,
      "name": "Plant_Crop_Mushroom_Block_Blue",
      "rotation": 1
    },
    {
      "x": -15,
      "y": 34,
      "z": 4,
      "name": "Plant_Crop_Mushroom_Block_Blue",
      "rotation": 1
    },
    {
      "x": -15,
      "y": 35,
      "z": 4,
      "name": "Plant_Crop_Mushroom_Block_Blue",
      "rotation": 1
    },
    {
      "x": -15,
      "y": 36,
      "z": 4,
      "name": "Plant_Crop_Mushroom_Block_Blue",
      "rotation": 1
    },
    {
      "x": -15,
      "y": 37,
      "z": 4,
      "name": "Plant_Crop_Mushroom_Block_Blue"
    },
    {
      "x": -15,
      "y": 38,
      "z": 4,
      "name": "Plant_Crop_Mushroom_Glowing_Blue"
    },
    {
      "x": -15,
      "y": 26,
      "z": 5,
      "name": "Plant_Crop_Mushroom_Block_Blue"
    },
    {
      "x": -15,
      "y": 27,
      "z": 5,
      "name": "Plant_Crop_Mushroom_Block_Blue",
      "rotation": 1
    },
    {
      "x": -15,
      "y": 28,
      "z": 5,
      "name": "Plant_Crop_Mushroom_Block_Blue",
      "rotation": 1
    },
    {
      "x": -15,
      "y": 29,
      "z": 5,
      "name": "Plant_Crop_Mushroom_Block_Blue",
      "rotation": 1
    },
    {
      "x": -15,
      "y": 30,
      "z": 5,
      "name": "Plant_Crop_Mushroom_Block_Blue",
      "rotation": 1
    },
    {
      "x": -15,
      "y": 31,
      "z": 5,
      "name": "Plant_Crop_Mushroom_Block_Blue",
      "rotation": 1
    },
    {
      "x": -15,
      "y": 32,
      "z": 5,
      "name": "Plant_Crop_Mushroom_Block_Blue",
      "rotation": 1
    },
    {
      "x": -15,
      "y": 33,
      "z": 5,
      "name": "Plant_Crop_Mushroom_Block_Blue",
      "rotation": 1
    },
    {
      "x": -15,
      "y": 34,
      "z": 5,
      "name": "Plant_Crop_Mushroom_Block_Blue",
      "rotation": 1
    },
    {
      "x": -15,
      "y": 35,
      "z": 5,
      "name": "Plant_Crop_Mushroom_Block_Blue",
      "rotation": 1
    },
    {
      "x": -15,
      "y": 36,
      "z": 5,
      "name": "Plant_Crop_Mushroom_Block_Blue",
      "rotation": 1
    },
    {
      "x": -15,
      "y": 37,
      "z": 5,
      "name": "Plant_Crop_Mushroom_Block_Blue"
    },
    {
      "x": -15,
      "y": 38,
      "z": 5,
      "name": "Plant_Crop_Mushroom_Glowing_Blue"
    },
    {
      "x": -15,
      "y": 26,
      "z": 6,
      "name": "Plant_Crop_Mushroom_Block_Blue"
    },
    {
      "x": -15,
      "y": 27,
      "z": 6,
      "name": "Plant_Crop_Mushroom_Block_Blue",
      "rotation": 1
    },
    {
      "x": -15,
      "y": 28,
      "z": 6,
      "name": "Plant_Crop_Mushroom_Block_Blue",
      "rotation": 1
    },
    {
      "x": -15,
      "y": 29,
      "z": 6,
      "name": "Plant_Crop_Mushroom_Block_Blue",
      "rotation": 1
    },
    {
      "x": -15,
      "y": 30,
      "z": 6,
      "name": "Plant_Crop_Mushroom_Block_Blue",
      "rotation": 1
    },
    {
      "x": -15,
      "y": 31,
      "z": 6,
      "name": "Plant_Crop_Mushroom_Block_Blue",
      "rotation": 1
    },
    {
      "x": -15,
      "y": 32,
      "z": 6,
      "name": "Plant_Crop_Mushroom_Block_Blue",
      "rotation": 1
    },
    {
      "x": -15,
      "y": 33,
      "z": 6,
      "name": "Plant_Crop_Mushroom_Block_Blue",
      "rotation": 1
    },
    {
      "x": -15,
      "y": 34,
      "z": 6,
      "name": "Plant_Crop_Mushroom_Block_Blue",
      "rotation": 1
    },
    {
      "x": -15,
      "y": 35,
      "z": 6,
      "name": "Plant_Crop_Mushroom_Block_Blue",
      "rotation": 1
    },
    {
      "x": -15,
      "y": 36,
      "z": 6,
      "name": "Plant_Crop_Mushroom_Block_Blue",
      "rotation": 1
    },
    {
      "x": -15,
      "y": 37,
      "z": 6,
      "name": "Plant_Crop_Mushroom_Block_Blue"
    },
    {
      "x": -15,
      "y": 38,
      "z": 6,
      "name": "Plant_Crop_Mushroom_Glowing_Blue"
    },
    {
      "x": -15,
      "y": 26,
      "z": 7,
      "name": "Plant_Crop_Mushroom_Block_Blue"
    },
    {
      "x": -15,
      "y": 27,
      "z": 7,
      "name": "Plant_Crop_Mushroom_Block_Blue",
      "rotation": 1
    },
    {
      "x": -15,
      "y": 28,
      "z": 7,
      "name": "Plant_Crop_Mushroom_Block_Blue",
      "rotation": 1
    },
    {
      "x": -15,
      "y": 29,
      "z": 7,
      "name": "Plant_Crop_Mushroom_Block_Blue",
      "rotation": 1
    },
    {
      "x": -15,
      "y": 30,
      "z": 7,
      "name": "Plant_Crop_Mushroom_Block_Blue",
      "rotation": 1
    },
    {
      "x": -15,
      "y": 31,
      "z": 7,
      "name": "Plant_Crop_Mushroom_Block_Blue",
      "rotation": 1
    },
    {
      "x": -15,
      "y": 32,
      "z": 7,
      "name": "Plant_Crop_Mushroom_Block_Blue",
      "rotation": 1
    },
    {
      "x": -15,
      "y": 33,
      "z": 7,
      "name": "Plant_Crop_Mushroom_Block_Blue",
      "rotation": 1
    },
    {
      "x": -15,
      "y": 34,
      "z": 7,
      "name": "Plant_Crop_Mushroom_Block_Blue",
